Workbook
Name EntId: '1) Artists list'!$I$1
Name CompContributor: '7) Comp ContributorPublisher li'!$A$5:$A$995
Name TrackProperties: 'Reference info'!$R$3:$R$10
Name ReleaseType: 'Reference info'!$G$3:$G$7
Name Language: 'Reference info'!$K$3:$K$418
Name Publishing: 'Reference info'!$O$3:$O$5
Name ArtistRole: 'Reference info'!$J$3:$J$430
Name CompositionRole: 'Reference info'!$Q$3:$Q$14
Name Label: '2) Labels list'!$A$5:$A$998
Name Genre: 'Reference info'!$H$3:$H$419
Name Publisher: '7) Comp ContributorPublisher li'!$D$5:$D$995
Name Artist: '1) Artists list'!$A$5:$A$944
Name TenantId: '1) Artists list'!$I$2

Sheet Introduction
B1: INTRODUCTION
A2: 1) | B2: Please make a copy of the master document in order to start filling it out. Make a copy by going to: File > Make a copy
A3: 2) | B3: Rename this document by replacing "MASTER" with your company name.
A4: 3) | B4: Share it with kenny@revelator.com, milan@revelator.com and nicolas.g@revelator.com and provide FULL Edit permissions across the worksheet:
B5: go to Data>Protected sheets and ranges>Show all protected ranges>Change permissions to full editing across ALL protected ranges from tabs 1 to 8
B7: You can also add anyone else from your team as needed.
B9: • Please fill out the catalog insert tabs enumerated in this spreadsheet by following the instructions in the corresponding fields and reading any applicable notes throughout
B10: • A black triangle in the top right corner of a cell means that there is a note — mouse over it to read it
B11: • If you are importing catalog metadata for reporting purposes only, then you only need to complete fields marked as REQUIRED as well as any UPC/ISRC or ID fields through tab 6
B13: Use the 'Sample Data' tab for additional guidance
B15: NOTE: Batch importing new catalog from the worksheet is generally not available on an ongoing basis so be sure all releases and tracks for import are included in the worksheet beforehand.
B16: After the initial import, adding catalog is meant to be done from the frontend of your account (or with the API if you are on an API plan). There are liable to be additional fees if the worksheet is to be used for new catalog after the initial import.
B18: • We DO NOT support importing files from Google Drive
B21: NO DSP sale reports should be uploaded and reporting feeds should NOT be set up until the account's catalog has been finalized, which includes the following steps:
B22: • ALL EXISTING catalog content has been imported
B23: • ALL catalog Delivery/Ingestion FEEDS have been DISABLED
... B30: • Delete ALL error matching rules

Sheet 1) Artists list
A1: =IFERROR(__xludf.DUMMYFUNCTION("COUNTUNIQUE(A5:A944)-if(COUNTIF('4) Release_Artist(s)'!E:E, ""Various Artists"")>0,0,1)"),2.0) -> 2 | B1: List all Artists to Import | C1: =IFERROR(__xludf.DUMMYFUNCTION("COUNTUNIQUE(C5:C944)"),2.0) -> 2 | D1: =IFERROR(__xludf.DUMMYFUNCTION("COUNTUNIQUE(D5:D944)"),2.0) -> 2 | E1: =IFERROR(__xludf.DUMMYFUNCTION("COUNTUNIQUE(E5:E944)"),2.0) -> 2 | F1: =IFERROR(__xludf.DUMMYFUNCTION("COUNTUNIQUE(F5:F944)"),0.0) -> 0 | G1: =IFERROR(__xludf.DUMMYFUNCTION("COUNTUNIQUE(B5:B944)"),2.0) -> 2 | H1: EnterpriseId= | I1: 414849 | J1: ="SELECT * FROM Artists where EntId="&EntId -> SELECT * FROM Artists where EntId=414849
A2: = REQUIRED FIELD | B2: = OPTIONAL FIELD | D2: = READ NOTES / INSTRUCTIONS | F2: = OPTIONAL FIELD | G2: =countif(B5:B944,"<>""")-countif(B5:B944,"") -> 2 | H2: TenantId= | I2: 332920
A3: Artist Name | B3: Artist Image url | C3: Apple ArtistId | D3: Spotify Artist URI | E3: Meta ArtistId | F3: SoundCloud ProfileId | H3: Duplicate Names
A4: Written EXACTLY as per label copy | B4: public URL triggering DIRECT DOWNLOAD of file | C4: Enter Artist's AppleId or 'NEW'=new AppleId | D4: Enter Artist's Spotify URI link or 'NEW'=new Spotify URI link | E4: Facebook Audio Library & Rights Manager ArtistId | F4: SoundCloud Artist Username | H4: =IFERROR(__xludf.DUMMYFUNCTION("counta(A5:A944)-COUNTUNIQUE(A5:A944)"),0.0) -> 0
A5: JKZ | B5: https://www.dropbox.com/scl/fi/7safoetk4p2k4vwi29k4c/Receba-789294845633-UPC.jpg?rlkey=3vty6hb78ol10iv3y6h4md8h3&st=m30ox0p4&dl=1 | C5: 1532352644 | D5: spotify:artist:1Gn8eEXtOWHA7XU8wEWXOb | E5: 697315585919469 | I5: =IFERROR(__xludf.DUMMYFUNCTION("""Insert into Artists VALUES(N'""&SUBSTITUTE(trim(A5),""'"",""''"")&""', (select CreatedBy from Enterprises where EnterpriseId=""&EntId&""), (select ImageId from Images where Filename='""&REGEXREPLACE(A5,""[^[:alnum:]]"","""")&EntId&G5&""'), null, null, g"&"etdate(), null, null, null, null, ""&EntId&"", null, null, null, null, 0, null, null, ""&TenantId&"", null, null, null, null, null, null, 0, 0)"""),"Insert into Artists VALUES(N'JKZ', (select CreatedBy from Enterprises where EnterpriseId=414849), (select ImageId from Images where Filename='JKZ414849'), null, null, getdate(), null, null, null, null, 414849, null, null, null, null, 0, null, null, 332920"&", null, null, null, null, null, null, 0, 0)") -> Insert into Artists VALUES(N'JKZ', (select CreatedBy from Enterprises where EnterpriseId=414849), (select ImageId from Images where Filename='JKZ414849'), null, null, getdate(), null, null, null, null, 414849, null, null, null, null, 0, null, null, 332920, null, null, null, null, null, null, 0, 0) | J5: =if(C5="","","insert into Artists_ExternalIds values ( (select ArtistId from Artists where Name=N'"&SUBSTITUTE(trim($A5),"'","''")&"' and EnterpriseId="&EntId&"), "&if(trim(C5)="new","null","'"&trim(C5)&"'")&", 1)") -> insert into Artists_ExternalIds values ( (select ArtistId from Artists where Name=N'JKZ' and EnterpriseId=414849), '1532352644', 1) | K5: =if(D5="","","insert into Artists_ExternalIds values ( (select ArtistId from Artists where Name=N'"&SUBSTITUTE(trim($A5),"'","''")&"' and EnterpriseId="&EntId&"), "&if(trim(D5)="new","null","'"&right(trim(D5),22)&"'")&", 9)") -> insert into Artists_ExternalIds values ( (select ArtistId from Artists where Name=N'JKZ' and EnterpriseId=414849), '1Gn8eEXtOWHA7XU8wEWXOb', 9)
A6: Flash Beats Manow | B6: https://www.dropbox.com/scl/fi/wky0ryb739s0xs3wo5qop/A-Cl-usula-do-Contrato-789294962088-UPC.jpg?rlkey=91bp85llgb8ho5lnfcs56105s&st=dn12pxrd&dl=1 | C6: 1601139620 | D6: spotify:artist:0ZIlwtVZkqtMZUpbHrz8TL | E6: 697315585919468 | I6: =IFERROR(__xludf.DUMMYFUNCTION("""Insert into Artists VALUES(N'""&SUBSTITUTE(trim(A6),""'"",""''"")&""', (select CreatedBy from Enterprises where EnterpriseId=""&EntId&""), (select ImageId from Images where Filename='""&REGEXREPLACE(A6,""[^[:alnum:]]"","""")&EntId&G6&""'), null, null, g"&"etdate(), null, null, null, null, ""&EntId&"", null, null, null, null, 0, null, null, ""&TenantId&"", null, null, null, null, null, null, 0, 0)"""),"Insert into Artists VALUES(N'Flash Beats Manow', (select CreatedBy from Enterprises where EnterpriseId=414849), (select ImageId from Images where Filename='FlashBeatsManow414849'), null, null, getdate(), null, null, null, null, 414849, null, null, null, n"&"ull, 0, null, null, 332920, null, null, null, null, null, null, 0, 0)") -> Insert into Artists VALUES(N'Flash Beats Manow', (select CreatedBy from Enterprises where EnterpriseId=414849), (select ImageId from Images where Filename='FlashBeatsManow414849'), null, null, getdate(), null, null, null, null, 414849, null, null, null, null, 0, null, null, 332920, null, null, null, null, null, null, 0, 0) | J6: =if(C6="","","insert into Artists_ExternalIds values ( (select ArtistId from Artists where Name=N'"&SUBSTITUTE(trim($A6),"'","''")&"' and EnterpriseId="&EntId&"), "&if(trim(C6)="new","null","'"&trim(C6)&"'")&", 1)") -> insert into Artists_ExternalIds values ( (select ArtistId from Artists where Name=N'Flash Beats Manow' and EnterpriseId=414849), '1601139620', 1) | K6: =if(D6="","","insert into Artists_ExternalIds values ( (select ArtistId from Artists where Name=N'"&SUBSTITUTE(trim($A6),"'","''")&"' and EnterpriseId="&EntId&"), "&if(trim(D6)="new","null","'"&right(trim(D6),22)&"'")&", 9)") -> insert into Artists_ExternalIds values ( (select ArtistId from Artists where Name=N'Flash Beats Manow' and EnterpriseId=414849), '0ZIlwtVZkqtMZUpbHrz8TL', 9)
A944: Various Artists

Sheet 2) Labels list
A1: List all Labels to Import | B1: =IFERROR(__xludf.DUMMYFUNCTION("COUNTUNIQUE(A5:A998)"),2.0) -> 2
A2: = REQUIRED FIELD | B2: Duplicate Names
A3: Label Name | B3: =IFERROR(__xludf.DUMMYFUNCTION("counta(A5:A998)-COUNTUNIQUE(A5:A998)"),0.0) -> 0
A4: Written EXACTLY as per label copy
A5: TokyoRecords | C5: ="Insert into Labels VALUES(N'"&SUBSTITUTE(trim(A5),"'","''")&"', (select CreatedBy from Enterprises where EnterpriseId="&EntId&"), null, null, null, null, null, getdate(), null, null, "&EntId&", null, null, null, null, null, null, "&TenantId&")" -> Insert into Labels VALUES(N'TokyoRecords', (select CreatedBy from Enterprises where EnterpriseId=414849), null, null, null, null, null, getdate(), null, null, 414849, null, null, null, null, null, null, 332920)
A6: PEJOTA10* | C6: ="Insert into Labels VALUES(N'"&SUBSTITUTE(trim(A6),"'","''")&"', (select CreatedBy from Enterprises where EnterpriseId="&EntId&"), null, null, null, null, null, getdate(), null, null, "&EntId&", null, null, null, null, null, null, "&TenantId&")" -> Insert into Labels VALUES(N'PEJOTA10*', (select CreatedBy from Enterprises where EnterpriseId=414849), null, null, null, null, null, getdate(), null, null, 414849, null, null, null, null, null, null, 332920)

Sheet 3) Release_Label
A1: =IFERROR(__xludf.DUMMYFUNCTION("COUNTUNIQUE(A5:A624)"),2.0) -> 2 | B1: = REQUIRED FIELD | C1: =IFERROR(__xludf.DUMMYFUNCTION("COUNTUNIQUE(B5:B624)"),2.0) -> 2 | D1: =IFERROR(__xludf.DUMMYFUNCTION("COUNTUNIQUE(D5:D624)"),2.0) -> 2 | E1: =IFERROR(__xludf.DUMMYFUNCTION("COUNTUNIQUE(E5:E624)"),0.0) -> 0 | F1: = READ NOTES / INSTRUCTIONS | G1: =COUNTA(F5:F624) -> 2 | H1: = OPTIONAL | I1: =countif(I5:I624,"Video")+countif(I5:I624,"Ringtone") -> 0 | M1: = REQUIRED FIELD | N1: = OPTIONAL | R1: ="SELECT count(distinct (ReleaseId)) FROM v_kr_catalog where EnterpriseId="&EntId -> SELECT count(distinct (ReleaseId)) FROM v_kr_catalog where EnterpriseId=414849
A2: RELEASE LEVEL - Label<>UPC/ID | R2: ="SELECT count(*) FROM Releases where CreatedBy=(select CreatedBy from Enterprises where EnterpriseId="&EntId&")" -> SELECT count(*) FROM Releases where CreatedBy=(select CreatedBy from Enterprises where EnterpriseId=414849)
A3: LABEL | B3: COVER IMAGE URL | C3: IMAGE TYPE | D3: UPC / EAN / JAN | E3: CATALOG RELEASE ID | F3: RELEASE TITLE | G3: TITLE LANGUAGE | H3: RELEASE VERSION | I3: RELEASE TYPE | J3: (P) Copyright | L3: (C) Copyright | N3: ORIGINAL RELEASE DATE | O3: GENRE 1 | P3: GENRE 2
A4: (select from Labels list, start typing or drag) | B4: public URL triggering DIRECT DOWNLOAD of file (10 MB max) required if distributing content | C4: jpeg / jpg ONLY | D4: UPC: 12 digits EAN: 13 digits blank if no code yet | E4: Internal Ref. ID required if no code yet | F4: Written EXACTLY as per label copy (no version, type or contributor info) | G4: (select from list, start typing or drag) | H4: If applicable | I4: (select from list, start typing or drag) | J4: Year | K4: Holder | L4: Year | M4: Holder | N4: YYYY-MM-DD | O4: (select from list, start typing or drag) | P4: (select from list, start typing or drag) | Q4: Existing UPCs/ Catalog IDs | T4: Genre Dup
A5: TokyoRecords | B5: https://www.dropbox.com/scl/fi/7safoetk4p2k4vwi29k4c/Receba-789294845633-UPC.jpg?rlkey=3vty6hb78ol10iv3y6h4md8h3&st=m30ox0p4&dl=1 | C5: jpg | D5: 789294845633 | F5: Receba | G5: Portuguese | H5: Extended | I5: Single | J5: 2022 | K5: TokyoRecords | L5: 2022 | M5: TokyoRecords | N5: 44886 | O5: Hip Hop/Rap | P5: African Reggae | R5: =if(B5="","","insert into Images VALUES (NEWID(),'"&if(D5="",trim(E5)&"."&C5,D5&"."&C5)&"', '."&C5&"', getdate(), 0, null, '"&SUBSTITUTE(trim(B5),"'","''")&"', 0, getdate(), null, null)") -> insert into Images VALUES (NEWID(),'789294845633.jpg', '.jpg', getdate(), 0, null, 'https://www.dropbox.com/scl/fi/7safoetk4p2k4vwi29k4c/Receba-789294845633-UPC.jpg?rlkey=3vty6hb78ol10iv3y6h4md8h3&st=m30ox0p4&dl=1', 0, getdate(), null, null) | S5: ="Insert into Releases VALUES((select ReleaseTypeId from ReleaseTypes where Title='"&I5&"'), N'"&SUBSTITUTE(trim(F5),"'","''")&"', null, (select LabelId from Labels where Name=N'"&SUBSTITUTE(trim(A5),"'","''")&"' and EnterpriseId="&EntId&"), "&IF(D5="","null",D5)&", null, null, "&IF(H5="","null","N'"&SUBSTITUTE(trim(H5),"'","''")&"'")&", N'"&J5&" "&SUBSTITUTE(trim(K5),"'","''")&"', N'"&L5&" "&SUBSTITUTE(trim(M5),"'","''")&"', "&IF(N5="","null","'"&TEXT(N5,"yyyy-mm-dd")&"'")&", "&IF(E5="","null","'"&SUBSTITUTE(trim(E5),"'","''")&"'")&", "&if(B5="","null",if(D5="","(select ImageId from Images where Filename='"&E5&"."&C5&"' and ExternalUrl='"&SUBSTITUTE(trim(B5),"'","''")&"')","(select ImageId from Images where Filename='"&D5&"."&C5&"' and ExternalUrl='"&SUBSTITUTE(trim(B5),"'","''")&"')"))&", null, null, null, (select min(LanguageId) from Languages where LanguageName='"&G5&"' and IsValidMetadataLanguage=1), getdate(), (select CreatedBy from Enterprises where EnterpriseId="&EntId&"), null, '34F4C88E-B410-461E-AD75-6C01536FDCD3', null, null, null, null, null, null, null, null, null, 1, null, null, null, "&VLOOKUP(O5,'Reference info'!H:I,2,FALSE)&", "&IF(P5="","null",VLOOKUP(P5,'Reference info'!H:I,2,FALSE))&", 0, null, null, null,"&IF(N5="",0,1)&", 1, null, null, null, null, null, null, null, null, null, 1, null, (NEXT VALUE FOR [AssetIdSequence]), null, null, null, "&TenantId&", "&EntId&", null, "&if(D5<>"",countif('5) Release_Track'!A:A,D5),countif('5) Release_Track'!B:B,E5))&")" -> Insert into Releases VALUES((select ReleaseTypeId from ReleaseTypes where Title='Single'), N'Receba', null, (select LabelId from Labels where Name=N'TokyoRecords' and EnterpriseId=414849), 789294845633, null, null, N'Extended', N'2022 TokyoRecords', N'2022 TokyoRecords', '2022-11-21', null, (select ImageId from Images where Filename='789294845633.jpg' and ExternalUrl='https://www.dropbox.com/scl/fi/7safoetk4p2k4vwi29k4c/Receba-789294845633-UPC.jpg?rlkey=3vty6hb78ol10iv3y6h4md8h3&st=m30ox0p4&dl=1'), null, null, null, (select min(LanguageId) from Languages where LanguageName='Portuguese' and IsValidMetadataLanguage=1), getdate(), (select CreatedBy from Enterprises where EnterpriseId=414849), null, '34F4C88E-B410-461E-AD75-6C01536FDCD3', null, null, null, null, null, null, null, null, null, 1, null, null, null, 41, 555, 0, null, null, null,1, 1, null, null, null, null, null, null, null, null, null, 1, null, (NEXT VALUE FOR [AssetIdSequence]), null, null, null, 332920, 414849, null, 1) | T5: ="update Releases set RevelatorExternalUsageReleaseId=AssetId where ReleaseId=(select max(ReleaseId) from Releases where "&IF(D5="","Catalog='"&E5&"'","UPC="&D5)&" and EnterpriseId="&EntId&")" -> update Releases set RevelatorExternalUsageReleaseId=AssetId where ReleaseId=(select max(ReleaseId) from Releases where UPC=789294845633 and EnterpriseId=414849) | V5: =VLOOKUP(D5,'4) Release_Artist(s)'!A:A,1,0) -> 789294845633
A6: PEJOTA10* | B6: https://www.dropbox.com/scl/fi/wky0ryb739s0xs3wo5qop/A-Cl-usula-do-Contrato-789294962088-UPC.jpg?rlkey=91bp85llgb8ho5lnfcs56105s&st=dn12pxrd&dl=1 | C6: jpg | D6: 789294962088 | F6: A Cláusula do Contrato | G6: Portuguese | I6: Single | J6: 2022 | K6: TokyoRecords | L6: 2022 | M6: TokyoRecords | N6: 44889 | O6: Hip Hop/Rap | P6: African Reggae | R6: =if(B6="","","insert into Images VALUES (NEWID(),'"&if(D6="",trim(E6)&"."&C6,D6&"."&C6)&"', '."&C6&"', getdate(), 0, null, '"&SUBSTITUTE(trim(B6),"'","''")&"', 0, getdate(), null, null)") -> insert into Images VALUES (NEWID(),'789294962088.jpg', '.jpg', getdate(), 0, null, 'https://www.dropbox.com/scl/fi/wky0ryb739s0xs3wo5qop/A-Cl-usula-do-Contrato-789294962088-UPC.jpg?rlkey=91bp85llgb8ho5lnfcs56105s&st=dn12pxrd&dl=1', 0, getdate(), null, null) | S6: ="Insert into Releases VALUES((select ReleaseTypeId from ReleaseTypes where Title='"&I6&"'), N'"&SUBSTITUTE(trim(F6),"'","''")&"', null, (select LabelId from Labels where Name=N'"&SUBSTITUTE(trim(A6),"'","''")&"' and EnterpriseId="&EntId&"), "&IF(D6="","null",D6)&", null, null, "&IF(H6="","null","N'"&SUBSTITUTE(trim(H6),"'","''")&"'")&", N'"&J6&" "&SUBSTITUTE(trim(K6),"'","''")&"', N'"&L6&" "&SUBSTITUTE(trim(M6),"'","''")&"', "&IF(N6="","null","'"&TEXT(N6,"yyyy-mm-dd")&"'")&", "&IF(E6="","null","'"&SUBSTITUTE(trim(E6),"'","''")&"'")&", "&if(B6="","null",if(D6="","(select ImageId from Images where Filename='"&E6&"."&C6&"' and ExternalUrl='"&SUBSTITUTE(trim(B6),"'","''")&"')","(select ImageId from Images where Filename='"&D6&"."&C6&"' and ExternalUrl='"&SUBSTITUTE(trim(B6),"'","''")&"')"))&", null, null, null, (select min(LanguageId) from Languages where LanguageName='"&G6&"' and IsValidMetadataLanguage=1), getdate(), (select CreatedBy from Enterprises where EnterpriseId="&EntId&"), null, '34F4C88E-B410-461E-AD75-6C01536FDCD3', null, null, null, null, null, null, null, null, null, 1, null, null, null, "&VLOOKUP(O6,'Reference info'!H:I,2,FALSE)&", "&IF(P6="","null",VLOOKUP(P6,'Reference info'!H:I,2,FALSE))&", 0, null, null, null,"&IF(N6="",0,1)&", 1, null, null, null, null, null, null, null, null, null, 1, null, (NEXT VALUE FOR [AssetIdSequence]), null, null, null, "&TenantId&", "&EntId&", null, "&if(D6<>"",countif('5) Release_Track'!A:A,D6),countif('5) Release_Track'!B:B,E6))&")" -> Insert into Releases VALUES((select ReleaseTypeId from ReleaseTypes where Title='Single'), N'A Cláusula do Contrato', null, (select LabelId from Labels where Name=N'PEJOTA10*' and EnterpriseId=414849), 789294962088, null, null, null, N'2022 TokyoRecords', N'2022 TokyoRecords', '2022-11-24', null, (select ImageId from Images where Filename='789294962088.jpg' and ExternalUrl='https://www.dropbox.com/scl/fi/wky0ryb739s0xs3wo5qop/A-Cl-usula-do-Contrato-789294962088-UPC.jpg?rlkey=91bp85llgb8ho5lnfcs56105s&st=dn12pxrd&dl=1'), null, null, null, (select min(LanguageId) from Languages where LanguageName='Portuguese' and IsValidMetadataLanguage=1), getdate(), (select CreatedBy from Enterprises where EnterpriseId=414849), null, '34F4C88E-B410-461E-AD75-6C01536FDCD3', null, null, null, null, null, null, null, null, null, 1, null, null, null, 41, 555, 0, null, null, null,1, 1, null, null, null, null, null, null, null, null, null, 1, null, (NEXT VALUE FOR [AssetIdSequence]), null, null, null, 332920, 414849, null, 1) | T6: ="update Releases set RevelatorExternalUsageReleaseId=AssetId where ReleaseId=(select max(ReleaseId) from Releases where "&IF(D6="","Catalog='"&E6&"'","UPC="&D6)&" and EnterpriseId="&EntId&")" -> update Releases set RevelatorExternalUsageReleaseId=AssetId where ReleaseId=(select max(ReleaseId) from Releases where UPC=789294962088 and EnterpriseId=414849) | V6: =VLOOKUP(D6,'4) Release_Artist(s)'!A:A,1,0) -> 789294962088

Sheet 4) Release_Artist(s)
A1: =IFERROR(__xludf.DUMMYFUNCTION("COUNTUNIQUE(A5:A520)-'3) Release_Label'!D1"),0.0) -> 0 | B1: =IFERROR(__xludf.DUMMYFUNCTION("COUNTUNIQUE(B5:B520)-'3) Release_Label'!E1"),0.0) -> 0 | C1: = FILLED AUTOMATICALLY IF CODES/IDS MATCH | E1: =IFERROR(__xludf.DUMMYFUNCTION("COUNTUNIQUE(E5:E520)"),2.0) -> 2 | F1: = REQUIRED FIELD | G1: =countif(F:F,"Main Primary Artist")-'3) Release_Label'!G1 -> 0 | H1: = READ NOTES / INSTRUCTIONS
A2: RELEASE LEVEL - Artist<>UPC/ID : One Arist per row. If a Release has multiple Artists, add the same Release Code/ID to a new row for each Artist.
A3: UPC / EAN / JAN | B3: CATALOG RELEASE ID | C3: RELEASE TITLE | D3: RELEASE VERSION | E3: ARTIST | F3: ARTIST ROLE | G3: ARTIST ROLE CATEGORY | H3: =IFERROR(__xludf.DUMMYFUNCTION("if(iserror(filter(A:B,G:G=""Producer & Engineer"")),0, countunique(filter(A:B,G:G=""Producer & Engineer"")))-'3) Release_Label'!G1"),0.0) -> 0
A4: from Release_Label tab | B4: from Release_Label tab | C4: auto-fills if Release Code/Id matches Code/Id in Release_Label tab | E4: ONE ARTIST PER ROW select from Artists list, start typing or drag If compilation: Various Artists | F4: (select from list, start typing or drag) | G4: artist category auto-fills based on artist role
A5: 789294845633 | C5: {=ifs(and(isblank($A5),isblank($B5)),"", not(iserror(vlookup($A5&$B5,'3) Release_Label'!$D:$D&'3) Release_Label'!$E:$E,1,0))),vlookup($A5&$B5,{'3) Release_Label'!$D:$D&'3) Release_Label'!$E:$E,'3) Release_Label'!$F:$F},2,0), or(and(not(isblank($B5)),$B5=$B4,$A5<>$A4),and(not(isblank($A5)),$A5=$A4,$B5<>$B4)),"ID LISTS UNALIGNED",and($A5<>"",countif('3) Release_Label'!$D:$D,$A5)=0),"NO UPC MATCH in Release_Label",and($B5<>"",countif('3) Release_Label'!$E:$E,$B5)=0),"NO CATALOG ID MATCH in Release_Label",iserror(vlookup($A5&$B5,'3) Release_Label'!$D:$D&'3) Release_Label'!$E:$E,1,0)),"NO UPC-CATALOG ID pair MATCH in Release_Label" )} -> Receba | D5: {=ifs(and(isblank($A5),isblank($B5)),"", not(iserror(vlookup($A5&$B5,'3) Release_Label'!$D:$D&'3) Release_Label'!$E:$E,1,0))),vlookup($A5&$B5,{'3) Release_Label'!$D:$D&'3) Release_Label'!$E:$E,'3) Release_Label'!$H:$H},2,0), or(and(not(isblank($B5)),$B5=$B4,$A5<>$A4),and(not(isblank($A5)),$A5=$A4,$B5<>$B4)),"ID LISTS UNALIGNED",and($A5<>"",countif('3) Release_Label'!$D:$D,$A5)=0),"NO UPC MATCH in Release_Label",and($B5<>"",countif('3) Release_Label'!$E:$E,$B5)=0),"NO CATALOG ID MATCH in Release_Label",iserror(vlookup($A5&$B5,'3) Release_Label'!$D:$D&'3) Release_Label'!$E:$E,1,0)),"NO UPC-CATALOG ID pair MATCH in Release_Label" )} -> Extended | E5: JKZ | F5: Main Primary Artist | G5: {=ifs(or($F5="",$F5="Main Primary Artist"),$F5,not(iserror(vlookup($F5,'Reference info'!$J$5:$J$8,1,0))),"Key Artist",not(iserror(vlookup($F5,'Reference info'!$J$38:$J$405,1,0))),"Performer",not(iserror(vlookup($F5,'Reference info'!$J$10:$J$36,1,0))),"Producer & Engineer")} -> Main Primary Artist | I5: =IF(AND(F5="Main Primary Artist",SUBSTITUTE(E5," ","")<>"VariousArtists",SUBSTITUTE(E5," ","")<>"VariousArtist",E5<>"Various",SUBSTITUTE(E5," ","")<>"AssortedArtists",SUBSTITUTE(E5," ","")<>"AssortedArtist",E5<>"Assorted",SUBSTITUTE(E5," ","")<>"AsortedArtists",SUBSTITUTE(E5," ","")<>"AsortedArtist",E5<>"Asorted",E5<>"Other",,SUBSTITUTE(E5," ","")<>"MiscellaneousArtists",SUBSTITUTE(E5," ","")<>"MiscellaneousArtist",E5<>"Miscellaneous",SUBSTITUTE(E5," ","")<>"MiscelaneousArtists",SUBSTITUTE(E5," ","")<>"MiscelaneousArtist",E5<>"Miscelaneous"),"update Releases set ArtistId=(select ArtistId from Artists where Name=N'"&SUBSTITUTE(trim(E5),"'","''")&"' and EnterpriseId="&EntId&"), SearchKeywords=concat_ws(' ', Name, N'"&SUBSTITUTE(trim(E5),"'","''")&"',(select Name from Labels where LabelId=Releases.LabelId), ReleaseId, UPC, Catalog) where "&IF(A5<>"","UPC="&A5,"Catalog='"&SUBSTITUTE(trim(B5),"'","''")&"'")&" and EnterpriseId="&EntId,IF(and(F5<>"Main Primary Artist",SUBSTITUTE(E5," ","")<>"VariousArtists",SUBSTITUTE(E5," ","")<>"VariousArtist",E5<>"Various",SUBSTITUTE(E5," ","")<>"AssortedArtists",SUBSTITUTE(E5," ","")<>"AssortedArtist",E5<>"Assorted",SUBSTITUTE(E5," ","")<>"AsortedArtists",SUBSTITUTE(E5," ","")<>"AsortedArtist",E5<>"Asorted",E5<>"Other",,SUBSTITUTE(E5," ","")<>"MiscellaneousArtists",SUBSTITUTE(E5," ","")<>"MiscellaneousArtist",E5<>"Miscellaneous",SUBSTITUTE(E5," ","")<>"MiscelaneousArtists",SUBSTITUTE(E5," ","")<>"MiscelaneousArtist",E5<>"Miscelaneous"),"INSERT into Contributors VALUES (newid(), "&IF(F5<>"Primary Artist", "(select RoleId from ContributorRoles where Name='"&F5&"'), 0", "49, 1")& ", null, (select max(ReleaseId) from Releases where "&IF(A5<>"","UPC="&A5,"Catalog='"&SUBSTITUTE(trim(B5),"'","''")&"'")&" and EnterpriseId="&EntId&"), (select ArtistId from Artists where Name=N'"&SUBSTITUTE(trim(E5),"'","''")&"' and EnterpriseId="&EntId&"), null)","")) -> update Releases set ArtistId=(select ArtistId from Artists where Name=N'JKZ' and EnterpriseId=414849), SearchKeywords=concat_ws(' ', Name, N'JKZ',(select Name from Labels where LabelId=Releases.LabelId), ReleaseId, UPC, Catalog) where UPC=789294845633 and EnterpriseId=414849
A6: 789294845633 | C6: {=ifs(and(isblank($A6),isblank($B6)),"", not(iserror(vlookup($A6&$B6,'3) Release_Label'!$D:$D&'3) Release_Label'!$E:$E,1,0))),vlookup($A6&$B6,{'3) Release_Label'!$D:$D&'3) Release_Label'!$E:$E,'3) Release_Label'!$F:$F},2,0), or(and(not(isblank($B6)),$B6=$B5,$A6<>$A5),and(not(isblank($A6)),$A6=$A5,$B6<>$B5)),"ID LISTS UNALIGNED",and($A6<>"",countif('3) Release_Label'!$D:$D,$A6)=0),"NO UPC MATCH in Release_Label",and($B6<>"",countif('3) Release_Label'!$E:$E,$B6)=0),"NO CATALOG ID MATCH in Release_Label",iserror(vlookup($A6&$B6,'3) Release_Label'!$D:$D&'3) Release_Label'!$E:$E,1,0)),"NO UPC-CATALOG ID pair MATCH in Release_Label" )} -> Receba | D6: {=ifs(and(isblank($A6),isblank($B6)),"", not(iserror(vlookup($A6&$B6,'3) Release_Label'!$D:$D&'3) Release_Label'!$E:$E,1,0))),vlookup($A6&$B6,{'3) Release_Label'!$D:$D&'3) Release_Label'!$E:$E,'3) Release_Label'!$H:$H},2,0), or(and(not(isblank($B6)),$B6=$B5,$A6<>$A5),and(not(isblank($A6)),$A6=$A5,$B6<>$B5)),"ID LISTS UNALIGNED",and($A6<>"",countif('3) Release_Label'!$D:$D,$A6)=0),"NO UPC MATCH in Release_Label",and($B6<>"",countif('3) Release_Label'!$E:$E,$B6)=0),"NO CATALOG ID MATCH in Release_Label",iserror(vlookup($A6&$B6,'3) Release_Label'!$D:$D&'3) Release_Label'!$E:$E,1,0)),"NO UPC-CATALOG ID pair MATCH in Release_Label" )} -> Extended | E6: JKZ | F6: Producer | G6: {=ifs(or($F6="",$F6="Main Primary Artist"),$F6,not(iserror(vlookup($F6,'Reference info'!$J$5:$J$8,1,0))),"Key Artist",not(iserror(vlookup($F6,'Reference info'!$J$38:$J$405,1,0))),"Performer",not(iserror(vlookup($F6,'Reference info'!$J$10:$J$36,1,0))),"Producer & Engineer")} -> Producer & Engineer | H6: sort(if(countif($A$5:$A&$B$5:$B,'3) Release_Label'!$D$5:$D&'3) Release_Label'!$E$5:$E)=0,'3) Release_Label'!$D$5:$D&" "&'3) Release_Label'!$E$5:$E,)) | I6: =IF(AND(F6="Main Primary Artist",SUBSTITUTE(E6," ","")<>"VariousArtists",SUBSTITUTE(E6," ","")<>"VariousArtist",E6<>"Various",SUBSTITUTE(E6," ","")<>"AssortedArtists",SUBSTITUTE(E6," ","")<>"AssortedArtist",E6<>"Assorted",SUBSTITUTE(E6," ","")<>"AsortedArtists",SUBSTITUTE(E6," ","")<>"AsortedArtist",E6<>"Asorted",E6<>"Other",,SUBSTITUTE(E6," ","")<>"MiscellaneousArtists",SUBSTITUTE(E6," ","")<>"MiscellaneousArtist",E6<>"Miscellaneous",SUBSTITUTE(E6," ","")<>"MiscelaneousArtists",SUBSTITUTE(E6," ","")<>"MiscelaneousArtist",E6<>"Miscelaneous"),"update Releases set ArtistId=(select ArtistId from Artists where Name=N'"&SUBSTITUTE(trim(E6),"'","''")&"' and EnterpriseId="&EntId&"), SearchKeywords=concat_ws(' ', Name, N'"&SUBSTITUTE(trim(E6),"'","''")&"',(select Name from Labels where LabelId=Releases.LabelId), ReleaseId, UPC, Catalog) where "&IF(A6<>"","UPC="&A6,"Catalog='"&SUBSTITUTE(trim(B6),"'","''")&"'")&" and EnterpriseId="&EntId,IF(and(F6<>"Main Primary Artist",SUBSTITUTE(E6," ","")<>"VariousArtists",SUBSTITUTE(E6," ","")<>"VariousArtist",E6<>"Various",SUBSTITUTE(E6," ","")<>"AssortedArtists",SUBSTITUTE(E6," ","")<>"AssortedArtist",E6<>"Assorted",SUBSTITUTE(E6," ","")<>"AsortedArtists",SUBSTITUTE(E6," ","")<>"AsortedArtist",E6<>"Asorted",E6<>"Other",,SUBSTITUTE(E6," ","")<>"MiscellaneousArtists",SUBSTITUTE(E6," ","")<>"MiscellaneousArtist",E6<>"Miscellaneous",SUBSTITUTE(E6," ","")<>"MiscelaneousArtists",SUBSTITUTE(E6," ","")<>"MiscelaneousArtist",E6<>"Miscelaneous"),"INSERT into Contributors VALUES (newid(), "&IF(F6<>"Primary Artist", "(select RoleId from ContributorRoles where Name='"&F6&"'), 0", "49, 1")& ", null, (select max(ReleaseId) from Releases where "&IF(A6<>"","UPC="&A6,"Catalog='"&SUBSTITUTE(trim(B6),"'","''")&"'")&" and EnterpriseId="&EntId&"), (select ArtistId from Artists where Name=N'"&SUBSTITUTE(trim(E6),"'","''")&"' and EnterpriseId="&EntId&"), null)","")) -> INSERT into Contributors VALUES (newid(), (select RoleId from ContributorRoles where Name='Producer'), 0, null, (select max(ReleaseId) from Releases where UPC=789294845633 and EnterpriseId=414849), (select ArtistId from Artists where Name=N'JKZ' and EnterpriseId=414849), null)
A7: 789294845633 | C7: {=ifs(and(isblank($A7),isblank($B7)),"", not(iserror(vlookup($A7&$B7,'3) Release_Label'!$D:$D&'3) Release_Label'!$E:$E,1,0))),vlookup($A7&$B7,{'3) Release_Label'!$D:$D&'3) Release_Label'!$E:$E,'3) Release_Label'!$F:$F},2,0), or(and(not(isblank($B7)),$B7=$B6,$A7<>$A6),and(not(isblank($A7)),$A7=$A6,$B7<>$B6)),"ID LISTS UNALIGNED",and($A7<>"",countif('3) Release_Label'!$D:$D,$A7)=0),"NO UPC MATCH in Release_Label",and($B7<>"",countif('3) Release_Label'!$E:$E,$B7)=0),"NO CATALOG ID MATCH in Release_Label",iserror(vlookup($A7&$B7,'3) Release_Label'!$D:$D&'3) Release_Label'!$E:$E,1,0)),"NO UPC-CATALOG ID pair MATCH in Release_Label" )} -> Receba | D7: {=ifs(and(isblank($A7),isblank($B7)),"", not(iserror(vlookup($A7&$B7,'3) Release_Label'!$D:$D&'3) Release_Label'!$E:$E,1,0))),vlookup($A7&$B7,{'3) Release_Label'!$D:$D&'3) Release_Label'!$E:$E,'3) Release_Label'!$H:$H},2,0), or(and(not(isblank($B7)),$B7=$B6,$A7<>$A6),and(not(isblank($A7)),$A7=$A6,$B7<>$B6)),"ID LISTS UNALIGNED",and($A7<>"",countif('3) Release_Label'!$D:$D,$A7)=0),"NO UPC MATCH in Release_Label",and($B7<>"",countif('3) Release_Label'!$E:$E,$B7)=0),"NO CATALOG ID MATCH in Release_Label",iserror(vlookup($A7&$B7,'3) Release_Label'!$D:$D&'3) Release_Label'!$E:$E,1,0)),"NO UPC-CATALOG ID pair MATCH in Release_Label" )} -> Extended | E7: JKZ | F7: Engineer | G7: {=ifs(or($F7="",$F7="Main Primary Artist"),$F7,not(iserror(vlookup($F7,'Reference info'!$J$5:$J$8,1,0))),"Key Artist",not(iserror(vlookup($F7,'Reference info'!$J$38:$J$405,1,0))),"Performer",not(iserror(vlookup($F7,'Reference info'!$J$10:$J$36,1,0))),"Producer & Engineer")} -> Producer & Engineer | H7: sort(if(countif({A5:A,B5:B},{'3) Release_Label'!D5:D,'3) Release_Label'!E5:E})=0,{'3) Release_Label'!D5:D,'3) Release_Label'!E5:E},)) | I7: =IF(AND(F7="Main Primary Artist",SUBSTITUTE(E7," ","")<>"VariousArtists",SUBSTITUTE(E7," ","")<>"VariousArtist",E7<>"Various",SUBSTITUTE(E7," ","")<>"AssortedArtists",SUBSTITUTE(E7," ","")<>"AssortedArtist",E7<>"Assorted",SUBSTITUTE(E7," ","")<>"AsortedArtists",SUBSTITUTE(E7," ","")<>"AsortedArtist",E7<>"Asorted",E7<>"Other",,SUBSTITUTE(E7," ","")<>"MiscellaneousArtists",SUBSTITUTE(E7," ","")<>"MiscellaneousArtist",E7<>"Miscellaneous",SUBSTITUTE(E7," ","")<>"MiscelaneousArtists",SUBSTITUTE(E7," ","")<>"MiscelaneousArtist",E7<>"Miscelaneous"),"update Releases set ArtistId=(select ArtistId from Artists where Name=N'"&SUBSTITUTE(trim(E7),"'","''")&"' and EnterpriseId="&EntId&"), SearchKeywords=concat_ws(' ', Name, N'"&SUBSTITUTE(trim(E7),"'","''")&"',(select Name from Labels where LabelId=Releases.LabelId), ReleaseId, UPC, Catalog) where "&IF(A7<>"","UPC="&A7,"Catalog='"&SUBSTITUTE(trim(B7),"'","''")&"'")&" and EnterpriseId="&EntId,IF(and(F7<>"Main Primary Artist",SUBSTITUTE(E7," ","")<>"VariousArtists",SUBSTITUTE(E7," ","")<>"VariousArtist",E7<>"Various",SUBSTITUTE(E7," ","")<>"AssortedArtists",SUBSTITUTE(E7," ","")<>"AssortedArtist",E7<>"Assorted",SUBSTITUTE(E7," ","")<>"AsortedArtists",SUBSTITUTE(E7," ","")<>"AsortedArtist",E7<>"Asorted",E7<>"Other",,SUBSTITUTE(E7," ","")<>"MiscellaneousArtists",SUBSTITUTE(E7," ","")<>"MiscellaneousArtist",E7<>"Miscellaneous",SUBSTITUTE(E7," ","")<>"MiscelaneousArtists",SUBSTITUTE(E7," ","")<>"MiscelaneousArtist",E7<>"Miscelaneous"),"INSERT into Contributors VALUES (newid(), "&IF(F7<>"Primary Artist", "(select RoleId from ContributorRoles where Name='"&F7&"'), 0", "49, 1")& ", null, (select max(ReleaseId) from Releases where "&IF(A7<>"","UPC="&A7,"Catalog='"&SUBSTITUTE(trim(B7),"'","''")&"'")&" and EnterpriseId="&EntId&"), (select ArtistId from Artists where Name=N'"&SUBSTITUTE(trim(E7),"'","''")&"' and EnterpriseId="&EntId&"), null)","")) -> INSERT into Contributors VALUES (newid(), (select RoleId from ContributorRoles where Name='Engineer'), 0, null, (select max(ReleaseId) from Releases where UPC=789294845633 and EnterpriseId=414849), (select ArtistId from Artists where Name=N'JKZ' and EnterpriseId=414849), null)
A8: 789294962088 | C8: {=ifs(and(isblank($A8),isblank($B8)),"", not(iserror(vlookup($A8&$B8,'3) Release_Label'!$D:$D&'3) Release_Label'!$E:$E,1,0))),vlookup($A8&$B8,{'3) Release_Label'!$D:$D&'3) Release_Label'!$E:$E,'3) Release_Label'!$F:$F},2,0), or(and(not(isblank($B8)),$B8=$B7,$A8<>$A7),and(not(isblank($A8)),$A8=$A7,$B8<>$B7)),"ID LISTS UNALIGNED",and($A8<>"",countif('3) Release_Label'!$D:$D,$A8)=0),"NO UPC MATCH in Release_Label",and($B8<>"",countif('3) Release_Label'!$E:$E,$B8)=0),"NO CATALOG ID MATCH in Release_Label",iserror(vlookup($A8&$B8,'3) Release_Label'!$D:$D&'3) Release_Label'!$E:$E,1,0)),"NO UPC-CATALOG ID pair MATCH in Release_Label" )} -> A Cláusula do Contrato | D8: {=ifs(and(isblank($A8),isblank($B8)),"", not(iserror(vlookup($A8&$B8,'3) Release_Label'!$D:$D&'3) Release_Label'!$E:$E,1,0))),vlookup($A8&$B8,{'3) Release_Label'!$D:$D&'3) Release_Label'!$E:$E,'3) Release_Label'!$H:$H},2,0), or(and(not(isblank($B8)),$B8=$B7,$A8<>$A7),and(not(isblank($A8)),$A8=$A7,$B8<>$B7)),"ID LISTS UNALIGNED",and($A8<>"",countif('3) Release_Label'!$D:$D,$A8)=0),"NO UPC MATCH in Release_Label",and($B8<>"",countif('3) Release_Label'!$E:$E,$B8)=0),"NO CATALOG ID MATCH in Release_Label",iserror(vlookup($A8&$B8,'3) Release_Label'!$D:$D&'3) Release_Label'!$E:$E,1,0)),"NO UPC-CATALOG ID pair MATCH in Release_Label" )} | E8: Flash Beats Manow | F8: Main Primary Artist | G8: {=ifs(or($F8="",$F8="Main Primary Artist"),$F8,not(iserror(vlookup($F8,'Reference info'!$J$5:$J$8,1,0))),"Key Artist",not(iserror(vlookup($F8,'Reference info'!$J$38:$J$405,1,0))),"Performer",not(iserror(vlookup($F8,'Reference info'!$J$10:$J$36,1,0))),"Producer & Engineer")} -> Main Primary Artist | H8: =IFERROR(__xludf.DUMMYFUNCTION("sort(if(countif(filter($A:$B,$F:$F=""Main Primary Artist""),'3) Release_Label'!$D$5:$E520)=0,'3) Release_Label'!$D$5:$E520,))"),"#REF!") -> #REF! | I8: =IF(AND(F8="Main Primary Artist",SUBSTITUTE(E8," ","")<>"VariousArtists",SUBSTITUTE(E8," ","")<>"VariousArtist",E8<>"Various",SUBSTITUTE(E8," ","")<>"AssortedArtists",SUBSTITUTE(E8," ","")<>"AssortedArtist",E8<>"Assorted",SUBSTITUTE(E8," ","")<>"AsortedArtists",SUBSTITUTE(E8," ","")<>"AsortedArtist",E8<>"Asorted",E8<>"Other",,SUBSTITUTE(E8," ","")<>"MiscellaneousArtists",SUBSTITUTE(E8," ","")<>"MiscellaneousArtist",E8<>"Miscellaneous",SUBSTITUTE(E8," ","")<>"MiscelaneousArtists",SUBSTITUTE(E8," ","")<>"MiscelaneousArtist",E8<>"Miscelaneous"),"update Releases set ArtistId=(select ArtistId from Artists where Name=N'"&SUBSTITUTE(trim(E8),"'","''")&"' and EnterpriseId="&EntId&"), SearchKeywords=concat_ws(' ', Name, N'"&SUBSTITUTE(trim(E8),"'","''")&"',(select Name from Labels where LabelId=Releases.LabelId), ReleaseId, UPC, Catalog) where "&IF(A8<>"","UPC="&A8,"Catalog='"&SUBSTITUTE(trim(B8),"'","''")&"'")&" and EnterpriseId="&EntId,IF(and(F8<>"Main Primary Artist",SUBSTITUTE(E8," ","")<>"VariousArtists",SUBSTITUTE(E8," ","")<>"VariousArtist",E8<>"Various",SUBSTITUTE(E8," ","")<>"AssortedArtists",SUBSTITUTE(E8," ","")<>"AssortedArtist",E8<>"Assorted",SUBSTITUTE(E8," ","")<>"AsortedArtists",SUBSTITUTE(E8," ","")<>"AsortedArtist",E8<>"Asorted",E8<>"Other",,SUBSTITUTE(E8," ","")<>"MiscellaneousArtists",SUBSTITUTE(E8," ","")<>"MiscellaneousArtist",E8<>"Miscellaneous",SUBSTITUTE(E8," ","")<>"MiscelaneousArtists",SUBSTITUTE(E8," ","")<>"MiscelaneousArtist",E8<>"Miscelaneous"),"INSERT into Contributors VALUES (newid(), "&IF(F8<>"Primary Artist", "(select RoleId from ContributorRoles where Name='"&F8&"'), 0", "49, 1")& ", null, (select max(ReleaseId) from Releases where "&IF(A8<>"","UPC="&A8,"Catalog='"&SUBSTITUTE(trim(B8),"'","''")&"'")&" and EnterpriseId="&EntId&"), (select ArtistId from Artists where Name=N'"&SUBSTITUTE(trim(E8),"'","''")&"' and EnterpriseId="&EntId&"), null)","")) -> update Releases set ArtistId=(select ArtistId from Artists where Name=N'Flash Beats Manow' and EnterpriseId=414849), SearchKeywords=concat_ws(' ', Name, N'Flash Beats Manow',(select Name from Labels where LabelId=Releases.LabelId), ReleaseId, UPC, Catalog) where UPC=789294962088 and EnterpriseId=414849
A9: 789294962088 | C9: {=ifs(and(isblank($A9),isblank($B9)),"", not(iserror(vlookup($A9&$B9,'3) Release_Label'!$D:$D&'3) Release_Label'!$E:$E,1,0))),vlookup($A9&$B9,{'3) Release_Label'!$D:$D&'3) Release_Label'!$E:$E,'3) Release_Label'!$F:$F},2,0), or(and(not(isblank($B9)),$B9=$B8,$A9<>$A8),and(not(isblank($A9)),$A9=$A8,$B9<>$B8)),"ID LISTS UNALIGNED",and($A9<>"",countif('3) Release_Label'!$D:$D,$A9)=0),"NO UPC MATCH in Release_Label",and($B9<>"",countif('3) Release_Label'!$E:$E,$B9)=0),"NO CATALOG ID MATCH in Release_Label",iserror(vlookup($A9&$B9,'3) Release_Label'!$D:$D&'3) Release_Label'!$E:$E,1,0)),"NO UPC-CATALOG ID pair MATCH in Release_Label" )} -> A Cláusula do Contrato | D9: {=ifs(and(isblank($A9),isblank($B9)),"", not(iserror(vlookup($A9&$B9,'3) Release_Label'!$D:$D&'3) Release_Label'!$E:$E,1,0))),vlookup($A9&$B9,{'3) Release_Label'!$D:$D&'3) Release_Label'!$E:$E,'3) Release_Label'!$H:$H},2,0), or(and(not(isblank($B9)),$B9=$B8,$A9<>$A8),and(not(isblank($A9)),$A9=$A8,$B9<>$B8)),"ID LISTS UNALIGNED",and($A9<>"",countif('3) Release_Label'!$D:$D,$A9)=0),"NO UPC MATCH in Release_Label",and($B9<>"",countif('3) Release_Label'!$E:$E,$B9)=0),"NO CATALOG ID MATCH in Release_Label",iserror(vlookup($A9&$B9,'3) Release_Label'!$D:$D&'3) Release_Label'!$E:$E,1,0)),"NO UPC-CATALOG ID pair MATCH in Release_Label" )} | E9: Flash Beats Manow | F9: Producer | G9: {=ifs(or($F9="",$F9="Main Primary Artist"),$F9,not(iserror(vlookup($F9,'Reference info'!$J$5:$J$8,1,0))),"Key Artist",not(iserror(vlookup($F9,'Reference info'!$J$38:$J$405,1,0))),"Performer",not(iserror(vlookup($F9,'Reference info'!$J$10:$J$36,1,0))),"Producer & Engineer")} -> Producer & Engineer | I9: =IF(AND(F9="Main Primary Artist",SUBSTITUTE(E9," ","")<>"VariousArtists",SUBSTITUTE(E9," ","")<>"VariousArtist",E9<>"Various",SUBSTITUTE(E9," ","")<>"AssortedArtists",SUBSTITUTE(E9," ","")<>"AssortedArtist",E9<>"Assorted",SUBSTITUTE(E9," ","")<>"AsortedArtists",SUBSTITUTE(E9," ","")<>"AsortedArtist",E9<>"Asorted",E9<>"Other",,SUBSTITUTE(E9," ","")<>"MiscellaneousArtists",SUBSTITUTE(E9," ","")<>"MiscellaneousArtist",E9<>"Miscellaneous",SUBSTITUTE(E9," ","")<>"MiscelaneousArtists",SUBSTITUTE(E9," ","")<>"MiscelaneousArtist",E9<>"Miscelaneous"),"update Releases set ArtistId=(select ArtistId from Artists where Name=N'"&SUBSTITUTE(trim(E9),"'","''")&"' and EnterpriseId="&EntId&"), SearchKeywords=concat_ws(' ', Name, N'"&SUBSTITUTE(trim(E9),"'","''")&"',(select Name from Labels where LabelId=Releases.LabelId), ReleaseId, UPC, Catalog) where "&IF(A9<>"","UPC="&A9,"Catalog='"&SUBSTITUTE(trim(B9),"'","''")&"'")&" and EnterpriseId="&EntId,IF(and(F9<>"Main Primary Artist",SUBSTITUTE(E9," ","")<>"VariousArtists",SUBSTITUTE(E9," ","")<>"VariousArtist",E9<>"Various",SUBSTITUTE(E9," ","")<>"AssortedArtists",SUBSTITUTE(E9," ","")<>"AssortedArtist",E9<>"Assorted",SUBSTITUTE(E9," ","")<>"AsortedArtists",SUBSTITUTE(E9," ","")<>"AsortedArtist",E9<>"Asorted",E9<>"Other",,SUBSTITUTE(E9," ","")<>"MiscellaneousArtists",SUBSTITUTE(E9," ","")<>"MiscellaneousArtist",E9<>"Miscellaneous",SUBSTITUTE(E9," ","")<>"MiscelaneousArtists",SUBSTITUTE(E9," ","")<>"MiscelaneousArtist",E9<>"Miscelaneous"),"INSERT into Contributors VALUES (newid(), "&IF(F9<>"Primary Artist", "(select RoleId from ContributorRoles where Name='"&F9&"'), 0", "49, 1")& ", null, (select max(ReleaseId) from Releases where "&IF(A9<>"","UPC="&A9,"Catalog='"&SUBSTITUTE(trim(B9),"'","''")&"'")&" and EnterpriseId="&EntId&"), (select ArtistId from Artists where Name=N'"&SUBSTITUTE(trim(E9),"'","''")&"' and EnterpriseId="&EntId&"), null)","")) -> INSERT into Contributors VALUES (newid(), (select RoleId from ContributorRoles where Name='Producer'), 0, null, (select max(ReleaseId) from Releases where UPC=789294962088 and EnterpriseId=414849), (select ArtistId from Artists where Name=N'Flash Beats Manow' and EnterpriseId=414849), null)
A10: 789294962088 | C10: {=ifs(and(isblank($A10),isblank($B10)),"", not(iserror(vlookup($A10&$B10,'3) Release_Label'!$D:$D&'3) Release_Label'!$E:$E,1,0))),vlookup($A10&$B10,{'3) Release_Label'!$D:$D&'3) Release_Label'!$E:$E,'3) Release_Label'!$F:$F},2,0), or(and(not(isblank($B10)),$B10=$B9,$A10<>$A9),and(not(isblank($A10)),$A10=$A9,$B10<>$B9)),"ID LISTS UNALIGNED",and($A10<>"",countif('3) Release_Label'!$D:$D,$A10)=0),"NO UPC MATCH in Release_Label",and($B10<>"",countif('3) Release_Label'!$E:$E,$B10)=0),"NO CATALOG ID MATCH in Release_Label",iserror(vlookup($A10&$B10,'3) Release_Label'!$D:$D&'3) Release_Label'!$E:$E,1,0)),"NO UPC-CATALOG ID pair MATCH in Release_Label" )} -> A Cláusula do Contrato | D10: {=ifs(and(isblank($A10),isblank($B10)),"", not(iserror(vlookup($A10&$B10,'3) Release_Label'!$D:$D&'3) Release_Label'!$E:$E,1,0))),vlookup($A10&$B10,{'3) Release_Label'!$D:$D&'3) Release_Label'!$E:$E,'3) Release_Label'!$H:$H},2,0), or(and(not(isblank($B10)),$B10=$B9,$A10<>$A9),and(not(isblank($A10)),$A10=$A9,$B10<>$B9)),"ID LISTS UNALIGNED",and($A10<>"",countif('3) Release_Label'!$D:$D,$A10)=0),"NO UPC MATCH in Release_Label",and($B10<>"",countif('3) Release_Label'!$E:$E,$B10)=0),"NO CATALOG ID MATCH in Release_Label",iserror(vlookup($A10&$B10,'3) Release_Label'!$D:$D&'3) Release_Label'!$E:$E,1,0)),"NO UPC-CATALOG ID pair MATCH in Release_Label" )} | E10: Flash Beats Manow | F10: Engineer | G10: {=ifs(or($F10="",$F10="Main Primary Artist"),$F10,not(iserror(vlookup($F10,'Reference info'!$J$5:$J$8,1,0))),"Key Artist",not(iserror(vlookup($F10,'Reference info'!$J$38:$J$405,1,0))),"Performer",not(iserror(vlookup($F10,'Reference info'!$J$10:$J$36,1,0))),"Producer & Engineer")} -> Producer & Engineer | I10: =IF(AND(F10="Main Primary Artist",SUBSTITUTE(E10," ","")<>"VariousArtists",SUBSTITUTE(E10," ","")<>"VariousArtist",E10<>"Various",SUBSTITUTE(E10," ","")<>"AssortedArtists",SUBSTITUTE(E10," ","")<>"AssortedArtist",E10<>"Assorted",SUBSTITUTE(E10," ","")<>"AsortedArtists",SUBSTITUTE(E10," ","")<>"AsortedArtist",E10<>"Asorted",E10<>"Other",,SUBSTITUTE(E10," ","")<>"MiscellaneousArtists",SUBSTITUTE(E10," ","")<>"MiscellaneousArtist",E10<>"Miscellaneous",SUBSTITUTE(E10," ","")<>"MiscelaneousArtists",SUBSTITUTE(E10," ","")<>"MiscelaneousArtist",E10<>"Miscelaneous"),"update Releases set ArtistId=(select ArtistId from Artists where Name=N'"&SUBSTITUTE(trim(E10),"'","''")&"' and EnterpriseId="&EntId&"), SearchKeywords=concat_ws(' ', Name, N'"&SUBSTITUTE(trim(E10),"'","''")&"',(select Name from Labels where LabelId=Releases.LabelId), ReleaseId, UPC, Catalog) where "&IF(A10<>"","UPC="&A10,"Catalog='"&SUBSTITUTE(trim(B10),"'","''")&"'")&" and EnterpriseId="&EntId,IF(and(F10<>"Main Primary Artist",SUBSTITUTE(E10," ","")<>"VariousArtists",SUBSTITUTE(E10," ","")<>"VariousArtist",E10<>"Various",SUBSTITUTE(E10," ","")<>"AssortedArtists",SUBSTITUTE(E10," ","")<>"AssortedArtist",E10<>"Assorted",SUBSTITUTE(E10," ","")<>"AsortedArtists",SUBSTITUTE(E10," ","")<>"AsortedArtist",E10<>"Asorted",E10<>"Other",,SUBSTITUTE(E10," ","")<>"MiscellaneousArtists",SUBSTITUTE(E10," ","")<>"MiscellaneousArtist",E10<>"Miscellaneous",SUBSTITUTE(E10," ","")<>"MiscelaneousArtists",SUBSTITUTE(E10," ","")<>"MiscelaneousArtist",E10<>"Miscelaneous"),"INSERT into Contributors VALUES (newid(), "&IF(F10<>"Primary Artist", "(select RoleId from ContributorRoles where Name='"&F10&"'), 0", "49, 1")& ", null, (select max(ReleaseId) from Releases where "&IF(A10<>"","UPC="&A10,"Catalog='"&SUBSTITUTE(trim(B10),"'","''")&"'")&" and EnterpriseId="&EntId&"), (select ArtistId from Artists where Name=N'"&SUBSTITUTE(trim(E10),"'","''")&"' and EnterpriseId="&EntId&"), null)","")) -> INSERT into Contributors VALUES (newid(), (select RoleId from ContributorRoles where Name='Engineer'), 0, null, (select max(ReleaseId) from Releases where UPC=789294962088 and EnterpriseId=414849), (select ArtistId from Artists where Name=N'Flash Beats Manow' and EnterpriseId=414849), null)
G11: {=ifs(or($F11="",$F11="Main Primary Artist"),$F11,not(iserror(vlookup($F11,'Reference info'!$J$5:$J$8,1,0))),"Key Artist",not(iserror(vlookup($F11,'Reference info'!$J$38:$J$405,1,0))),"Performer",not(iserror(vlookup($F11,'Reference info'!$J$10:$J$36,1,0))),"Producer & Engineer")}
G12: {=ifs(or($F12="",$F12="Main Primary Artist"),$F12,not(iserror(vlookup($F12,'Reference info'!$J$5:$J$8,1,0))),"Key Artist",not(iserror(vlookup($F12,'Reference info'!$J$38:$J$405,1,0))),"Performer",not(iserror(vlookup($F12,'Reference info'!$J$10:$J$36,1,0))),"Producer & Engineer")}
G13: {=ifs(or($F13="",$F13="Main Primary Artist"),$F13,not(iserror(vlookup($F13,'Reference info'!$J$5:$J$8,1,0))),"Key Artist",not(iserror(vlookup($F13,'Reference info'!$J$38:$J$405,1,0))),"Performer",not(iserror(vlookup($F13,'Reference info'!$J$10:$J$36,1,0))),"Producer & Engineer")}
G14: {=ifs(or($F14="",$F14="Main Primary Artist"),$F14,not(iserror(vlookup($F14,'Reference info'!$J$5:$J$8,1,0))),"Key Artist",not(iserror(vlookup($F14,'Reference info'!$J$38:$J$405,1,0))),"Performer",not(iserror(vlookup($F14,'Reference info'!$J$10:$J$36,1,0))),"Producer & Engineer")}
G15: {=ifs(or($F15="",$F15="Main Primary Artist"),$F15,not(iserror(vlookup($F15,'Reference info'!$J$5:$J$8,1,0))),"Key Artist",not(iserror(vlookup($F15,'Reference info'!$J$38:$J$405,1,0))),"Performer",not(iserror(vlookup($F15,'Reference info'!$J$10:$J$36,1,0))),"Producer & Engineer")}
G16: {=ifs(or($F16="",$F16="Main Primary Artist"),$F16,not(iserror(vlookup($F16,'Reference info'!$J$5:$J$8,1,0))),"Key Artist",not(iserror(vlookup($F16,'Reference info'!$J$38:$J$405,1,0))),"Performer",not(iserror(vlookup($F16,'Reference info'!$J$10:$J$36,1,0))),"Producer & Engineer")}
G17: {=ifs(or($F17="",$F17="Main Primary Artist"),$F17,not(iserror(vlookup($F17,'Reference info'!$J$5:$J$8,1,0))),"Key Artist",not(iserror(vlookup($F17,'Reference info'!$J$38:$J$405,1,0))),"Performer",not(iserror(vlookup($F17,'Reference info'!$J$10:$J$36,1,0))),"Producer & Engineer")}
G18: {=ifs(or($F18="",$F18="Main Primary Artist"),$F18,not(iserror(vlookup($F18,'Reference info'!$J$5:$J$8,1,0))),"Key Artist",not(iserror(vlookup($F18,'Reference info'!$J$38:$J$405,1,0))),"Performer",not(iserror(vlookup($F18,'Reference info'!$J$10:$J$36,1,0))),"Producer & Engineer")}
G19: {=ifs(or($F19="",$F19="Main Primary Artist"),$F19,not(iserror(vlookup($F19,'Reference info'!$J$5:$J$8,1,0))),"Key Artist",not(iserror(vlookup($F19,'Reference info'!$J$38:$J$405,1,0))),"Performer",not(iserror(vlookup($F19,'Reference info'!$J$10:$J$36,1,0))),"Producer & Engineer")}
G20: {=ifs(or($F20="",$F20="Main Primary Artist"),$F20,not(iserror(vlookup($F20,'Reference info'!$J$5:$J$8,1,0))),"Key Artist",not(iserror(vlookup($F20,'Reference info'!$J$38:$J$405,1,0))),"Performer",not(iserror(vlookup($F20,'Reference info'!$J$10:$J$36,1,0))),"Producer & Engineer")}
G21: {=ifs(or($F21="",$F21="Main Primary Artist"),$F21,not(iserror(vlookup($F21,'Reference info'!$J$5:$J$8,1,0))),"Key Artist",not(iserror(vlookup($F21,'Reference info'!$J$38:$J$405,1,0))),"Performer",not(iserror(vlookup($F21,'Reference info'!$J$10:$J$36,1,0))),"Producer & Engineer")}
G22: {=ifs(or($F22="",$F22="Main Primary Artist"),$F22,not(iserror(vlookup($F22,'Reference info'!$J$5:$J$8,1,0))),"Key Artist",not(iserror(vlookup($F22,'Reference info'!$J$38:$J$405,1,0))),"Performer",not(iserror(vlookup($F22,'Reference info'!$J$10:$J$36,1,0))),"Producer & Engineer")}
... G89: {=ifs(or($F89="",$F89="Main Primary Artist"),$F89,not(iserror(vlookup($F89,'Reference info'!$J$5:$J$8,1,0))),"Key Artist",not(iserror(vlookup($F89,'Reference info'!$J$38:$J$405,1,0))),"Performer",not(iserror(vlookup($F89,'Reference info'!$J$10:$J$36,1,0))),"Producer & Engineer")}

Sheet 5) Release_Track
A1: =IFERROR(__xludf.DUMMYFUNCTION("COUNTUNIQUE(A5:A617)-'3) Release_Label'!D1"),0.0) -> 0 | B1: =IFERROR(__xludf.DUMMYFUNCTION("COUNTUNIQUE(B5:B617)-'3) Release_Label'!E1"),0.0) -> 0 | C1: = FILLED AUTOMATICALLY IF CODES/IDS MATCH | E1: =count(E5:E617) -> 2 | F1: =IFERROR(__xludf.DUMMYFUNCTION("COUNTUNIQUE(F5:F617)"),2.0) -> 2 | G1: =IFERROR(__xludf.DUMMYFUNCTION("COUNTUNIQUE(G5:G617)"),0.0) -> 0 | H1: = READ NOTES / INSTRUCTIONS | I1: = OPTIONAL | J1: = REQUIRED FIELD | M1: =IFERROR(__xludf.DUMMYFUNCTION("COUNTUNIQUE(M5:M617)"),2.0) -> 2 | N1: =COUNTA(N5:N617) -> 2
A2: TRACK LEVEL - UPC/ID<>ISRC/ID
A3: UPC / EAN / JAN | B3: CATALOG RELEASE ID | C3: RELEASE TITLE | D3: RELEASE VERSION | E3: TRACK | F3: ISRC/vISRC | G3: CATALOG TRACK ID | H3: TRACK TITLE | I3: TRACK VERSION | J3: LANGUAGE OF LYRICS | K3: EXPLICIT | L3: TYPE | M3: AUDIO FILE URL | N3: AUDIO TYPE | O3: TRACK PREVIEW | P3: COMPOSITION ISWC
A4: from Release_Label tab | B4: from Release_Label tab | C4: auto-fills if Release Code/Id matches Code/Id in Release_Label tab | E4: NUMBER | F4: CCXXXYY##### blank if no ISRC yet | G4: Internal Ref. ID required if no ISRC/vISRC | H4: Written EXACTLY as per label copy (no version, type or contributor info) | I4: If applicable | J4: (select from list, start typing or drag) If no lyrics, select Instrumental | K4: YES / NO | L4: Original / Public Domain | M4: public URL MUST trigger audio file DOWNLOAD | N4: wav / flac ONLY | O4: Preview Start Time (in seconds)
A5: 789294845633 | C5: {=ifs(and(isblank($A5),isblank($B5)),"", not(iserror(vlookup($A5&$B5,'3) Release_Label'!$D:$D&'3) Release_Label'!$E:$E,1,0))),vlookup($A5&$B5,{'3) Release_Label'!$D:$D&'3) Release_Label'!$E:$E,'3) Release_Label'!$F:$F},2,0), or(and(not(isblank($B5)),$B5=#REF!,$A5<>#REF!),and(not(isblank($A5)),$A5=#REF!,$B5<>#REF!)),"ID LISTS UNALIGNED",and($A5<>"",countif('3) Release_Label'!$D:$D,$A5)=0),"NO UPC MATCH in Release_Label",and($B5<>"",countif('3) Release_Label'!$E:$E,$B5)=0),"NO CATALOG ID MATCH in Release_Label",iserror(vlookup($A5&$B5,'3) Release_Label'!$D:$D&'3) Release_Label'!$E:$E,1,0)),"NO UPC-CATALOG ID pair MATCH in Release_Label" )} -> Receba | D5: {=ifs(and(isblank($A5),isblank($B5)),"", not(iserror(vlookup($A5&$B5,'3) Release_Label'!$D:$D&'3) Release_Label'!$E:$E,1,0))),vlookup($A5&$B5,{'3) Release_Label'!$D:$D&'3) Release_Label'!$E:$E,'3) Release_Label'!$H:$H},2,0), or(and(not(isblank($B5)),$B5=#REF!,$A5<>#REF!),and(not(isblank($A5)),$A5=#REF!,$B5<>#REF!)),"ID LISTS UNALIGNED",and($A5<>"",countif('3) Release_Label'!$D:$D,$A5)=0),"NO UPC MATCH in Release_Label",and($B5<>"",countif('3) Release_Label'!$E:$E,$B5)=0),"NO CATALOG ID MATCH in Release_Label",iserror(vlookup($A5&$B5,'3) Release_Label'!$D:$D&'3) Release_Label'!$E:$E,1,0)),"NO UPC-CATALOG ID pair MATCH in Release_Label" )} -> Extended | E5: =if(and(isblank($A5),isblank($B5)),"",if(not(iserror(find("MATCH in ",D5))),D5,if(or(and(not(isblank($B5)),$B5=$B4,$A5<>$A4),and(not(isblank($A5)),$A5=$A4,$B5<>$B4)),"ID LISTS UNALIGNED",if(not(isblank($A5)),if($A5=$A4,1+E4,1),if($B5=$B4,1+E4,1))))) -> 1 | F5: QZW9M2221000 | H5: Receba | I5: Extended | J5: Portuguese | K5: NO | L5: Original | M5: https://www.dropbox.com/scl/fi/sjv55c5eqq0utzgy15ojq/Joy-Mejia-Amarte-Es-Mi-Pasatiempo.wav?rlkey=6j5ruxil4gc3vxonuf8ownxvi&st=8kysye3f&dl=1 | N5: flac | O5: 140 | P5: 12345 | R5: =if(OR(M5="",Q5>1),"","insert into AudioFiles VALUES (NEWID(),'"&if(G5="",F5&"."&N5,G5&"."&N5)&"', '."&N5&"', getdate(), null, 0, null, '"&SUBSTITUTE(trim(M5),"'","''")&"', 0, null, null, null, null)") -> insert into AudioFiles VALUES (NEWID(),'QZW9M2221000.flac', '.flac', getdate(), null, 0, null, 'https://www.dropbox.com/scl/fi/sjv55c5eqq0utzgy15ojq/Joy-Mejia-Amarte-Es-Mi-Pasatiempo.wav?rlkey=6j5ruxil4gc3vxonuf8ownxvi&st=8kysye3f&dl=1', 0, null, null, null, null) | S5: ="Insert into Tracks VALUES(N'"&SUBSTITUTE(trim(H5),"'","''")&"', 371631, "&if(not(ISBLANK(A5)),"(select LabelId from Releases where UPC="&A5&" and EnterpriseId="&EntId&")","(select LabelId from Releases where Catalog='"&SUBSTITUTE(trim(B5),"'","''")&"' and EnterpriseId="&EntId&")")&", "&if(F5="", "null", "'"&F5&"'")&", "&if(I5="", "null","N'"&SUBSTITUTE(trim(I5),"'","''")&"'")&", null, null, "&if(G5="", "null","'"&SUBSTITUTE(trim(G5),"'","''")&"'")&", null, null, null, "&if(M5="","null",if(G5="","(select AudioId from AudioFiles where Filename='"&F5&".wav' and ExternalUrl='"&SUBSTITUTE(trim(M5),"'","''")&"' and IsDownloadedFromExternalUrl=0)","(select AudioId from AudioFiles where Filename='"&G5&".wav' and ExternalUrl='"&SUBSTITUTE(trim(M5),"'","''")&"' and IsDownloadedFromExternalUrl=0)"))&", null, null, null, (select min(LanguageId) from Languages where LanguageName='"&J5&"' and IsValidMetadataLanguage=1), null, "&if(K5="YES", 1,0)&", getdate(), (select CreatedBy from Enterprises where EnterpriseId="&EntId&"), null, '34F4C88E-B410-461E-AD75-6C01536FDCD3', null, 0, null, null, null, null, "&if(M5="","null",if(G5="","(select AudioId from AudioFiles where Filename='"&F5&".flac' and ExternalUrl='"&SUBSTITUTE(trim(M5),"'","''")&"' and IsDownloadedFromExternalUrl=0)","(select AudioId from AudioFiles where Filename='"&G5&".flac' and ExternalUrl='"&SUBSTITUTE(trim(M5),"'","''")&"' and IsDownloadedFromExternalUrl=0)"))&", null, null, null, null, null, "&if(not(ISBLANK(A5)),"(select PrimaryMusicStyleId from Releases where UPC="&A5&" and EnterpriseId="&EntId&")","(select PrimaryMusicStyleId from Releases where Catalog='"&SUBSTITUTE(trim(B5),"'","''")&"' and EnterpriseId="&EntId&")")&", "&if(not(ISBLANK(A5)),"(select SecondaryMusicStyleId from Releases where UPC="&A5&" and EnterpriseId="&EntId&")","(select SecondaryMusicStyleId from Releases where Catalog='"&SUBSTITUTE(trim(B5),"'","''")&"' and EnterpriseId="&EntId&")")&", "&IF(O5="","null",O5)&", 0, null, (select id from internal_TrackTypes where description='"&L5&"'), null, null, null, null, (NEXT VALUE FOR [AssetIdSequence]), null, "&TenantId&", "&EntId&", "&if(F5<>"",countif(F$5:F5,F5),countif(G$5:G5,G5))&"); insert into Releases_Tracks values ( (select ReleaseId from Releases where "&if(not(ISBLANK(A5)),"UPC="&A5,"Catalog='"&SUBSTITUTE(trim(B5),"'","''")&"'")&" and EnterpriseId="&EntId&"), (select max(TrackId) from Tracks where "&if(trim(G5)="","ISRC='"&F5&"'","TrackVendorId='"&SUBSTITUTE(trim(G5),"'","''")&"'") &" and EnterpriseId="&EntId&"), "&E5&", (NEXT VALUE FOR [AssetIdSequence]), null); update Releases_Tracks set RevelatorExternalUsageTrackId=AssetId where TrackId=(select max(TrackId) from Tracks where "&IF(F5="","TrackVendorId='"&G5&"'","ISRC='"&F5&"'")&" and EnterpriseId="&EntId&"); Insert into TrackRecordingVersions values ((select max(TrackId) from Tracks where "&IF(F5="","TrackVendorId='"&G5&"'","ISRC='"&F5&"'")&" and EnterpriseId="&EntId&"), "&IF(F5="","null","'"&F5&"'")&", 1, getdate()); Insert into TrackRecordingVersionsAudioFiles values ((select max(TrackRecordingVersionId) from TrackRecordingVersions where TrackId in (select max(TrackId) from Tracks where "&IF(F5="","TrackVendorId='"&G5&"'","ISRC='"&F5&"'")&" and EnterpriseId="&EntId&")), "&if(M5="","null",if(G5="","(select AudioId from AudioFiles where Filename='"&F5&"."&N5&"' and ExternalUrl='"&SUBSTITUTE(trim(M5),"'","''")&"' and IsDownloadedFromExternalUrl=0)","(select AudioId from AudioFiles where Filename='"&G5&"."&N5&"' and ExternalUrl='"&SUBSTITUTE(trim(M5),"'","''")&"' and IsDownloadedFromExternalUrl=0)"))&", "&IFS(N5="","null",N5="wav","1",N5="flac","2")&"); Insert into Track_TrackProperties values ((select max(TrackId) from Tracks where "&IF(F5="","TrackVendorId='"&G5&"'","ISRC='"&F5&"'")&" and EnterpriseId="&EntId&"),1);" -> Insert into Tracks VALUES(N'Receba', 371631, (select LabelId from Releases where UPC=789294845633 and EnterpriseId=414849), 'QZW9M2221000', N'Extended', null, null, null, null, null, null, (select AudioId from AudioFiles where Filename='QZW9M2221000.wav' and ExternalUrl='https://www.dropbox.com/scl/fi/sjv55c5eqq0utzgy15ojq/Joy-Mejia-Amarte-Es-Mi-Pasatiempo.wav?rlkey=6j5ruxil4gc3vxonuf8ownxvi&st=8kysye3f&dl=1' and IsDownloadedFromExternalUrl=0), null, null, null, (select min(LanguageId) from Languages where LanguageName='Portuguese' and IsValidMetadataLanguage=1), null, 0, getdate(), (select CreatedBy from Enterprises where EnterpriseId=414849), null, '34F4C88E-B410-461E-AD75-6C01536FDCD3', null, 0, null, null, null, null, (select AudioId from AudioFiles where Filename='QZW9M2221000.flac' and ExternalUrl='https://www.dropbox.com/scl/fi/sjv55c5eqq0utzgy15ojq/Joy-Mejia-Amarte-Es-Mi-Pasatiempo.wav?rlkey=6j5ruxil4gc3vxonuf8ownxvi&st=8kysye3f&dl=1' and IsDownloadedFromExternalUrl=0), null, null, null, null, null, (select PrimaryMusicStyleId from Releases where UPC=789294845633 and EnterpriseId=414849), (select SecondaryMusicStyleId from Releases where UPC=789294845633 and EnterpriseId=414849), 140, 0, null, (select id from internal_TrackTypes where description='Original'), null, null, null, null, (NEXT VALUE FOR [AssetIdSequence]), null, 332920, 414849, 1); insert into Releases_Tracks values ( (select ReleaseId from Releases where UPC=789294845633 and EnterpriseId=414849), (select max(TrackId) from Tracks where ISRC='QZW9M2221000' and EnterpriseId=414849), 1, (NEXT VALUE FOR [AssetIdSequence]), null); update Releases_Tracks set RevelatorExternalUsageTrackId=AssetId where TrackId=(select max(TrackId) from Tracks where ISRC='QZW9M2221000' and EnterpriseId=414849); Insert into TrackRecordingVersions values ((select max(TrackId) from Tracks where ISRC='QZW9M2221000' and EnterpriseId=414849), 'QZW9M2221000', 1, getdate()); Insert into TrackRecordingVersionsAudioFiles values ((select max(TrackRecordingVersionId) from TrackRecordingVersions where TrackId in (select max(TrackId) from Tracks where ISRC='QZW9M2221000' and EnterpriseId=414849)), (select AudioId from AudioFiles where Filename='QZW9M2221000.flac' and ExternalUrl='https://www.dropbox.com/scl/fi/sjv55c5eqq0utzgy15ojq/Joy-Mejia-Amarte-Es-Mi-Pasatiempo.wav?rlkey=6j5ruxil4gc3vxonuf8ownxvi&st=8kysye3f&dl=1' and IsDownloadedFromExternalUrl=0), 2); Insert into Track_TrackProperties values ((select max(TrackId) from Tracks where ISRC='QZW9M2221000' and EnterpriseId=414849),1); | U5: =VLOOKUP(F5,'6) Track_Artist(s)'!A:A,1,0) -> QZW9M2221000
