Workbook
Name Country: 'Reference info'!$T$3:$T$257
Name EntId: '1) Artists list'!$H$1
Name CompContributor: '7) Comp ContributorPublisher li'!$A$5:$A$1001
Name TrackProperties: 'Reference info'!$R$3:$R$10
Name ReleaseType: 'Reference info'!$G$3:$G$7
Name Language: 'Reference info'!$K$3:$K$418
Name Publishing: 'Reference info'!$O$3:$O$5
Name ArtistRole: 'Reference info'!$J$3:$J$429
Name CompositionRole: 'Reference info'!$Q$3:$Q$14
Name Label: '2) Labels list'!$A$5:$A$999
Name Genre: 'Reference info'!$H$3:$H$419
Name Publisher: '7) Comp ContributorPublisher li'!$G$5:$G$1001
Name Artist: '1) Artists list'!$A$5:$A$999
Name TenantId: '1) Artists list'!$J$2

Sheet Introduction
B1: INTRODUCTION
A2: 1) | B2: Please make a copy of the master document in order to start filling it out. Make a copy by going to: File > Make a copy
A3: 2) | B3: Rename this document by replacing "MASTER" with your company name.
A4: 3) | B4: Share it with kenny@revelator.com, milan@revelator.com and nicolas.g@revelator.com and provide FULL Edit permissions across the worksheet:
B5: go to Data>Protected sheets and ranges>Show all protected ranges>Change permissions to full editing across ALL protected ranges from tabs 1 to 9
B7: You can also add anyone else from your team as needed.
B9: • Please fill out the catalog insert tabs enumerated in this spreadsheet by following the instructions in the corresponding fields and reading any applicable notes throughout
B10: • A black triangle in the top right corner of a cell means that there is a note — mouse over it to read it
B11: • If you are importing catalog metadata for reporting purposes only, then you only need to complete fields marked as REQUIRED as well as any UPC/ISRC or ID fields through tab 6
B13: Use the 'Sample Data' tab for additional guidance
B15: NOTE: Batch importing new catalog from the worksheet is generally not available on an ongoing basis so be sure all releases and tracks for import are included in the worksheet beforehand.
B16: After the initial import, adding catalog is meant to be done from the frontend of your account (or with the API if you are on an API plan). There are liable to be additional fees if the worksheet is to be used for new catalog after the initial import.
B18: • We DO NOT support importing files from Google Drive
B21: NO DSP sale reports should be uploaded and reporting feeds should NOT be set up until the account's catalog has been finalized, which includes the following steps:
B22: • ALL EXISTING catalog content has been imported
B23: • ALL catalog Delivery/Ingestion FEEDS have been DISABLED
... B30: • Delete ALL error matching rules

Sheet 1) Artists list
A1: =IFERROR(__xludf.DUMMYFUNCTION("COUNTUNIQUE(A5:A999)-if(COUNTIF('4) Release_Artist(s)'!E:E, ""Various Artists"")>0,0,1)"),2.0) -> 2 | B1: List all Artists to Import | C1: =IFERROR(__xludf.DUMMYFUNCTION("COUNTUNIQUE(C5:C999)"),2.0) -> 2 | D1: =IFERROR(__xludf.DUMMYFUNCTION("COUNTUNIQUE(D5:D999)"),2.0) -> 2 | E1: =IFERROR(__xludf.DUMMYFUNCTION("COUNTUNIQUE(E5:E999)"),2.0) -> 2 | F1: =IFERROR(__xludf.DUMMYFUNCTION("COUNTUNIQUE(F5:F999)"),0.0) -> 0 | G1: =IFERROR(__xludf.DUMMYFUNCTION("COUNTUNIQUE(G5:G999)"),1.0) -> 1 | H1: =IFERROR(__xludf.DUMMYFUNCTION("COUNTUNIQUE(B5:B999)"),2.0) -> 2 | I1: EnterpriseId= | J1: 691097
A2: = REQUIRED FIELD | B2: = OPTIONAL FIELD | D2: = READ NOTES / INSTRUCTIONS | F2: = OPTIONAL FIELD | H2: =countif(B5:B999,"<>""")-countif(B5:B999,"") -> 2 | I2: TenantId= | J2: 332920
A3: Artist Name | B3: Artist Image url | C3: Apple ArtistId | D3: Spotify Artist URI | E3: Meta ArtistId | F3: SoundCloud ProfileId | G3: ISNI | I3: Duplicate Names
A4: Written EXACTLY as per label copy | B4: public URL triggering DIRECT DOWNLOAD of file | C4: Enter Artist's AppleId or 'NEW'=new AppleId | D4: Enter Artist's Spotify URI link or 'NEW'=new Spotify URI link | E4: Facebook Audio Library & Rights Manager ArtistId | F4: SoundCloud Artist Username | I4: =IFERROR(__xludf.DUMMYFUNCTION("counta(A5:A999)-COUNTUNIQUE(A5:A999)"),0.0) -> 0
A5: JKZTest | B5: https://www.dropbox.com/scl/fi/7safoetk4p2k4vwi29k4c/Receba-789294845633-UPC.jpg?rlkey=3vty6hb78ol10iv3y6h4md8h3&st=m30ox0p4&dl=1 | C5: 1532352644 | D5: spotify:artist:1Gn8eEXtOWHA7XU8wEWXOb | E5: 697315585919469 | G5: 0000000121032683 | I5: =IFERROR(__xludf.DUMMYFUNCTION("if(B5="""","""",""insert into Images VALUES (NEWID(),'""&REGEXREPLACE(A5,""[^[:alnum:]]"","""")&EntId&H5&""', '""&H5&""', getdate(), 0, null, '""&trim(B5)&""', 0, getdate(), null, null)"")"),"insert into Images VALUES (NEWID(),'JKZTest2', '', getdate(), 0, null, 'https://www.dropbox.com/scl/fi/7safoetk4p2k4vwi29k4c/Receba-789294845633-UPC.jpg?rlkey=3vty6hb78ol10iv3y6h4md8h3&st=m30ox0p4&dl=1', 0, getdate(), null, null)") -> insert into Images VALUES (NEWID(),'JKZTest2', '', getdate(), 0, null, 'https://www.dropbox.com/scl/fi/7safoetk4p2k4vwi29k4c/Receba-789294845633-UPC.jpg?rlkey=3vty6hb78ol10iv3y6h4md8h3&st=m30ox0p4&dl=1', 0, getdate(), null, null)
A6: Flash Beats ManowTest | B6: https://www.dropbox.com/scl/fi/wky0ryb739s0xs3wo5qop/A-Cl-usula-do-Contrato-789294962088-UPC.jpg?rlkey=91bp85llgb8ho5lnfcs56105s&st=dn12pxrd&dl=1 | C6: 1601139620 | D6: spotify:artist:0ZIlwtVZkqtMZUpbHrz8TL | E6: 697315585919468
A999: Various Artists

Sheet 2) Labels list
A1: List all Labels to Import | B1: =IFERROR(__xludf.DUMMYFUNCTION("COUNTUNIQUE(A5:A999)"),2.0) -> 2
A2: = REQUIRED FIELD | B2: Duplicate Names
A3: Label Name | B3: =IFERROR(__xludf.DUMMYFUNCTION("counta(A5:A999)-COUNTUNIQUE(A5:A999)"),0.0) -> 0
A4: Written EXACTLY as per label copy
A5: TokyoRecordsFULLTEST
A6: PEJOTA10*FULLTEST

Sheet 3) Release_Label
A1: =IFERROR(__xludf.DUMMYFUNCTION("COUNTUNIQUE(A5:A1005)"),2.0) -> 2 | B1: = REQUIRED FIELD | C1: =IFERROR(__xludf.DUMMYFUNCTION("COUNTUNIQUE(B5:B1005)"),2.0) -> 2 | D1: =IFERROR(__xludf.DUMMYFUNCTION("COUNTUNIQUE(D5:D1005)"),2.0) -> 2 | E1: =IFERROR(__xludf.DUMMYFUNCTION("COUNTUNIQUE(E5:E1005)"),0.0) -> 0 | F1: = READ NOTES / INSTRUCTIONS | G1: =COUNTA(F5:F1005) -> 2 | H1: = OPTIONAL | I1: =countif(I5:I1005,"Video")+countif(I5:I1005,"Ringtone") -> 0 | M1: = REQUIRED FIELD | N1: = OPTIONAL
A2: RELEASE LEVEL - Label<>UPC/ID
A3: LABEL | B3: COVER IMAGE URL | C3: IMAGE TYPE | D3: UPC / EAN / JAN | E3: CATALOG RELEASE ID | F3: RELEASE TITLE | G3: TITLE LANGUAGE | H3: RELEASE VERSION | I3: RELEASE TYPE | J3: (P) Copyright | L3: (C) Copyright | N3: ORIGINAL RELEASE DATE | O3: GENRE 1 | P3: GENRE 2
A4: (select from Labels list, start typing or drag) | B4: public URL triggering DIRECT DOWNLOAD of file (10 MB max) required if distributing content | C4: jpeg / jpg ONLY | D4: UPC: 12 digits EAN: 13 digits blank if no code yet | E4: Internal Ref. ID required if no code yet | F4: Written EXACTLY as per label copy (no version, type or contributor info) | G4: (select from list, start typing or drag) | H4: If applicable | I4: (select from list, start typing or drag) | J4: Year | K4: Holder | L4: Year | M4: Holder | N4: YYYY-MM-DD | O4: (select from list, start typing or drag) | P4: (select from list, start typing or drag)
A5: TokyoRecordsFULLTEST | B5: https://www.dropbox.com/scl/fi/7safoetk4p2k4vwi29k4c/Receba-789294845633-UPC.jpg?rlkey=3vty6hb78ol10iv3y6h4md8h3&st=m30ox0p4&dl=1 | C5: jpg | D5: 789294845633 | F5: Receba | G5: Portuguese | H5: Extended | I5: Single | J5: 2022 | K5: TokyoP | L5: 2022 | M5: TokyoC | N5: 44886 | O5: Hip Hop/Rap | P5: African Reggae
A6: PEJOTA10*FULLTEST | B6: https://www.dropbox.com/scl/fi/wky0ryb739s0xs3wo5qop/A-Cl-usula-do-Contrato-789294962088-UPC.jpg?rlkey=91bp85llgb8ho5lnfcs56105s&st=dn12pxrd&dl=1 | C6: jpg | D6: 789294962088 | F6: A Cláusula do Contrato | G6: Portuguese | I6: Single | J6: 2022 | K6: PEJOTAP | L6: 2022 | M6: PEJOTAC | N6: 44889 | O6: Hip Hop/Rap | P6: African Reggae

Sheet 4) Release_Artist(s)
A1: =IFERROR(__xludf.DUMMYFUNCTION("COUNTUNIQUE(A5:A1006)-'3) Release_Label'!D1"),0.0) -> 0 | B1: =IFERROR(__xludf.DUMMYFUNCTION("COUNTUNIQUE(B5:B1006)-'3) Release_Label'!E1"),0.0) -> 0 | C1: = FILLED AUTOMATICALLY IF CODES/IDS MATCH | E1: =IFERROR(__xludf.DUMMYFUNCTION("COUNTUNIQUE(E5:E1006)"),2.0) -> 2 | F1: = REQUIRED FIELD | G1: =countif(F:F,"Main Primary Artist")-'3) Release_Label'!G1 -> 0 | H1: = READ NOTES / INSTRUCTIONS
A2: RELEASE LEVEL - Artist<>UPC/ID : One Arist per row. If a Release has multiple Artists, add the same Release Code/ID to a new row for each Artist.
A3: UPC / EAN / JAN | B3: CATALOG RELEASE ID | C3: RELEASE TITLE | D3: RELEASE VERSION | E3: ARTIST | F3: ARTIST ROLE | G3: ARTIST ROLE CATEGORY | H3: =IFERROR(__xludf.DUMMYFUNCTION("if(iserror(filter(A:B,G:G=""Producer & Engineer"")),0, countunique(filter(A:B,G:G=""Producer & Engineer"")))-'3) Release_Label'!G1"),0.0) -> 0
A4: from Release_Label tab | B4: from Release_Label tab | C4: auto-fills if Release Code/Id matches Code/Id in Release_Label tab | E4: ONE ARTIST PER ROW select from Artists list, start typing or drag If compilation: Various Artists | F4: (select from list, start typing or drag) | G4: artist category auto-fills based on artist role | H4: =IFERROR(__xludf.DUMMYFUNCTION("if(iserror(filter(A:B,G:G=""Performer"")),0, countunique(filter(A:B,G:G=""Performer"")))-'3) Release_Label'!G1"),-2.0) -> -2
A5: 789294845633 | C5: {=ifs(and(isblank($A5),isblank($B5)),"", not(iserror(vlookup($A5&$B5,'3) Release_Label'!$D:$D&'3) Release_Label'!$E:$E,1,0))),vlookup($A5&$B5,{'3) Release_Label'!$D:$D&'3) Release_Label'!$E:$E,'3) Release_Label'!$F:$F},2,0), or(and(not(isblank($B5)),$B5=$B4,$A5<>$A4),and(not(isblank($A5)),$A5=$A4,$B5<>$B4)),"ID LISTS UNALIGNED",and($A5<>"",countif('3) Release_Label'!$D:$D,$A5)=0),"NO UPC MATCH in Release_Label",and($B5<>"",countif('3) Release_Label'!$E:$E,$B5)=0),"NO CATALOG ID MATCH in Release_Label",iserror(vlookup($A5&$B5,'3) Release_Label'!$D:$D&'3) Release_Label'!$E:$E,1,0)),"NO UPC-CATALOG ID pair MATCH in Release_Label" )} -> Receba | D5: {=ifs(and(isblank($A5),isblank($B5)),"", not(iserror(vlookup($A5&$B5,'3) Release_Label'!$D:$D&'3) Release_Label'!$E:$E,1,0))),vlookup($A5&$B5,{'3) Release_Label'!$D:$D&'3) Release_Label'!$E:$E,'3) Release_Label'!$H:$H},2,0), or(and(not(isblank($B5)),$B5=$B4,$A5<>$A4),and(not(isblank($A5)),$A5=$A4,$B5<>$B4)),"ID LISTS UNALIGNED",and($A5<>"",countif('3) Release_Label'!$D:$D,$A5)=0),"NO UPC MATCH in Release_Label",and($B5<>"",countif('3) Release_Label'!$E:$E,$B5)=0),"NO CATALOG ID MATCH in Release_Label",iserror(vlookup($A5&$B5,'3) Release_Label'!$D:$D&'3) Release_Label'!$E:$E,1,0)),"NO UPC-CATALOG ID pair MATCH in Release_Label" )} -> Extended | E5: JKZTest | F5: Main Primary Artist | G5: {=ifs(or($F5="",$F5="Main Primary Artist"),$F5,not(iserror(vlookup($F5,'Reference info'!$J$5:$J$8,1,0))),"Key Artist",not(iserror(vlookup($F5,'Reference info'!$J$38:$J$405,1,0))),"Performer",not(iserror(vlookup($F5,'Reference info'!$J$10:$J$36,1,0))),"Producer & Engineer")} -> Main Primary Artist
A6: 789294845633 | C6: {=ifs(and(isblank($A6),isblank($B6)),"", not(iserror(vlookup($A6&$B6,'3) Release_Label'!$D:$D&'3) Release_Label'!$E:$E,1,0))),vlookup($A6&$B6,{'3) Release_Label'!$D:$D&'3) Release_Label'!$E:$E,'3) Release_Label'!$F:$F},2,0), or(and(not(isblank($B6)),$B6=$B5,$A6<>$A5),and(not(isblank($A6)),$A6=$A5,$B6<>$B5)),"ID LISTS UNALIGNED",and($A6<>"",countif('3) Release_Label'!$D:$D,$A6)=0),"NO UPC MATCH in Release_Label",and($B6<>"",countif('3) Release_Label'!$E:$E,$B6)=0),"NO CATALOG ID MATCH in Release_Label",iserror(vlookup($A6&$B6,'3) Release_Label'!$D:$D&'3) Release_Label'!$E:$E,1,0)),"NO UPC-CATALOG ID pair MATCH in Release_Label" )} -> Receba | D6: {=ifs(and(isblank($A6),isblank($B6)),"", not(iserror(vlookup($A6&$B6,'3) Release_Label'!$D:$D&'3) Release_Label'!$E:$E,1,0))),vlookup($A6&$B6,{'3) Release_Label'!$D:$D&'3) Release_Label'!$E:$E,'3) Release_Label'!$H:$H},2,0), or(and(not(isblank($B6)),$B6=$B5,$A6<>$A5),and(not(isblank($A6)),$A6=$A5,$B6<>$B5)),"ID LISTS UNALIGNED",and($A6<>"",countif('3) Release_Label'!$D:$D,$A6)=0),"NO UPC MATCH in Release_Label",and($B6<>"",countif('3) Release_Label'!$E:$E,$B6)=0),"NO CATALOG ID MATCH in Release_Label",iserror(vlookup($A6&$B6,'3) Release_Label'!$D:$D&'3) Release_Label'!$E:$E,1,0)),"NO UPC-CATALOG ID pair MATCH in Release_Label" )} -> Extended | E6: JKZTest | F6: Producer | G6: {=ifs(or($F6="",$F6="Main Primary Artist"),$F6,not(iserror(vlookup($F6,'Reference info'!$J$5:$J$8,1,0))),"Key Artist",not(iserror(vlookup($F6,'Reference info'!$J$38:$J$405,1,0))),"Performer",not(iserror(vlookup($F6,'Reference info'!$J$10:$J$36,1,0))),"Producer & Engineer")} -> Producer & Engineer
A7: 789294845633 | C7: {=ifs(and(isblank($A7),isblank($B7)),"", not(iserror(vlookup($A7&$B7,'3) Release_Label'!$D:$D&'3) Release_Label'!$E:$E,1,0))),vlookup($A7&$B7,{'3) Release_Label'!$D:$D&'3) Release_Label'!$E:$E,'3) Release_Label'!$F:$F},2,0), or(and(not(isblank($B7)),$B7=$B6,$A7<>$A6),and(not(isblank($A7)),$A7=$A6,$B7<>$B6)),"ID LISTS UNALIGNED",and($A7<>"",countif('3) Release_Label'!$D:$D,$A7)=0),"NO UPC MATCH in Release_Label",and($B7<>"",countif('3) Release_Label'!$E:$E,$B7)=0),"NO CATALOG ID MATCH in Release_Label",iserror(vlookup($A7&$B7,'3) Release_Label'!$D:$D&'3) Release_Label'!$E:$E,1,0)),"NO UPC-CATALOG ID pair MATCH in Release_Label" )} -> Receba | D7: {=ifs(and(isblank($A7),isblank($B7)),"", not(iserror(vlookup($A7&$B7,'3) Release_Label'!$D:$D&'3) Release_Label'!$E:$E,1,0))),vlookup($A7&$B7,{'3) Release_Label'!$D:$D&'3) Release_Label'!$E:$E,'3) Release_Label'!$H:$H},2,0), or(and(not(isblank($B7)),$B7=$B6,$A7<>$A6),and(not(isblank($A7)),$A7=$A6,$B7<>$B6)),"ID LISTS UNALIGNED",and($A7<>"",countif('3) Release_Label'!$D:$D,$A7)=0),"NO UPC MATCH in Release_Label",and($B7<>"",countif('3) Release_Label'!$E:$E,$B7)=0),"NO CATALOG ID MATCH in Release_Label",iserror(vlookup($A7&$B7,'3) Release_Label'!$D:$D&'3) Release_Label'!$E:$E,1,0)),"NO UPC-CATALOG ID pair MATCH in Release_Label" )} -> Extended | E7: JKZTest | F7: Engineer | G7: {=ifs(or($F7="",$F7="Main Primary Artist"),$F7,not(iserror(vlookup($F7,'Reference info'!$J$5:$J$8,1,0))),"Key Artist",not(iserror(vlookup($F7,'Reference info'!$J$38:$J$405,1,0))),"Performer",not(iserror(vlookup($F7,'Reference info'!$J$10:$J$36,1,0))),"Producer & Engineer")} -> Producer & Engineer
A8: 789294962088 | C8: {=ifs(and(isblank($A8),isblank($B8)),"", not(iserror(vlookup($A8&$B8,'3) Release_Label'!$D:$D&'3) Release_Label'!$E:$E,1,0))),vlookup($A8&$B8,{'3) Release_Label'!$D:$D&'3) Release_Label'!$E:$E,'3) Release_Label'!$F:$F},2,0), or(and(not(isblank($B8)),$B8=$B7,$A8<>$A7),and(not(isblank($A8)),$A8=$A7,$B8<>$B7)),"ID LISTS UNALIGNED",and($A8<>"",countif('3) Release_Label'!$D:$D,$A8)=0),"NO UPC MATCH in Release_Label",and($B8<>"",countif('3) Release_Label'!$E:$E,$B8)=0),"NO CATALOG ID MATCH in Release_Label",iserror(vlookup($A8&$B8,'3) Release_Label'!$D:$D&'3) Release_Label'!$E:$E,1,0)),"NO UPC-CATALOG ID pair MATCH in Release_Label" )} -> A Cláusula do Contrato | D8: {=ifs(and(isblank($A8),isblank($B8)),"", not(iserror(vlookup($A8&$B8,'3) Release_Label'!$D:$D&'3) Release_Label'!$E:$E,1,0))),vlookup($A8&$B8,{'3) Release_Label'!$D:$D&'3) Release_Label'!$E:$E,'3) Release_Label'!$H:$H},2,0), or(and(not(isblank($B8)),$B8=$B7,$A8<>$A7),and(not(isblank($A8)),$A8=$A7,$B8<>$B7)),"ID LISTS UNALIGNED",and($A8<>"",countif('3) Release_Label'!$D:$D,$A8)=0),"NO UPC MATCH in Release_Label",and($B8<>"",countif('3) Release_Label'!$E:$E,$B8)=0),"NO CATALOG ID MATCH in Release_Label",iserror(vlookup($A8&$B8,'3) Release_Label'!$D:$D&'3) Release_Label'!$E:$E,1,0)),"NO UPC-CATALOG ID pair MATCH in Release_Label" )} | E8: Flash Beats ManowTest | F8: Main Primary Artist | G8: {=ifs(or($F8="",$F8="Main Primary Artist"),$F8,not(iserror(vlookup($F8,'Reference info'!$J$5:$J$8,1,0))),"Key Artist",not(iserror(vlookup($F8,'Reference info'!$J$38:$J$405,1,0))),"Performer",not(iserror(vlookup($F8,'Reference info'!$J$10:$J$36,1,0))),"Producer & Engineer")} -> Main Primary Artist
A9: 789294962088 | C9: {=ifs(and(isblank($A9),isblank($B9)),"", not(iserror(vlookup($A9&$B9,'3) Release_Label'!$D:$D&'3) Release_Label'!$E:$E,1,0))),vlookup($A9&$B9,{'3) Release_Label'!$D:$D&'3) Release_Label'!$E:$E,'3) Release_Label'!$F:$F},2,0), or(and(not(isblank($B9)),$B9=$B8,$A9<>$A8),and(not(isblank($A9)),$A9=$A8,$B9<>$B8)),"ID LISTS UNALIGNED",and($A9<>"",countif('3) Release_Label'!$D:$D,$A9)=0),"NO UPC MATCH in Release_Label",and($B9<>"",countif('3) Release_Label'!$E:$E,$B9)=0),"NO CATALOG ID MATCH in Release_Label",iserror(vlookup($A9&$B9,'3) Release_Label'!$D:$D&'3) Release_Label'!$E:$E,1,0)),"NO UPC-CATALOG ID pair MATCH in Release_Label" )} -> A Cláusula do Contrato | D9: {=ifs(and(isblank($A9),isblank($B9)),"", not(iserror(vlookup($A9&$B9,'3) Release_Label'!$D:$D&'3) Release_Label'!$E:$E,1,0))),vlookup($A9&$B9,{'3) Release_Label'!$D:$D&'3) Release_Label'!$E:$E,'3) Release_Label'!$H:$H},2,0), or(and(not(isblank($B9)),$B9=$B8,$A9<>$A8),and(not(isblank($A9)),$A9=$A8,$B9<>$B8)),"ID LISTS UNALIGNED",and($A9<>"",countif('3) Release_Label'!$D:$D,$A9)=0),"NO UPC MATCH in Release_Label",and($B9<>"",countif('3) Release_Label'!$E:$E,$B9)=0),"NO CATALOG ID MATCH in Release_Label",iserror(vlookup($A9&$B9,'3) Release_Label'!$D:$D&'3) Release_Label'!$E:$E,1,0)),"NO UPC-CATALOG ID pair MATCH in Release_Label" )} | E9: Flash Beats ManowTest | F9: Producer | G9: {=ifs(or($F9="",$F9="Main Primary Artist"),$F9,not(iserror(vlookup($F9,'Reference info'!$J$5:$J$8,1,0))),"Key Artist",not(iserror(vlookup($F9,'Reference info'!$J$38:$J$405,1,0))),"Performer",not(iserror(vlookup($F9,'Reference info'!$J$10:$J$36,1,0))),"Producer & Engineer")} -> Producer & Engineer
A10: 789294962088 | C10: {=ifs(and(isblank($A10),isblank($B10)),"", not(iserror(vlookup($A10&$B10,'3) Release_Label'!$D:$D&'3) Release_Label'!$E:$E,1,0))),vlookup($A10&$B10,{'3) Release_Label'!$D:$D&'3) Release_Label'!$E:$E,'3) Release_Label'!$F:$F},2,0), or(and(not(isblank($B10)),$B10=$B9,$A10<>$A9),and(not(isblank($A10)),$A10=$A9,$B10<>$B9)),"ID LISTS UNALIGNED",and($A10<>"",countif('3) Release_Label'!$D:$D,$A10)=0),"NO UPC MATCH in Release_Label",and($B10<>"",countif('3) Release_Label'!$E:$E,$B10)=0),"NO CATALOG ID MATCH in Release_Label",iserror(vlookup($A10&$B10,'3) Release_Label'!$D:$D&'3) Release_Label'!$E:$E,1,0)),"NO UPC-CATALOG ID pair MATCH in Release_Label" )} -> A Cláusula do Contrato | D10: {=ifs(and(isblank($A10),isblank($B10)),"", not(iserror(vlookup($A10&$B10,'3) Release_Label'!$D:$D&'3) Release_Label'!$E:$E,1,0))),vlookup($A10&$B10,{'3) Release_Label'!$D:$D&'3) Release_Label'!$E:$E,'3) Release_Label'!$H:$H},2,0), or(and(not(isblank($B10)),$B10=$B9,$A10<>$A9),and(not(isblank($A10)),$A10=$A9,$B10<>$B9)),"ID LISTS UNALIGNED",and($A10<>"",countif('3) Release_Label'!$D:$D,$A10)=0),"NO UPC MATCH in Release_Label",and($B10<>"",countif('3) Release_Label'!$E:$E,$B10)=0),"NO CATALOG ID MATCH in Release_Label",iserror(vlookup($A10&$B10,'3) Release_Label'!$D:$D&'3) Release_Label'!$E:$E,1,0)),"NO UPC-CATALOG ID pair MATCH in Release_Label" )} | E10: Flash Beats ManowTest | F10: Engineer | G10: {=ifs(or($F10="",$F10="Main Primary Artist"),$F10,not(iserror(vlookup($F10,'Reference info'!$J$5:$J$8,1,0))),"Key Artist",not(iserror(vlookup($F10,'Reference info'!$J$38:$J$405,1,0))),"Performer",not(iserror(vlookup($F10,'Reference info'!$J$10:$J$36,1,0))),"Producer & Engineer")} -> Producer & Engineer
C12: {=ifs(and(isblank($A12),isblank($B12)),"", not(iserror(vlookup($A12&$B12,'3) Release_Label'!$D:$D&'3) Release_Label'!$E:$E,1,0))),vlookup($A12&$B12,{'3) Release_Label'!$D:$D&'3) Release_Label'!$E:$E,'3) Release_Label'!$F:$F},2,0), or(and(not(isblank($B12)),$B12=$B11,$A12<>$A11),and(not(isblank($A12)),$A12=$A11,$B12<>$B11)),"ID LISTS UNALIGNED",and($A12<>"",countif('3) Release_Label'!$D:$D,$A12)=0),"NO UPC MATCH in Release_Label",and($B12<>"",countif('3) Release_Label'!$E:$E,$B12)=0),"NO CATALOG ID MATCH in Release_Label",iserror(vlookup($A12&$B12,'3) Release_Label'!$D:$D&'3) Release_Label'!$E:$E,1,0)),"NO UPC-CATALOG ID pair MATCH in Release_Label" )} | D12: {=ifs(and(isblank($A12),isblank($B12)),"", not(iserror(vlookup($A12&$B12,'3) Release_Label'!$D:$D&'3) Release_Label'!$E:$E,1,0))),vlookup($A12&$B12,{'3) Release_Label'!$D:$D&'3) Release_Label'!$E:$E,'3) Release_Label'!$H:$H},2,0), or(and(not(isblank($B12)),$B12=$B11,$A12<>$A11),and(not(isblank($A12)),$A12=$A11,$B12<>$B11)),"ID LISTS UNALIGNED",and($A12<>"",countif('3) Release_Label'!$D:$D,$A12)=0),"NO UPC MATCH in Release_Label",and($B12<>"",countif('3) Release_Label'!$E:$E,$B12)=0),"NO CATALOG ID MATCH in Release_Label",iserror(vlookup($A12&$B12,'3) Release_Label'!$D:$D&'3) Release_Label'!$E:$E,1,0)),"NO UPC-CATALOG ID pair MATCH in Release_Label" )} | G12: {=ifs(or($F12="",$F12="Main Primary Artist"),$F12,not(iserror(vlookup($F12,'Reference info'!$J$5:$J$8,1,0))),"Key Artist",not(iserror(vlookup($F12,'Reference info'!$J$38:$J$405,1,0))),"Performer",not(iserror(vlookup($F12,'Reference info'!$J$10:$J$36,1,0))),"Producer & Engineer")} | H12: sort(if(countif($A$5:$A&$B$5:$B,'3) Release_Label'!$D$5:$D&'3) Release_Label'!$E$5:$E)=0,'3) Release_Label'!$D$5:$D&" "&'3) Release_Label'!$E$5:$E,))
C13: {=ifs(and(isblank($A13),isblank($B13)),"", not(iserror(vlookup($A13&$B13,'3) Release_Label'!$D:$D&'3) Release_Label'!$E:$E,1,0))),vlookup($A13&$B13,{'3) Release_Label'!$D:$D&'3) Release_Label'!$E:$E,'3) Release_Label'!$F:$F},2,0), or(and(not(isblank($B13)),$B13=$B12,$A13<>$A12),and(not(isblank($A13)),$A13=$A12,$B13<>$B12)),"ID LISTS UNALIGNED",and($A13<>"",countif('3) Release_Label'!$D:$D,$A13)=0),"NO UPC MATCH in Release_Label",and($B13<>"",countif('3) Release_Label'!$E:$E,$B13)=0),"NO CATALOG ID MATCH in Release_Label",iserror(vlookup($A13&$B13,'3) Release_Label'!$D:$D&'3) Release_Label'!$E:$E,1,0)),"NO UPC-CATALOG ID pair MATCH in Release_Label" )} | D13: {=ifs(and(isblank($A13),isblank($B13)),"", not(iserror(vlookup($A13&$B13,'3) Release_Label'!$D:$D&'3) Release_Label'!$E:$E,1,0))),vlookup($A13&$B13,{'3) Release_Label'!$D:$D&'3) Release_Label'!$E:$E,'3) Release_Label'!$H:$H},2,0), or(and(not(isblank($B13)),$B13=$B12,$A13<>$A12),and(not(isblank($A13)),$A13=$A12,$B13<>$B12)),"ID LISTS UNALIGNED",and($A13<>"",countif('3) Release_Label'!$D:$D,$A13)=0),"NO UPC MATCH in Release_Label",and($B13<>"",countif('3) Release_Label'!$E:$E,$B13)=0),"NO CATALOG ID MATCH in Release_Label",iserror(vlookup($A13&$B13,'3) Release_Label'!$D:$D&'3) Release_Label'!$E:$E,1,0)),"NO UPC-CATALOG ID pair MATCH in Release_Label" )} | G13: {=ifs(or($F13="",$F13="Main Primary Artist"),$F13,not(iserror(vlookup($F13,'Reference info'!$J$5:$J$8,1,0))),"Key Artist",not(iserror(vlookup($F13,'Reference info'!$J$38:$J$405,1,0))),"Performer",not(iserror(vlookup($F13,'Reference info'!$J$10:$J$36,1,0))),"Producer & Engineer")} | H13: sort(if(countif({A5:A,B5:B},{'3) Release_Label'!D5:D,'3) Release_Label'!E5:E})=0,{'3) Release_Label'!D5:D,'3) Release_Label'!E5:E},))
C14: {=ifs(and(isblank($A14),isblank($B14)),"", not(iserror(vlookup($A14&$B14,'3) Release_Label'!$D:$D&'3) Release_Label'!$E:$E,1,0))),vlookup($A14&$B14,{'3) Release_Label'!$D:$D&'3) Release_Label'!$E:$E,'3) Release_Label'!$F:$F},2,0), or(and(not(isblank($B14)),$B14=$B13,$A14<>$A13),and(not(isblank($A14)),$A14=$A13,$B14<>$B13)),"ID LISTS UNALIGNED",and($A14<>"",countif('3) Release_Label'!$D:$D,$A14)=0),"NO UPC MATCH in Release_Label",and($B14<>"",countif('3) Release_Label'!$E:$E,$B14)=0),"NO CATALOG ID MATCH in Release_Label",iserror(vlookup($A14&$B14,'3) Release_Label'!$D:$D&'3) Release_Label'!$E:$E,1,0)),"NO UPC-CATALOG ID pair MATCH in Release_Label" )} | D14: {=ifs(and(isblank($A14),isblank($B14)),"", not(iserror(vlookup($A14&$B14,'3) Release_Label'!$D:$D&'3) Release_Label'!$E:$E,1,0))),vlookup($A14&$B14,{'3) Release_Label'!$D:$D&'3) Release_Label'!$E:$E,'3) Release_Label'!$H:$H},2,0), or(and(not(isblank($B14)),$B14=$B13,$A14<>$A13),and(not(isblank($A14)),$A14=$A13,$B14<>$B13)),"ID LISTS UNALIGNED",and($A14<>"",countif('3) Release_Label'!$D:$D,$A14)=0),"NO UPC MATCH in Release_Label",and($B14<>"",countif('3) Release_Label'!$E:$E,$B14)=0),"NO CATALOG ID MATCH in Release_Label",iserror(vlookup($A14&$B14,'3) Release_Label'!$D:$D&'3) Release_Label'!$E:$E,1,0)),"NO UPC-CATALOG ID pair MATCH in Release_Label" )} | G14: {=ifs(or($F14="",$F14="Main Primary Artist"),$F14,not(iserror(vlookup($F14,'Reference info'!$J$5:$J$8,1,0))),"Key Artist",not(iserror(vlookup($F14,'Reference info'!$J$38:$J$405,1,0))),"Performer",not(iserror(vlookup($F14,'Reference info'!$J$10:$J$36,1,0))),"Producer & Engineer")} | H14: sort(if(countif(filter($A:$B,$F:$F="Main Primary Artist"),'3) Release_Label'!$D$5:$E)=0,'3) Release_Label'!$D$5:$E,))
C15: {=ifs(and(isblank($A15),isblank($B15)),"", not(iserror(vlookup($A15&$B15,'3) Release_Label'!$D:$D&'3) Release_Label'!$E:$E,1,0))),vlookup($A15&$B15,{'3) Release_Label'!$D:$D&'3) Release_Label'!$E:$E,'3) Release_Label'!$F:$F},2,0), or(and(not(isblank($B15)),$B15=$B14,$A15<>$A14),and(not(isblank($A15)),$A15=$A14,$B15<>$B14)),"ID LISTS UNALIGNED",and($A15<>"",countif('3) Release_Label'!$D:$D,$A15)=0),"NO UPC MATCH in Release_Label",and($B15<>"",countif('3) Release_Label'!$E:$E,$B15)=0),"NO CATALOG ID MATCH in Release_Label",iserror(vlookup($A15&$B15,'3) Release_Label'!$D:$D&'3) Release_Label'!$E:$E,1,0)),"NO UPC-CATALOG ID pair MATCH in Release_Label" )} | D15: {=ifs(and(isblank($A15),isblank($B15)),"", not(iserror(vlookup($A15&$B15,'3) Release_Label'!$D:$D&'3) Release_Label'!$E:$E,1,0))),vlookup($A15&$B15,{'3) Release_Label'!$D:$D&'3) Release_Label'!$E:$E,'3) Release_Label'!$H:$H},2,0), or(and(not(isblank($B15)),$B15=$B14,$A15<>$A14),and(not(isblank($A15)),$A15=$A14,$B15<>$B14)),"ID LISTS UNALIGNED",and($A15<>"",countif('3) Release_Label'!$D:$D,$A15)=0),"NO UPC MATCH in Release_Label",and($B15<>"",countif('3) Release_Label'!$E:$E,$B15)=0),"NO CATALOG ID MATCH in Release_Label",iserror(vlookup($A15&$B15,'3) Release_Label'!$D:$D&'3) Release_Label'!$E:$E,1,0)),"NO UPC-CATALOG ID pair MATCH in Release_Label" )} | G15: {=ifs(or($F15="",$F15="Main Primary Artist"),$F15,not(iserror(vlookup($F15,'Reference info'!$J$5:$J$8,1,0))),"Key Artist",not(iserror(vlookup($F15,'Reference info'!$J$38:$J$405,1,0))),"Performer",not(iserror(vlookup($F15,'Reference info'!$J$10:$J$36,1,0))),"Producer & Engineer")} | H15: sort(if(countif(filter($A:$B,$F:$F="Main Primary Artist"),'3) Release_Label'!$D$5:$E)>1,'3) Release_Label'!$D$5:$E,))
C16: {=ifs(and(isblank($A16),isblank($B16)),"", not(iserror(vlookup($A16&$B16,'3) Release_Label'!$D:$D&'3) Release_Label'!$E:$E,1,0))),vlookup($A16&$B16,{'3) Release_Label'!$D:$D&'3) Release_Label'!$E:$E,'3) Release_Label'!$F:$F},2,0), or(and(not(isblank($B16)),$B16=$B15,$A16<>$A15),and(not(isblank($A16)),$A16=$A15,$B16<>$B15)),"ID LISTS UNALIGNED",and($A16<>"",countif('3) Release_Label'!$D:$D,$A16)=0),"NO UPC MATCH in Release_Label",and($B16<>"",countif('3) Release_Label'!$E:$E,$B16)=0),"NO CATALOG ID MATCH in Release_Label",iserror(vlookup($A16&$B16,'3) Release_Label'!$D:$D&'3) Release_Label'!$E:$E,1,0)),"NO UPC-CATALOG ID pair MATCH in Release_Label" )} | D16: {=ifs(and(isblank($A16),isblank($B16)),"", not(iserror(vlookup($A16&$B16,'3) Release_Label'!$D:$D&'3) Release_Label'!$E:$E,1,0))),vlookup($A16&$B16,{'3) Release_Label'!$D:$D&'3) Release_Label'!$E:$E,'3) Release_Label'!$H:$H},2,0), or(and(not(isblank($B16)),$B16=$B15,$A16<>$A15),and(not(isblank($A16)),$A16=$A15,$B16<>$B15)),"ID LISTS UNALIGNED",and($A16<>"",countif('3) Release_Label'!$D:$D,$A16)=0),"NO UPC MATCH in Release_Label",and($B16<>"",countif('3) Release_Label'!$E:$E,$B16)=0),"NO CATALOG ID MATCH in Release_Label",iserror(vlookup($A16&$B16,'3) Release_Label'!$D:$D&'3) Release_Label'!$E:$E,1,0)),"NO UPC-CATALOG ID pair MATCH in Release_Label" )} | G16: {=ifs(or($F16="",$F16="Main Primary Artist"),$F16,not(iserror(vlookup($F16,'Reference info'!$J$5:$J$8,1,0))),"Key Artist",not(iserror(vlookup($F16,'Reference info'!$J$38:$J$405,1,0))),"Performer",not(iserror(vlookup($F16,'Reference info'!$J$10:$J$36,1,0))),"Producer & Engineer")}
C17: {=ifs(and(isblank($A17),isblank($B17)),"", not(iserror(vlookup($A17&$B17,'3) Release_Label'!$D:$D&'3) Release_Label'!$E:$E,1,0))),vlookup($A17&$B17,{'3) Release_Label'!$D:$D&'3) Release_Label'!$E:$E,'3) Release_Label'!$F:$F},2,0), or(and(not(isblank($B17)),$B17=$B16,$A17<>$A16),and(not(isblank($A17)),$A17=$A16,$B17<>$B16)),"ID LISTS UNALIGNED",and($A17<>"",countif('3) Release_Label'!$D:$D,$A17)=0),"NO UPC MATCH in Release_Label",and($B17<>"",countif('3) Release_Label'!$E:$E,$B17)=0),"NO CATALOG ID MATCH in Release_Label",iserror(vlookup($A17&$B17,'3) Release_Label'!$D:$D&'3) Release_Label'!$E:$E,1,0)),"NO UPC-CATALOG ID pair MATCH in Release_Label" )} | D17: {=ifs(and(isblank($A17),isblank($B17)),"", not(iserror(vlookup($A17&$B17,'3) Release_Label'!$D:$D&'3) Release_Label'!$E:$E,1,0))),vlookup($A17&$B17,{'3) Release_Label'!$D:$D&'3) Release_Label'!$E:$E,'3) Release_Label'!$H:$H},2,0), or(and(not(isblank($B17)),$B17=$B16,$A17<>$A16),and(not(isblank($A17)),$A17=$A16,$B17<>$B16)),"ID LISTS UNALIGNED",and($A17<>"",countif('3) Release_Label'!$D:$D,$A17)=0),"NO UPC MATCH in Release_Label",and($B17<>"",countif('3) Release_Label'!$E:$E,$B17)=0),"NO CATALOG ID MATCH in Release_Label",iserror(vlookup($A17&$B17,'3) Release_Label'!$D:$D&'3) Release_Label'!$E:$E,1,0)),"NO UPC-CATALOG ID pair MATCH in Release_Label" )} | G17: {=ifs(or($F17="",$F17="Main Primary Artist"),$F17,not(iserror(vlookup($F17,'Reference info'!$J$5:$J$8,1,0))),"Key Artist",not(iserror(vlookup($F17,'Reference info'!$J$38:$J$405,1,0))),"Performer",not(iserror(vlookup($F17,'Reference info'!$J$10:$J$36,1,0))),"Producer & Engineer")}
C18: {=ifs(and(isblank($A18),isblank($B18)),"", not(iserror(vlookup($A18&$B18,'3) Release_Label'!$D:$D&'3) Release_Label'!$E:$E,1,0))),vlookup($A18&$B18,{'3) Release_Label'!$D:$D&'3) Release_Label'!$E:$E,'3) Release_Label'!$F:$F},2,0), or(and(not(isblank($B18)),$B18=$B17,$A18<>$A17),and(not(isblank($A18)),$A18=$A17,$B18<>$B17)),"ID LISTS UNALIGNED",and($A18<>"",countif('3) Release_Label'!$D:$D,$A18)=0),"NO UPC MATCH in Release_Label",and($B18<>"",countif('3) Release_Label'!$E:$E,$B18)=0),"NO CATALOG ID MATCH in Release_Label",iserror(vlookup($A18&$B18,'3) Release_Label'!$D:$D&'3) Release_Label'!$E:$E,1,0)),"NO UPC-CATALOG ID pair MATCH in Release_Label" )} | D18: {=ifs(and(isblank($A18),isblank($B18)),"", not(iserror(vlookup($A18&$B18,'3) Release_Label'!$D:$D&'3) Release_Label'!$E:$E,1,0))),vlookup($A18&$B18,{'3) Release_Label'!$D:$D&'3) Release_Label'!$E:$E,'3) Release_Label'!$H:$H},2,0), or(and(not(isblank($B18)),$B18=$B17,$A18<>$A17),and(not(isblank($A18)),$A18=$A17,$B18<>$B17)),"ID LISTS UNALIGNED",and($A18<>"",countif('3) Release_Label'!$D:$D,$A18)=0),"NO UPC MATCH in Release_Label",and($B18<>"",countif('3) Release_Label'!$E:$E,$B18)=0),"NO CATALOG ID MATCH in Release_Label",iserror(vlookup($A18&$B18,'3) Release_Label'!$D:$D&'3) Release_Label'!$E:$E,1,0)),"NO UPC-CATALOG ID pair MATCH in Release_Label" )} | G18: {=ifs(or($F18="",$F18="Main Primary Artist"),$F18,not(iserror(vlookup($F18,'Reference info'!$J$5:$J$8,1,0))),"Key Artist",not(iserror(vlookup($F18,'Reference info'!$J$38:$J$405,1,0))),"Performer",not(iserror(vlookup($F18,'Reference info'!$J$10:$J$36,1,0))),"Producer & Engineer")}
C19: {=ifs(and(isblank($A19),isblank($B19)),"", not(iserror(vlookup($A19&$B19,'3) Release_Label'!$D:$D&'3) Release_Label'!$E:$E,1,0))),vlookup($A19&$B19,{'3) Release_Label'!$D:$D&'3) Release_Label'!$E:$E,'3) Release_Label'!$F:$F},2,0), or(and(not(isblank($B19)),$B19=$B18,$A19<>$A18),and(not(isblank($A19)),$A19=$A18,$B19<>$B18)),"ID LISTS UNALIGNED",and($A19<>"",countif('3) Release_Label'!$D:$D,$A19)=0),"NO UPC MATCH in Release_Label",and($B19<>"",countif('3) Release_Label'!$E:$E,$B19)=0),"NO CATALOG ID MATCH in Release_Label",iserror(vlookup($A19&$B19,'3) Release_Label'!$D:$D&'3) Release_Label'!$E:$E,1,0)),"NO UPC-CATALOG ID pair MATCH in Release_Label" )} | D19: {=ifs(and(isblank($A19),isblank($B19)),"", not(iserror(vlookup($A19&$B19,'3) Release_Label'!$D:$D&'3) Release_Label'!$E:$E,1,0))),vlookup($A19&$B19,{'3) Release_Label'!$D:$D&'3) Release_Label'!$E:$E,'3) Release_Label'!$H:$H},2,0), or(and(not(isblank($B19)),$B19=$B18,$A19<>$A18),and(not(isblank($A19)),$A19=$A18,$B19<>$B18)),"ID LISTS UNALIGNED",and($A19<>"",countif('3) Release_Label'!$D:$D,$A19)=0),"NO UPC MATCH in Release_Label",and($B19<>"",countif('3) Release_Label'!$E:$E,$B19)=0),"NO CATALOG ID MATCH in Release_Label",iserror(vlookup($A19&$B19,'3) Release_Label'!$D:$D&'3) Release_Label'!$E:$E,1,0)),"NO UPC-CATALOG ID pair MATCH in Release_Label" )} | G19: {=ifs(or($F19="",$F19="Main Primary Artist"),$F19,not(iserror(vlookup($F19,'Reference info'!$J$5:$J$8,1,0))),"Key Artist",not(iserror(vlookup($F19,'Reference info'!$J$38:$J$405,1,0))),"Performer",not(iserror(vlookup($F19,'Reference info'!$J$10:$J$36,1,0))),"Producer & Engineer")}
C20: {=ifs(and(isblank($A20),isblank($B20)),"", not(iserror(vlookup($A20&$B20,'3) Release_Label'!$D:$D&'3) Release_Label'!$E:$E,1,0))),vlookup($A20&$B20,{'3) Release_Label'!$D:$D&'3) Release_Label'!$E:$E,'3) Release_Label'!$F:$F},2,0), or(and(not(isblank($B20)),$B20=$B19,$A20<>$A19),and(not(isblank($A20)),$A20=$A19,$B20<>$B19)),"ID LISTS UNALIGNED",and($A20<>"",countif('3) Release_Label'!$D:$D,$A20)=0),"NO UPC MATCH in Release_Label",and($B20<>"",countif('3) Release_Label'!$E:$E,$B20)=0),"NO CATALOG ID MATCH in Release_Label",iserror(vlookup($A20&$B20,'3) Release_Label'!$D:$D&'3) Release_Label'!$E:$E,1,0)),"NO UPC-CATALOG ID pair MATCH in Release_Label" )} | D20: {=ifs(and(isblank($A20),isblank($B20)),"", not(iserror(vlookup($A20&$B20,'3) Release_Label'!$D:$D&'3) Release_Label'!$E:$E,1,0))),vlookup($A20&$B20,{'3) Release_Label'!$D:$D&'3) Release_Label'!$E:$E,'3) Release_Label'!$H:$H},2,0), or(and(not(isblank($B20)),$B20=$B19,$A20<>$A19),and(not(isblank($A20)),$A20=$A19,$B20<>$B19)),"ID LISTS UNALIGNED",and($A20<>"",countif('3) Release_Label'!$D:$D,$A20)=0),"NO UPC MATCH in Release_Label",and($B20<>"",countif('3) Release_Label'!$E:$E,$B20)=0),"NO CATALOG ID MATCH in Release_Label",iserror(vlookup($A20&$B20,'3) Release_Label'!$D:$D&'3) Release_Label'!$E:$E,1,0)),"NO UPC-CATALOG ID pair MATCH in Release_Label" )} | G20: {=ifs(or($F20="",$F20="Main Primary Artist"),$F20,not(iserror(vlookup($F20,'Reference info'!$J$5:$J$8,1,0))),"Key Artist",not(iserror(vlookup($F20,'Reference info'!$J$38:$J$405,1,0))),"Performer",not(iserror(vlookup($F20,'Reference info'!$J$10:$J$36,1,0))),"Producer & Engineer")}
C21: {=ifs(and(isblank($A21),isblank($B21)),"", not(iserror(vlookup($A21&$B21,'3) Release_Label'!$D:$D&'3) Release_Label'!$E:$E,1,0))),vlookup($A21&$B21,{'3) Release_Label'!$D:$D&'3) Release_Label'!$E:$E,'3) Release_Label'!$F:$F},2,0), or(and(not(isblank($B21)),$B21=$B20,$A21<>$A20),and(not(isblank($A21)),$A21=$A20,$B21<>$B20)),"ID LISTS UNALIGNED",and($A21<>"",countif('3) Release_Label'!$D:$D,$A21)=0),"NO UPC MATCH in Release_Label",and($B21<>"",countif('3) Release_Label'!$E:$E,$B21)=0),"NO CATALOG ID MATCH in Release_Label",iserror(vlookup($A21&$B21,'3) Release_Label'!$D:$D&'3) Release_Label'!$E:$E,1,0)),"NO UPC-CATALOG ID pair MATCH in Release_Label" )} | D21: {=ifs(and(isblank($A21),isblank($B21)),"", not(iserror(vlookup($A21&$B21,'3) Release_Label'!$D:$D&'3) Release_Label'!$E:$E,1,0))),vlookup($A21&$B21,{'3) Release_Label'!$D:$D&'3) Release_Label'!$E:$E,'3) Release_Label'!$H:$H},2,0), or(and(not(isblank($B21)),$B21=$B20,$A21<>$A20),and(not(isblank($A21)),$A21=$A20,$B21<>$B20)),"ID LISTS UNALIGNED",and($A21<>"",countif('3) Release_Label'!$D:$D,$A21)=0),"NO UPC MATCH in Release_Label",and($B21<>"",countif('3) Release_Label'!$E:$E,$B21)=0),"NO CATALOG ID MATCH in Release_Label",iserror(vlookup($A21&$B21,'3) Release_Label'!$D:$D&'3) Release_Label'!$E:$E,1,0)),"NO UPC-CATALOG ID pair MATCH in Release_Label" )} | G21: {=ifs(or($F21="",$F21="Main Primary Artist"),$F21,not(iserror(vlookup($F21,'Reference info'!$J$5:$J$8,1,0))),"Key Artist",not(iserror(vlookup($F21,'Reference info'!$J$38:$J$405,1,0))),"Performer",not(iserror(vlookup($F21,'Reference info'!$J$10:$J$36,1,0))),"Producer & Engineer")}
C22: {=ifs(and(isblank($A22),isblank($B22)),"", not(iserror(vlookup($A22&$B22,'3) Release_Label'!$D:$D&'3) Release_Label'!$E:$E,1,0))),vlookup($A22&$B22,{'3) Release_Label'!$D:$D&'3) Release_Label'!$E:$E,'3) Release_Label'!$F:$F},2,0), or(and(not(isblank($B22)),$B22=$B21,$A22<>$A21),and(not(isblank($A22)),$A22=$A21,$B22<>$B21)),"ID LISTS UNALIGNED",and($A22<>"",countif('3) Release_Label'!$D:$D,$A22)=0),"NO UPC MATCH in Release_Label",and($B22<>"",countif('3) Release_Label'!$E:$E,$B22)=0),"NO CATALOG ID MATCH in Release_Label",iserror(vlookup($A22&$B22,'3) Release_Label'!$D:$D&'3) Release_Label'!$E:$E,1,0)),"NO UPC-CATALOG ID pair MATCH in Release_Label" )} | D22: {=ifs(and(isblank($A22),isblank($B22)),"", not(iserror(vlookup($A22&$B22,'3) Release_Label'!$D:$D&'3) Release_Label'!$E:$E,1,0))),vlookup($A22&$B22,{'3) Release_Label'!$D:$D&'3) Release_Label'!$E:$E,'3) Release_Label'!$H:$H},2,0), or(and(not(isblank($B22)),$B22=$B21,$A22<>$A21),and(not(isblank($A22)),$A22=$A21,$B22<>$B21)),"ID LISTS UNALIGNED",and($A22<>"",countif('3) Release_Label'!$D:$D,$A22)=0),"NO UPC MATCH in Release_Label",and($B22<>"",countif('3) Release_Label'!$E:$E,$B22)=0),"NO CATALOG ID MATCH in Release_Label",iserror(vlookup($A22&$B22,'3) Release_Label'!$D:$D&'3) Release_Label'!$E:$E,1,0)),"NO UPC-CATALOG ID pair MATCH in Release_Label" )} | G22: {=ifs(or($F22="",$F22="Main Primary Artist"),$F22,not(iserror(vlookup($F22,'Reference info'!$J$5:$J$8,1,0))),"Key Artist",not(iserror(vlookup($F22,'Reference info'!$J$38:$J$405,1,0))),"Performer",not(iserror(vlookup($F22,'Reference info'!$J$10:$J$36,1,0))),"Producer & Engineer")}
C23: {=ifs(and(isblank($A23),isblank($B23)),"", not(iserror(vlookup($A23&$B23,'3) Release_Label'!$D:$D&'3) Release_Label'!$E:$E,1,0))),vlookup($A23&$B23,{'3) Release_Label'!$D:$D&'3) Release_Label'!$E:$E,'3) Release_Label'!$F:$F},2,0), or(and(not(isblank($B23)),$B23=$B22,$A23<>$A22),and(not(isblank($A23)),$A23=$A22,$B23<>$B22)),"ID LISTS UNALIGNED",and($A23<>"",countif('3) Release_Label'!$D:$D,$A23)=0),"NO UPC MATCH in Release_Label",and($B23<>"",countif('3) Release_Label'!$E:$E,$B23)=0),"NO CATALOG ID MATCH in Release_Label",iserror(vlookup($A23&$B23,'3) Release_Label'!$D:$D&'3) Release_Label'!$E:$E,1,0)),"NO UPC-CATALOG ID pair MATCH in Release_Label" )} | D23: {=ifs(and(isblank($A23),isblank($B23)),"", not(iserror(vlookup($A23&$B23,'3) Release_Label'!$D:$D&'3) Release_Label'!$E:$E,1,0))),vlookup($A23&$B23,{'3) Release_Label'!$D:$D&'3) Release_Label'!$E:$E,'3) Release_Label'!$H:$H},2,0), or(and(not(isblank($B23)),$B23=$B22,$A23<>$A22),and(not(isblank($A23)),$A23=$A22,$B23<>$B22)),"ID LISTS UNALIGNED",and($A23<>"",countif('3) Release_Label'!$D:$D,$A23)=0),"NO UPC MATCH in Release_Label",and($B23<>"",countif('3) Release_Label'!$E:$E,$B23)=0),"NO CATALOG ID MATCH in Release_Label",iserror(vlookup($A23&$B23,'3) Release_Label'!$D:$D&'3) Release_Label'!$E:$E,1,0)),"NO UPC-CATALOG ID pair MATCH in Release_Label" )} | G23: {=ifs(or($F23="",$F23="Main Primary Artist"),$F23,not(iserror(vlookup($F23,'Reference info'!$J$5:$J$8,1,0))),"Key Artist",not(iserror(vlookup($F23,'Reference info'!$J$38:$J$405,1,0))),"Performer",not(iserror(vlookup($F23,'Reference info'!$J$10:$J$36,1,0))),"Producer & Engineer")}
C24: {=ifs(and(isblank($A24),isblank($B24)),"", not(iserror(vlookup($A24&$B24,'3) Release_Label'!$D:$D&'3) Release_Label'!$E:$E,1,0))),vlookup($A24&$B24,{'3) Release_Label'!$D:$D&'3) Release_Label'!$E:$E,'3) Release_Label'!$F:$F},2,0), or(and(not(isblank($B24)),$B24=$B23,$A24<>$A23),and(not(isblank($A24)),$A24=$A23,$B24<>$B23)),"ID LISTS UNALIGNED",and($A24<>"",countif('3) Release_Label'!$D:$D,$A24)=0),"NO UPC MATCH in Release_Label",and($B24<>"",countif('3) Release_Label'!$E:$E,$B24)=0),"NO CATALOG ID MATCH in Release_Label",iserror(vlookup($A24&$B24,'3) Release_Label'!$D:$D&'3) Release_Label'!$E:$E,1,0)),"NO UPC-CATALOG ID pair MATCH in Release_Label" )} | D24: {=ifs(and(isblank($A24),isblank($B24)),"", not(iserror(vlookup($A24&$B24,'3) Release_Label'!$D:$D&'3) Release_Label'!$E:$E,1,0))),vlookup($A24&$B24,{'3) Release_Label'!$D:$D&'3) Release_Label'!$E:$E,'3) Release_Label'!$H:$H},2,0), or(and(not(isblank($B24)),$B24=$B23,$A24<>$A23),and(not(isblank($A24)),$A24=$A23,$B24<>$B23)),"ID LISTS UNALIGNED",and($A24<>"",countif('3) Release_Label'!$D:$D,$A24)=0),"NO UPC MATCH in Release_Label",and($B24<>"",countif('3) Release_Label'!$E:$E,$B24)=0),"NO CATALOG ID MATCH in Release_Label",iserror(vlookup($A24&$B24,'3) Release_Label'!$D:$D&'3) Release_Label'!$E:$E,1,0)),"NO UPC-CATALOG ID pair MATCH in Release_Label" )} | G24: {=ifs(or($F24="",$F24="Main Primary Artist"),$F24,not(iserror(vlookup($F24,'Reference info'!$J$5:$J$8,1,0))),"Key Artist",not(iserror(vlookup($F24,'Reference info'!$J$38:$J$405,1,0))),"Performer",not(iserror(vlookup($F24,'Reference info'!$J$10:$J$36,1,0))),"Producer & Engineer")}
C25: {=ifs(and(isblank($A25),isblank($B25)),"", not(iserror(vlookup($A25&$B25,'3) Release_Label'!$D:$D&'3) Release_Label'!$E:$E,1,0))),vlookup($A25&$B25,{'3) Release_Label'!$D:$D&'3) Release_Label'!$E:$E,'3) Release_Label'!$F:$F},2,0), or(and(not(isblank($B25)),$B25=$B24,$A25<>$A24),and(not(isblank($A25)),$A25=$A24,$B25<>$B24)),"ID LISTS UNALIGNED",and($A25<>"",countif('3) Release_Label'!$D:$D,$A25)=0),"NO UPC MATCH in Release_Label",and($B25<>"",countif('3) Release_Label'!$E:$E,$B25)=0),"NO CATALOG ID MATCH in Release_Label",iserror(vlookup($A25&$B25,'3) Release_Label'!$D:$D&'3) Release_Label'!$E:$E,1,0)),"NO UPC-CATALOG ID pair MATCH in Release_Label" )} | D25: {=ifs(and(isblank($A25),isblank($B25)),"", not(iserror(vlookup($A25&$B25,'3) Release_Label'!$D:$D&'3) Release_Label'!$E:$E,1,0))),vlookup($A25&$B25,{'3) Release_Label'!$D:$D&'3) Release_Label'!$E:$E,'3) Release_Label'!$H:$H},2,0), or(and(not(isblank($B25)),$B25=$B24,$A25<>$A24),and(not(isblank($A25)),$A25=$A24,$B25<>$B24)),"ID LISTS UNALIGNED",and($A25<>"",countif('3) Release_Label'!$D:$D,$A25)=0),"NO UPC MATCH in Release_Label",and($B25<>"",countif('3) Release_Label'!$E:$E,$B25)=0),"NO CATALOG ID MATCH in Release_Label",iserror(vlookup($A25&$B25,'3) Release_Label'!$D:$D&'3) Release_Label'!$E:$E,1,0)),"NO UPC-CATALOG ID pair MATCH in Release_Label" )} | G25: {=ifs(or($F25="",$F25="Main Primary Artist"),$F25,not(iserror(vlookup($F25,'Reference info'!$J$5:$J$8,1,0))),"Key Artist",not(iserror(vlookup($F25,'Reference info'!$J$38:$J$405,1,0))),"Performer",not(iserror(vlookup($F25,'Reference info'!$J$10:$J$36,1,0))),"Producer & Engineer")}
C26: {=ifs(and(isblank($A26),isblank($B26)),"", not(iserror(vlookup($A26&$B26,'3) Release_Label'!$D:$D&'3) Release_Label'!$E:$E,1,0))),vlookup($A26&$B26,{'3) Release_Label'!$D:$D&'3) Release_Label'!$E:$E,'3) Release_Label'!$F:$F},2,0), or(and(not(isblank($B26)),$B26=$B25,$A26<>$A25),and(not(isblank($A26)),$A26=$A25,$B26<>$B25)),"ID LISTS UNALIGNED",and($A26<>"",countif('3) Release_Label'!$D:$D,$A26)=0),"NO UPC MATCH in Release_Label",and($B26<>"",countif('3) Release_Label'!$E:$E,$B26)=0),"NO CATALOG ID MATCH in Release_Label",iserror(vlookup($A26&$B26,'3) Release_Label'!$D:$D&'3) Release_Label'!$E:$E,1,0)),"NO UPC-CATALOG ID pair MATCH in Release_Label" )} | D26: {=ifs(and(isblank($A26),isblank($B26)),"", not(iserror(vlookup($A26&$B26,'3) Release_Label'!$D:$D&'3) Release_Label'!$E:$E,1,0))),vlookup($A26&$B26,{'3) Release_Label'!$D:$D&'3) Release_Label'!$E:$E,'3) Release_Label'!$H:$H},2,0), or(and(not(isblank($B26)),$B26=$B25,$A26<>$A25),and(not(isblank($A26)),$A26=$A25,$B26<>$B25)),"ID LISTS UNALIGNED",and($A26<>"",countif('3) Release_Label'!$D:$D,$A26)=0),"NO UPC MATCH in Release_Label",and($B26<>"",countif('3) Release_Label'!$E:$E,$B26)=0),"NO CATALOG ID MATCH in Release_Label",iserror(vlookup($A26&$B26,'3) Release_Label'!$D:$D&'3) Release_Label'!$E:$E,1,0)),"NO UPC-CATALOG ID pair MATCH in Release_Label" )} | G26: {=ifs(or($F26="",$F26="Main Primary Artist"),$F26,not(iserror(vlookup($F26,'Reference info'!$J$5:$J$8,1,0))),"Key Artist",not(iserror(vlookup($F26,'Reference info'!$J$38:$J$405,1,0))),"Performer",not(iserror(vlookup($F26,'Reference info'!$J$10:$J$36,1,0))),"Producer & Engineer")}
C27: {=ifs(and(isblank($A27),isblank($B27)),"", not(iserror(vlookup($A27&$B27,'3) Release_Label'!$D:$D&'3) Release_Label'!$E:$E,1,0))),vlookup($A27&$B27,{'3) Release_Label'!$D:$D&'3) Release_Label'!$E:$E,'3) Release_Label'!$F:$F},2,0), or(and(not(isblank($B27)),$B27=$B26,$A27<>$A26),and(not(isblank($A27)),$A27=$A26,$B27<>$B26)),"ID LISTS UNALIGNED",and($A27<>"",countif('3) Release_Label'!$D:$D,$A27)=0),"NO UPC MATCH in Release_Label",and($B27<>"",countif('3) Release_Label'!$E:$E,$B27)=0),"NO CATALOG ID MATCH in Release_Label",iserror(vlookup($A27&$B27,'3) Release_Label'!$D:$D&'3) Release_Label'!$E:$E,1,0)),"NO UPC-CATALOG ID pair MATCH in Release_Label" )} | D27: {=ifs(and(isblank($A27),isblank($B27)),"", not(iserror(vlookup($A27&$B27,'3) Release_Label'!$D:$D&'3) Release_Label'!$E:$E,1,0))),vlookup($A27&$B27,{'3) Release_Label'!$D:$D&'3) Release_Label'!$E:$E,'3) Release_Label'!$H:$H},2,0), or(and(not(isblank($B27)),$B27=$B26,$A27<>$A26),and(not(isblank($A27)),$A27=$A26,$B27<>$B26)),"ID LISTS UNALIGNED",and($A27<>"",countif('3) Release_Label'!$D:$D,$A27)=0),"NO UPC MATCH in Release_Label",and($B27<>"",countif('3) Release_Label'!$E:$E,$B27)=0),"NO CATALOG ID MATCH in Release_Label",iserror(vlookup($A27&$B27,'3) Release_Label'!$D:$D&'3) Release_Label'!$E:$E,1,0)),"NO UPC-CATALOG ID pair MATCH in Release_Label" )} | G27: {=ifs(or($F27="",$F27="Main Primary Artist"),$F27,not(iserror(vlookup($F27,'Reference info'!$J$5:$J$8,1,0))),"Key Artist",not(iserror(vlookup($F27,'Reference info'!$J$38:$J$405,1,0))),"Performer",not(iserror(vlookup($F27,'Reference info'!$J$10:$J$36,1,0))),"Producer & Engineer")}
... C1006: {=ifs(and(isblank($A1006),isblank($B1006)),"", not(iserror(vlookup($A1006&$B1006,'3) Release_Label'!$D:$D&'3) Release_Label'!$E:$E,1,0))),vlookup($A1006&$B1006,{'3) Release_Label'!$D:$D&'3) Release_Label'!$E:$E,'3) Release_Label'!$F:$F},2,0), or(and(not(isblank($B1006)),$B1006=$B1005,$A1006<>$A1005),and(not(isblank($A1006)),$A1006=$A1005,$B1006<>$B1005)),"ID LISTS UNALIGNED",and($A1006<>"",countif('3) Release_Label'!$D:$D,$A1006)=0),"NO UPC MATCH in Release_Label",and($B1006<>"",countif('3) Release_Label'!$E:$E,$B1006)=0),"NO CATALOG ID MATCH in Release_Label",iserror(vlookup($A1006&$B1006,'3) Release_Label'!$D:$D&'3) Release_Label'!$E:$E,1,0)),"NO UPC-CATALOG ID pair MATCH in Release_Label" )} | D1006: {=ifs(and(isblank($A1006),isblank($B1006)),"", not(iserror(vlookup($A1006&$B1006,'3) Release_Label'!$D:$D&'3) Release_Label'!$E:$E,1,0))),vlookup($A1006&$B1006,{'3) Release_Label'!$D:$D&'3) Release_Label'!$E:$E,'3) Release_Label'!$H:$H},2,0), or(and(not(isblank($B1006)),$B1006=$B1005,$A1006<>$A1005),and(not(isblank($A1006)),$A1006=$A1005,$B1006<>$B1005)),"ID LISTS UNALIGNED",and($A1006<>"",countif('3) Release_Label'!$D:$D,$A1006)=0),"NO UPC MATCH in Release_Label",and($B1006<>"",countif('3) Release_Label'!$E:$E,$B1006)=0),"NO CATALOG ID MATCH in Release_Label",iserror(vlookup($A1006&$B1006,'3) Release_Label'!$D:$D&'3) Release_Label'!$E:$E,1,0)),"NO UPC-CATALOG ID pair MATCH in Release_Label" )} | G1006: {=ifs(or($F1006="",$F1006="Main Primary Artist"),$F1006,not(iserror(vlookup($F1006,'Reference info'!$J$5:$J$8,1,0))),"Key Artist",not(iserror(vlookup($F1006,'Reference info'!$J$38:$J$405,1,0))),"Performer",not(iserror(vlookup($F1006,'Reference info'!$J$10:$J$36,1,0))),"Producer & Engineer")}

Sheet 5) Release_Track
A1: =IFERROR(__xludf.DUMMYFUNCTION("COUNTUNIQUE(A5:A1005)-'3) Release_Label'!D1"),0.0) -> 0 | B1: =IFERROR(__xludf.DUMMYFUNCTION("COUNTUNIQUE(B5:B1005)-'3) Release_Label'!E1"),0.0) -> 0 | C1: = FILLED AUTOMATICALLY IF CODES/IDS MATCH | E1: =count(E5:E1005) -> 2 | F1: =IFERROR(__xludf.DUMMYFUNCTION("COUNTUNIQUE(F5:F1005)"),2.0) -> 2 | G1: =IFERROR(__xludf.DUMMYFUNCTION("COUNTUNIQUE(G5:G1005)"),0.0) -> 0 | H1: = READ NOTES / INSTRUCTIONS | I1: = OPTIONAL | J1: = REQUIRED FIELD | M1: =IFERROR(__xludf.DUMMYFUNCTION("COUNTUNIQUE(M5:M1005)"),2.0) -> 2 | N1: =COUNTA(N5:N1005) -> 2
A2: TRACK LEVEL - UPC/ID<>ISRC/ID
A3: UPC / EAN / JAN | B3: CATALOG RELEASE ID | C3: RELEASE TITLE | D3: RELEASE VERSION | E3: TRACK | F3: ISRC/vISRC | G3: CATALOG TRACK ID | H3: TRACK TITLE | I3: TRACK VERSION | J3: LANGUAGE OF LYRICS | K3: EXPLICIT | L3: TYPE | M3: AUDIO FILE URL | N3: AUDIO TYPE | O3: TRACK PREVIEW | P3: COMPOSITION ISWC
A4: from Release_Label tab | B4: from Release_Label tab | C4: auto-fills if Release Code/Id matches Code/Id in Release_Label tab | E4: NUMBER | F4: CCXXXYY##### blank if no ISRC yet | G4: Internal Ref. ID required if no ISRC/vISRC | H4: Written EXACTLY as per label copy (no version, type or contributor info) | I4: If applicable | J4: (select from list, start typing or drag) If no lyrics, select Instrumental | K4: YES / NO | L4: Original / Public Domain | M4: public URL MUST trigger audio file DOWNLOAD | N4: wav / flac ONLY | O4: Preview Start Time (in seconds)
A5: 789294845633 | C5: {=ifs(and(isblank($A5),isblank($B5)),"", not(iserror(vlookup($A5&$B5,'3) Release_Label'!$D:$D&'3) Release_Label'!$E:$E,1,0))),vlookup($A5&$B5,{'3) Release_Label'!$D:$D&'3) Release_Label'!$E:$E,'3) Release_Label'!$F:$F},2,0), or(and(not(isblank($B5)),$B5=#REF!,$A5<>#REF!),and(not(isblank($A5)),$A5=#REF!,$B5<>#REF!)),"ID LISTS UNALIGNED",and($A5<>"",countif('3) Release_Label'!$D:$D,$A5)=0),"NO UPC MATCH in Release_Label",and($B5<>"",countif('3) Release_Label'!$E:$E,$B5)=0),"NO CATALOG ID MATCH in Release_Label",iserror(vlookup($A5&$B5,'3) Release_Label'!$D:$D&'3) Release_Label'!$E:$E,1,0)),"NO UPC-CATALOG ID pair MATCH in Release_Label" )} -> Receba | D5: {=ifs(and(isblank($A5),isblank($B5)),"", not(iserror(vlookup($A5&$B5,'3) Release_Label'!$D:$D&'3) Release_Label'!$E:$E,1,0))),vlookup($A5&$B5,{'3) Release_Label'!$D:$D&'3) Release_Label'!$E:$E,'3) Release_Label'!$H:$H},2,0), or(and(not(isblank($B5)),$B5=#REF!,$A5<>#REF!),and(not(isblank($A5)),$A5=#REF!,$B5<>#REF!)),"ID LISTS UNALIGNED",and($A5<>"",countif('3) Release_Label'!$D:$D,$A5)=0),"NO UPC MATCH in Release_Label",and($B5<>"",countif('3) Release_Label'!$E:$E,$B5)=0),"NO CATALOG ID MATCH in Release_Label",iserror(vlookup($A5&$B5,'3) Release_Label'!$D:$D&'3) Release_Label'!$E:$E,1,0)),"NO UPC-CATALOG ID pair MATCH in Release_Label" )} -> Extended | E5: =if(and(isblank($A5),isblank($B5)),"",if(not(iserror(find("MATCH in ",D5))),D5,if(or(and(not(isblank($B5)),$B5=$B4,$A5<>$A4),and(not(isblank($A5)),$A5=$A4,$B5<>$B4)),"ID LISTS UNALIGNED",if(not(isblank($A5)),if($A5=$A4,1+E4,1),if($B5=$B4,1+E4,1))))) -> 1 | F5: QZW9M2221000 | H5: Receba | I5: Extended | J5: Portuguese | K5: NO | L5: Original | M5: https://www.dropbox.com/scl/fi/sjv55c5eqq0utzgy15ojq/Joy-Mejia-Amarte-Es-Mi-Pasatiempo.wav?rlkey=6j5ruxil4gc3vxonuf8ownxvi&st=8kysye3f&dl=1 | N5: flac | O5: 140 | P5: T-123.456.789-0
A6: 789294962088 | C6: {=ifs(and(isblank($A6),isblank($B6)),"", not(iserror(vlookup($A6&$B6,'3) Release_Label'!$D:$D&'3) Release_Label'!$E:$E,1,0))),vlookup($A6&$B6,{'3) Release_Label'!$D:$D&'3) Release_Label'!$E:$E,'3) Release_Label'!$F:$F},2,0), or(and(not(isblank($B6)),$B6=$B5,$A6<>$A5),and(not(isblank($A6)),$A6=$A5,$B6<>$B5)),"ID LISTS UNALIGNED",and($A6<>"",countif('3) Release_Label'!$D:$D,$A6)=0),"NO UPC MATCH in Release_Label",and($B6<>"",countif('3) Release_Label'!$E:$E,$B6)=0),"NO CATALOG ID MATCH in Release_Label",iserror(vlookup($A6&$B6,'3) Release_Label'!$D:$D&'3) Release_Label'!$E:$E,1,0)),"NO UPC-CATALOG ID pair MATCH in Release_Label" )} -> A Cláusula do Contrato | D6: {=ifs(and(isblank($A6),isblank($B6)),"", not(iserror(vlookup($A6&$B6,'3) Release_Label'!$D:$D&'3) Release_Label'!$E:$E,1,0))),vlookup($A6&$B6,{'3) Release_Label'!$D:$D&'3) Release_Label'!$E:$E,'3) Release_Label'!$H:$H},2,0), or(and(not(isblank($B6)),$B6=$B5,$A6<>$A5),and(not(isblank($A6)),$A6=$A5,$B6<>$B5)),"ID LISTS UNALIGNED",and($A6<>"",countif('3) Release_Label'!$D:$D,$A6)=0),"NO UPC MATCH in Release_Label",and($B6<>"",countif('3) Release_Label'!$E:$E,$B6)=0),"NO CATALOG ID MATCH in Release_Label",iserror(vlookup($A6&$B6,'3) Release_Label'!$D:$D&'3) Release_Label'!$E:$E,1,0)),"NO UPC-CATALOG ID pair MATCH in Release_Label" )} | E6: =if(and(isblank($A6),isblank($B6)),"",if(not(iserror(find("MATCH in ",D6))),D6,if(or(and(not(isblank($B6)),$B6=$B5,$A6<>$A5),and(not(isblank($A6)),$A6=$A5,$B6<>$B5)),"ID LISTS UNALIGNED",if(not(isblank($A6)),if($A6=$A5,1+E5,1),if($B6=$B5,1+E5,1))))) -> 1 | F6: QZW9M2236571 | H6: A Cláusula do Contrato | J6: Portuguese | K6: NO | L6: Original | M6: https://www.dropbox.com/scl/fi/ncgo2nf5srfafm0odhequ/Joy-Mejia-Te-Fall.wav?rlkey=6jl64vr3v0w4tn6km1sbhlxux&st=um08pokf&dl=1 | N6: flac | O6: 200 | P6: T-123.456.789-0
C7: {=ifs(and(isblank($A7),isblank($B7)),"", not(iserror(vlookup($A7&$B7,'3) Release_Label'!$D:$D&'3) Release_Label'!$E:$E,1,0))),vlookup($A7&$B7,{'3) Release_Label'!$D:$D&'3) Release_Label'!$E:$E,'3) Release_Label'!$F:$F},2,0), or(and(not(isblank($B7)),$B7=$B6,$A7<>$A6),and(not(isblank($A7)),$A7=$A6,$B7<>$B6)),"ID LISTS UNALIGNED",and($A7<>"",countif('3) Release_Label'!$D:$D,$A7)=0),"NO UPC MATCH in Release_Label",and($B7<>"",countif('3) Release_Label'!$E:$E,$B7)=0),"NO CATALOG ID MATCH in Release_Label",iserror(vlookup($A7&$B7,'3) Release_Label'!$D:$D&'3) Release_Label'!$E:$E,1,0)),"NO UPC-CATALOG ID pair MATCH in Release_Label" )} | D7: {=ifs(and(isblank($A7),isblank($B7)),"", not(iserror(vlookup($A7&$B7,'3) Release_Label'!$D:$D&'3) Release_Label'!$E:$E,1,0))),vlookup($A7&$B7,{'3) Release_Label'!$D:$D&'3) Release_Label'!$E:$E,'3) Release_Label'!$H:$H},2,0), or(and(not(isblank($B7)),$B7=$B6,$A7<>$A6),and(not(isblank($A7)),$A7=$A6,$B7<>$B6)),"ID LISTS UNALIGNED",and($A7<>"",countif('3) Release_Label'!$D:$D,$A7)=0),"NO UPC MATCH in Release_Label",and($B7<>"",countif('3) Release_Label'!$E:$E,$B7)=0),"NO CATALOG ID MATCH in Release_Label",iserror(vlookup($A7&$B7,'3) Release_Label'!$D:$D&'3) Release_Label'!$E:$E,1,0)),"NO UPC-CATALOG ID pair MATCH in Release_Label" )} | E7: =if(and(isblank($A7),isblank($B7)),"",if(not(iserror(find("MATCH in ",D7))),D7,if(or(and(not(isblank($B7)),$B7=$B6,$A7<>$A6),and(not(isblank($A7)),$A7=$A6,$B7<>$B6)),"ID LISTS UNALIGNED",if(not(isblank($A7)),if($A7=$A6,1+E6,1),if($B7=$B6,1+E6,1)))))
C8: {=ifs(and(isblank($A8),isblank($B8)),"", not(iserror(vlookup($A8&$B8,'3) Release_Label'!$D:$D&'3) Release_Label'!$E:$E,1,0))),vlookup($A8&$B8,{'3) Release_Label'!$D:$D&'3) Release_Label'!$E:$E,'3) Release_Label'!$F:$F},2,0), or(and(not(isblank($B8)),$B8=$B7,$A8<>$A7),and(not(isblank($A8)),$A8=$A7,$B8<>$B7)),"ID LISTS UNALIGNED",and($A8<>"",countif('3) Release_Label'!$D:$D,$A8)=0),"NO UPC MATCH in Release_Label",and($B8<>"",countif('3) Release_Label'!$E:$E,$B8)=0),"NO CATALOG ID MATCH in Release_Label",iserror(vlookup($A8&$B8,'3) Release_Label'!$D:$D&'3) Release_Label'!$E:$E,1,0)),"NO UPC-CATALOG ID pair MATCH in Release_Label" )} | D8: {=ifs(and(isblank($A8),isblank($B8)),"", not(iserror(vlookup($A8&$B8,'3) Release_Label'!$D:$D&'3) Release_Label'!$E:$E,1,0))),vlookup($A8&$B8,{'3) Release_Label'!$D:$D&'3) Release_Label'!$E:$E,'3) Release_Label'!$H:$H},2,0), or(and(not(isblank($B8)),$B8=$B7,$A8<>$A7),and(not(isblank($A8)),$A8=$A7,$B8<>$B7)),"ID LISTS UNALIGNED",and($A8<>"",countif('3) Release_Label'!$D:$D,$A8)=0),"NO UPC MATCH in Release_Label",and($B8<>"",countif('3) Release_Label'!$E:$E,$B8)=0),"NO CATALOG ID MATCH in Release_Label",iserror(vlookup($A8&$B8,'3) Release_Label'!$D:$D&'3) Release_Label'!$E:$E,1,0)),"NO UPC-CATALOG ID pair MATCH in Release_Label" )} | E8: =if(and(isblank($A8),isblank($B8)),"",if(not(iserror(find("MATCH in ",D8))),D8,if(or(and(not(isblank($B8)),$B8=$B7,$A8<>$A7),and(not(isblank($A8)),$A8=$A7,$B8<>$B7)),"ID LISTS UNALIGNED",if(not(isblank($A8)),if($A8=$A7,1+E7,1),if($B8=$B7,1+E7,1)))))
C9: {=ifs(and(isblank($A9),isblank($B9)),"", not(iserror(vlookup($A9&$B9,'3) Release_Label'!$D:$D&'3) Release_Label'!$E:$E,1,0))),vlookup($A9&$B9,{'3) Release_Label'!$D:$D&'3) Release_Label'!$E:$E,'3) Release_Label'!$F:$F},2,0), or(and(not(isblank($B9)),$B9=$B8,$A9<>$A8),and(not(isblank($A9)),$A9=$A8,$B9<>$B8)),"ID LISTS UNALIGNED",and($A9<>"",countif('3) Release_Label'!$D:$D,$A9)=0),"NO UPC MATCH in Release_Label",and($B9<>"",countif('3) Release_Label'!$E:$E,$B9)=0),"NO CATALOG ID MATCH in Release_Label",iserror(vlookup($A9&$B9,'3) Release_Label'!$D:$D&'3) Release_Label'!$E:$E,1,0)),"NO UPC-CATALOG ID pair MATCH in Release_Label" )} | D9: {=ifs(and(isblank($A9),isblank($B9)),"", not(iserror(vlookup($A9&$B9,'3) Release_Label'!$D:$D&'3) Release_Label'!$E:$E,1,0))),vlookup($A9&$B9,{'3) Release_Label'!$D:$D&'3) Release_Label'!$E:$E,'3) Release_Label'!$H:$H},2,0), or(and(not(isblank($B9)),$B9=$B8,$A9<>$A8),and(not(isblank($A9)),$A9=$A8,$B9<>$B8)),"ID LISTS UNALIGNED",and($A9<>"",countif('3) Release_Label'!$D:$D,$A9)=0),"NO UPC MATCH in Release_Label",and($B9<>"",countif('3) Release_Label'!$E:$E,$B9)=0),"NO CATALOG ID MATCH in Release_Label",iserror(vlookup($A9&$B9,'3) Release_Label'!$D:$D&'3) Release_Label'!$E:$E,1,0)),"NO UPC-CATALOG ID pair MATCH in Release_Label" )} | E9: =if(and(isblank($A9),isblank($B9)),"",if(not(iserror(find("MATCH in ",D9))),D9,if(or(and(not(isblank($B9)),$B9=$B8,$A9<>$A8),and(not(isblank($A9)),$A9=$A8,$B9<>$B8)),"ID LISTS UNALIGNED",if(not(isblank($A9)),if($A9=$A8,1+E8,1),if($B9=$B8,1+E8,1)))))
C10: {=ifs(and(isblank($A10),isblank($B10)),"", not(iserror(vlookup($A10&$B10,'3) Release_Label'!$D:$D&'3) Release_Label'!$E:$E,1,0))),vlookup($A10&$B10,{'3) Release_Label'!$D:$D&'3) Release_Label'!$E:$E,'3) Release_Label'!$F:$F},2,0), or(and(not(isblank($B10)),$B10=$B9,$A10<>$A9),and(not(isblank($A10)),$A10=$A9,$B10<>$B9)),"ID LISTS UNALIGNED",and($A10<>"",countif('3) Release_Label'!$D:$D,$A10)=0),"NO UPC MATCH in Release_Label",and($B10<>"",countif('3) Release_Label'!$E:$E,$B10)=0),"NO CATALOG ID MATCH in Release_Label",iserror(vlookup($A10&$B10,'3) Release_Label'!$D:$D&'3) Release_Label'!$E:$E,1,0)),"NO UPC-CATALOG ID pair MATCH in Release_Label" )} | D10: {=ifs(and(isblank($A10),isblank($B10)),"", not(iserror(vlookup($A10&$B10,'3) Release_Label'!$D:$D&'3) Release_Label'!$E:$E,1,0))),vlookup($A10&$B10,{'3) Release_Label'!$D:$D&'3) Release_Label'!$E:$E,'3) Release_Label'!$H:$H},2,0), or(and(not(isblank($B10)),$B10=$B9,$A10<>$A9),and(not(isblank($A10)),$A10=$A9,$B10<>$B9)),"ID LISTS UNALIGNED",and($A10<>"",countif('3) Release_Label'!$D:$D,$A10)=0),"NO UPC MATCH in Release_Label",and($B10<>"",countif('3) Release_Label'!$E:$E,$B10)=0),"NO CATALOG ID MATCH in Release_Label",iserror(vlookup($A10&$B10,'3) Release_Label'!$D:$D&'3) Release_Label'!$E:$E,1,0)),"NO UPC-CATALOG ID pair MATCH in Release_Label" )} | E10: =if(and(isblank($A10),isblank($B10)),"",if(not(iserror(find("MATCH in ",D10))),D10,if(or(and(not(isblank($B10)),$B10=$B9,$A10<>$A9),and(not(isblank($A10)),$A10=$A9,$B10<>$B9)),"ID LISTS UNALIGNED",if(not(isblank($A10)),if($A10=$A9,1+E9,1),if($B10=$B9,1+E9,1)))))
