Workbook
Name EntId: '1) Artists list'!$H$1
Name CompContributor: '7) Comp ContributorPublisher li'!$A$5:$A$1001
Name TrackProperties: 'Reference info'!$R$3:$R$10
Name ReleaseType: 'Reference info'!$G$3:$G$7
Name Language: 'Reference info'!$K$3:$K$418
Name Publishing: 'Reference info'!$O$3:$O$5
Name ArtistRole: 'Reference info'!$J$3:$J$430
Name CompositionRole: 'Reference info'!$Q$3:$Q$14
Name Label: '2) Labels list'!$A$5:$A$999
Name Genre: 'Reference info'!$H$3:$H$419
Name Publisher: '7) Comp ContributorPublisher li'!$G$5:$G$1001
Name Artist: '1) Artists list'!$A$5:$A$999
Name TenantId: '1) Artists list'!$J$2

Sheet Introduction
B1: INTRODUCTION
A2: 1) | B2: Please make a copy of the master document in order to start filling it out. Make a copy by going to: File > Make a copy
A3: 2) | B3: Rename this document by replacing "MASTER" with your company name.
B7: You can also add anyone else from your team as needed.
B9: • Please fill out the catalog insert tabs enumerated in this spreadsheet by following the instructions in the corresponding fields and reading any applicable notes throughout
B10: • A black triangle in the top right corner of a cell means that there is a note — mouse over it to read it
B11: • If you are importing catalog metadata for reporting purposes only, then you only need to complete fields marked as REQUIRED as well as any UPC/ISRC or ID fields through tab 6
B13: Use the 'Sample Data' tab for additional guidance
B15: NOTE: Batch importing new catalog from the worksheet is generally not available on an ongoing basis so be sure all releases and tracks for import are included in the worksheet beforehand.
B16: After the initial import, adding catalog is meant to be done from the frontend of your account (or with the API if you are on an API plan). There are liable to be additional fees if the worksheet is to be used for new catalog after the initial import.
B18: • We DO NOT support importing files from Google Drive
B21: NO DSP sale reports should be uploaded and reporting feeds should NOT be set up until the account's catalog has been finalized, which includes the following steps:
B22: • ALL EXISTING catalog content has been imported
B23: • ALL catalog Delivery/Ingestion FEEDS have been DISABLED
B24: • Existing catalog has been validated (based on catalog export from account)
... B30: • Delete ALL error matching rules

Sheet 1) Artists list
A1: =IFERROR(__xludf.DUMMYFUNCTION("COUNTUNIQUE(A5:A999)-if(COUNTIF('4) Release_Artist(s)'!E:E, ""Various Artists"")>0,0,1)"),47.0) -> 47 | B1: List all Artists to Import | C1: =IFERROR(__xludf.DUMMYFUNCTION("COUNTUNIQUE(C5:C999)"),47.0) -> 47 | D1: =IFERROR(__xludf.DUMMYFUNCTION("COUNTUNIQUE(D5:D999)"),47.0) -> 47 | E1: =IFERROR(__xludf.DUMMYFUNCTION("COUNTUNIQUE(E5:E999)"),0.0) -> 0 | F1: =IFERROR(__xludf.DUMMYFUNCTION("COUNTUNIQUE(F5:F999)"),0.0) -> 0 | G1: =IFERROR(__xludf.DUMMYFUNCTION("COUNTUNIQUE(G5:G999)"),0.0) -> 0 | H1: =IFERROR(__xludf.DUMMYFUNCTION("COUNTUNIQUE(B5:B999)"),0.0) -> 0 | I1: EnterpriseId= | J1: 693619
A2: = REQUIRED FIELD | B2: = OPTIONAL FIELD | D2: = READ NOTES / INSTRUCTIONS | F2: = OPTIONAL FIELD | H2: =countif(B5:B999,"<>""")-countif(B5:B999,"") -> 0 | I2: TenantId= | J2: 332920
A3: Artist Name | B3: Artist Image url | C3: Apple ArtistId | D3: Spotify Artist URI | E3: Meta ArtistId | F3: SoundCloud ProfileId | G3: ISNI | I3: Duplicate Names
A4: Written EXACTLY as per label copy | B4: public URL triggering DIRECT DOWNLOAD of file | C4: Enter Artist's AppleId or 'NEW'=new AppleId | D4: Enter Artist's Spotify URI link or 'NEW'=new Spotify URI link | E4: Facebook Audio Library & Rights Manager ArtistId | F4: SoundCloud Artist Username | I4: =IFERROR(__xludf.DUMMYFUNCTION("counta(A5:A999)-COUNTUNIQUE(A5:A999)"),0.0) -> 0
A5: Ranjit Bawa | C5: 999098231 | D5: spotify:artist:6pU5oz09VUYtnFTd4P1Mxn | I5: =IFERROR(__xludf.DUMMYFUNCTION("if(B5="""","""",""insert into Images VALUES (NEWID(),'""&REGEXREPLACE(A5,""[^[:alnum:]]"","""")&EntId&H5&""', '""&H5&""', getdate(), 0, null, '""&trim(B5)&""', 0, getdate(), null, null)"")"),"")
A6: Sunidhi Chauhan | C6: 14291650 | D6: spotify:artist:3eDT9fwXKuHWFvgZaaYC5v
A7: Gurmoh | C7: 591803144 | D7: spotify:artist:3mgciNhvc5PbGOjbmfcU2s
A8: Amrinder Gill | C8: 205696074 | D8: spotify:artist:1x02ug1CLkx7mrQP9FRswh
A9: Jatinder Shah | C9: 442638980 | D9: spotify:artist:4vGVzTMuXsO1vb5YA8vKEr
A10: Nimrat Khaira | C10: 1043132330 | D10: spotify:artist:0ea0y5ZxnN5TbEDzNtx5Fk
A11: Ammy Virk | C11: 492592838 | D11: spotify:artist:2RlWC7XKizSOsZ8F3uGi59
A12: Gurshabad | C12: 1042246708 | D12: spotify:artist:557gXmWZK1P5T3yNLjvLXP
A13: Tarsem Jassar | C13: 598287173 | D13: spotify:artist:67XQGZSc63AMXMINY8H7Fx
A14: R. Guru | C14: 1490004980 | D14: spotify:artist:2LKgaY0VVvgyQniOk6JA3V
A15: Bir Singh | C15: 1088182751 | D15: spotify:artist:6Su06O6MCxKJXOtxkM8iBi
A16: Satta Vairowalia | C16: 1017611432 | D16: spotify:artist:6NXhW9mHzDrkMl3SfFoCuG
A17: Gurpreet Maan | C17: 935676399 | D17: spotify:artist:5ukG4Kfwgbpt2oUWWTKNTM
... A51: B Praak | C51: 747872156 | D51: spotify:artist:56SjZARoEvag3RoKWIb16j
A999: Various Artists

Sheet 2) Labels list
A1: List all Labels to Import | B1: =IFERROR(__xludf.DUMMYFUNCTION("COUNTUNIQUE(A5:A999)"),1.0) -> 1
A2: = REQUIRED FIELD | B2: Duplicate Names
A3: Label Name | B3: =IFERROR(__xludf.DUMMYFUNCTION("counta(A5:A999)-COUNTUNIQUE(A5:A999)"),0.0) -> 0
A4: Written EXACTLY as per label copy
A5: Rhythm Boyz

Sheet 3) Release_Label
A1: =IFERROR(__xludf.DUMMYFUNCTION("COUNTUNIQUE(A5:A996)"),1.0) -> 1 | B1: = REQUIRED FIELD | C1: =IFERROR(__xludf.DUMMYFUNCTION("COUNTUNIQUE(B5:B996)"),71.0) -> 71 | D1: =IFERROR(__xludf.DUMMYFUNCTION("COUNTUNIQUE(D5:D996)"),71.0) -> 71 | E1: =IFERROR(__xludf.DUMMYFUNCTION("COUNTUNIQUE(E5:E996)"),0.0) -> 0 | F1: = READ NOTES / INSTRUCTIONS | G1: =COUNTA(F5:F996) -> 71 | H1: = OPTIONAL | I1: =countif(I5:I996,"Video")+countif(I5:I996,"Ringtone") -> 0 | M1: = REQUIRED FIELD | N1: = OPTIONAL
A2: RELEASE LEVEL - Label<>UPC/ID
A3: LABEL | B3: COVER IMAGE URL | C3: IMAGE TYPE | D3: UPC / EAN / JAN | E3: CATALOG RELEASE ID | F3: RELEASE TITLE | G3: TITLE LANGUAGE | H3: RELEASE VERSION | I3: RELEASE TYPE | J3: (P) Copyright | L3: (C) Copyright | N3: ORIGINAL RELEASE DATE | O3: GENRE 1 | P3: GENRE 2
A4: (select from Labels list, start typing or drag) | B4: public URL triggering DIRECT DOWNLOAD of file (10 MB max) required if distributing content | C4: jpeg / jpg ONLY | D4: UPC: 12 digits EAN: 13 digits blank if no code yet | E4: Internal Ref. ID required if no code yet | F4: Written EXACTLY as per label copy (no version, type or contributor info) | G4: (select from list, start typing or drag) | H4: If applicable | I4: (select from list, start typing or drag) | J4: Year | K4: Holder | L4: Year | M4: Holder | N4: YYYY-MM-DD | O4: (select from list, start typing or drag) | P4: (select from list, start typing or drag)
A5: Rhythm Boyz | B5: https://www.dropbox.com/scl/fi/qufijuq6phjyuq27sgstf/9995964332174.jpg?rlkey=wbd7ow19kc9yjnzje9xip5sok&st=ejmpczbx&dl=1 | C5: jpg | D5: 9995964332174 | F5: Aakad (From "Bhalwan Singh" Soundtrack) | G5: Punjabi | J5: 2017 | K5: Rhythm Boyz | L5: 2017 | M5: Rhythm Boyz | N5: 43029 | O5: Punjabi
A6: Rhythm Boyz | B6: https://www.dropbox.com/scl/fi/jk53oygv0mtn5g0z4ph2q/9995964356132.jpg?rlkey=cnw9bgvu42zneygn88zu9y25k&st=kukw5670&dl=1 | C6: jpg | D6: 9995964356132 | F6: Aisi Taisi (From "Golak Bugni Bank Te Batua" Soundtrack) | G6: Punjabi | J6: 2018 | K6: Rhythm Boyz | L6: 2018 | M6: Rhythm Boyz | N6: 43186 | O6: Punjabi
A7: Rhythm Boyz | B7: https://www.dropbox.com/scl/fi/ooqoh3adyfd75t3fp8b8f/9995964330651.jpg?rlkey=i3ia0ggccao5jx3v1xm2ds9gx&st=jp53xlf8&dl=1 | C7: jpg | D7: 9995964330651 | F7: Akhar - Female Version (From "Lahoriye" Soundtrack) | G7: Punjabi | J7: 2017 | K7: Rhythm Boyz | L7: 2017 | M7: Rhythm Boyz | N7: 43013 | O7: Punjabi
A8: Rhythm Boyz | B8: https://www.dropbox.com/scl/fi/kl3plq1efi0h99ig931pi/9995964330088.jpg?rlkey=ljx8c2idx1y64f1agfxabpj8d&st=gdpx78pq&dl=1 | C8: jpg | D8: 9995964330088 | F8: Akhar (From "Lahoriye" Soundtrack) | G8: Punjabi | J8: 2017 | K8: Rhythm Boyz | L8: 2017 | M8: Rhythm Boyz | N8: 42815 | O8: Punjabi
A9: Rhythm Boyz | B9: https://www.dropbox.com/scl/fi/9clnttcj5jh46hdnem2yf/9995964312657.jpg?rlkey=6a2gv031koqn7lab2xhbpstaz&st=5qrd9q82&dl=1 | C9: jpg | D9: 9995964312657 | F9: Angrej (Original Motion Picture Soundtrack) | G9: Punjabi | J9: 2015 | K9: Rhythm Boyz | L9: 2015 | M9: Rhythm Boyz | N9: 42208 | O9: Punjabi
A10: Rhythm Boyz | B10: https://www.dropbox.com/scl/fi/qu9mon6dhf6zcd9nf9u8j/9995964321390.jpg?rlkey=gh1yqcjqd6tndpkoltu0d0bsj&st=4fodrmi1&dl=1 | C10: jpg | D10: 9995964321390 | F10: Bambukat (From "Bambukat" Soundtrack) | G10: Punjabi | J10: 2016 | K10: Rhythm Boyz | L10: 2016 | M10: Rhythm Boyz | N10: 42578 | O10: Punjabi
A11: Rhythm Boyz | B11: https://www.dropbox.com/scl/fi/5obuv3byyzpudqegm9jem/9995964330187.jpg?rlkey=6ircnk2t5wpgozit6qdyvug5d&st=kqit24nw&dl=1 | C11: jpg | D11: 9995964330187 | F11: Chann Ve | G11: Punjabi | J11: 2017 | K11: Rhythm Boyz | L11: 2017 | M11: Rhythm Boyz | N11: 42824 | O11: Punjabi
A12: Rhythm Boyz | B12: https://www.dropbox.com/scl/fi/v2ej6tz1ohnn9yzgo0nfg/9995964330446.jpg?rlkey=fj0gio1t6j8557388vocmiciv&st=p4p8aqe3&dl=1 | C12: jpg | D12: 9995964330446 | F12: Chunni (From "Lahoriye" Soundtrack) | G12: Punjabi | J12: 2017 | K12: Rhythm Boyz | L12: 2017 | M12: Rhythm Boyz | N12: 42848 | O12: Punjabi
A13: Rhythm Boyz | B13: https://www.dropbox.com/scl/fi/cwnf46zcvczf2vgkpl1i8/9995964357078.jpg?rlkey=3v5943hxc8x37zndmkav2xyyh&st=lme4npqz&dl=1 | C13: jpg | D13: 9995964357078 | F13: Daana Paani - Title Song (From "Daana Paani" Soundtrack) | G13: Punjabi | J13: 2018 | K13: Rhythm Boyz | L13: 2018 | M13: Rhythm Boyz | N13: 43286 | O13: Punjabi
A14: Rhythm Boyz | B14: https://www.dropbox.com/scl/fi/h7aax7ov58o7p2o5u9oxp/9995964357016.jpg?rlkey=bwegzrcmkipujshp1nftrux4m&st=bep1drs0&dl=1 | C14: jpg | D14: 9995964357016 | F14: Daana Paani (From "Daana Paani" Soundtrack) | G14: Punjabi | J14: 2018 | K14: Rhythm Boyz | L14: 2018 | M14: Rhythm Boyz | N14: 43105 | O14: Punjabi
A15: Rhythm Boyz | B15: https://www.dropbox.com/scl/fi/5jwtx12fg73gb30md8itr/9995964332198.jpg?rlkey=a1at9qaz0izecnw7xc6wxmosb&st=sg9a4blk&dl=1 | C15: jpg | D15: 9995964332198 | F15: Dil Di Dua (From "Bhalwan Singh" Soundtrack) | G15: Punjabi | J15: 2017 | K15: Rhythm Boyz | L15: 2017 | M15: Rhythm Boyz | N15: 43031 | O15: Punjabi
A16: Rhythm Boyz | B16: https://www.dropbox.com/scl/fi/ko30g71pn0qpbl4y8i68v/9995964321710.jpg?rlkey=jun4sw5svvh55ypuurnia559t&st=841t61xv&dl=1 | C16: jpg | D16: 9995964321710 | F16: Geetkariyan | G16: Punjabi | J16: 2016 | K16: Rhythm Boyz | L16: 2016 | M16: Rhythm Boyz | N16: 42600 | O16: Punjabi
... A75: Rhythm Boyz | B75: https://www.dropbox.com/scl/fi/c5wehe6pilb75qcb31hdc/9999552111417.jpg?rlkey=n01eo7wlj1hrhu3wojo0901mc&st=yr73bn1l&dl=1 | C75: jpg | D75: 9999552111417 | F75: Doubt | G75: Punjabi | J75: 2020 | K75: Rhythm Boyz | L75: 2020 | M75: Rhythm Boyz | N75: 44047 | O75: Punjabi

Sheet 4) Release_Artist(s)
A1: =IFERROR(__xludf.DUMMYFUNCTION("COUNTUNIQUE(A5:A926)-'3) Release_Label'!D1"),0.0) -> 0 | B1: =IFERROR(__xludf.DUMMYFUNCTION("COUNTUNIQUE(B5:B926)-'3) Release_Label'!E1"),0.0) -> 0 | C1: = FILLED AUTOMATICALLY IF CODES/IDS MATCH | E1: =IFERROR(__xludf.DUMMYFUNCTION("COUNTUNIQUE(E5:E926)"),45.0) -> 45 | F1: = REQUIRED FIELD | G1: =countif(F:F,"Main Primary Artist")-'3) Release_Label'!G1 -> 0 | H1: = READ NOTES / INSTRUCTIONS
A2: RELEASE LEVEL - Artist<>UPC/ID : One Arist per row. If a Release has multiple Artists, add the same Release Code/ID to a new row for each Artist.
A3: UPC / EAN / JAN | B3: CATALOG RELEASE ID | C3: RELEASE TITLE | D3: RELEASE VERSION | E3: ARTIST | F3: ARTIST ROLE | G3: ARTIST ROLE CATEGORY | H3: =IFERROR(__xludf.DUMMYFUNCTION("if(iserror(filter(A:B,G:G=""Producer & Engineer"")),0, countunique(filter(A:B,G:G=""Producer & Engineer"")))-'3) Release_Label'!G1"),0.0) -> 0
A4: from Release_Label tab | B4: from Release_Label tab | C4: auto-fills if Release Code/Id matches Code/Id in Release_Label tab | E4: ONE ARTIST PER ROW select from Artists list, start typing or drag If compilation: Various Artists | F4: (select from list, start typing or drag) | G4: artist category auto-fills based on artist role | H4: =IFERROR(__xludf.DUMMYFUNCTION("if(iserror(filter(A:B,G:G=""Performer"")),0, countunique(filter(A:B,G:G=""Performer"")))-'3) Release_Label'!G1"),-71.0) -> -71
A5: 9995964332174 | C5: {=ifs(and(isblank($A5),isblank($B5)),"", not(iserror(vlookup($A5&$B5,'3) Release_Label'!$D:$D&'3) Release_Label'!$E:$E,1,0))),vlookup($A5&$B5,{'3) Release_Label'!$D:$D&'3) Release_Label'!$E:$E,'3) Release_Label'!$F:$F},2,0), or(and(not(isblank($B5)),$B5=$B4,$A5<>$A4),and(not(isblank($A5)),$A5=$A4,$B5<>$B4)),"ID LISTS UNALIGNED",and($A5<>"",countif('3) Release_Label'!$D:$D,$A5)=0),"NO UPC MATCH in Release_Label",and($B5<>"",countif('3) Release_Label'!$E:$E,$B5)=0),"NO CATALOG ID MATCH in Release_Label",iserror(vlookup($A5&$B5,'3) Release_Label'!$D:$D&'3) Release_Label'!$E:$E,1,0)),"NO UPC-CATALOG ID pair MATCH in Release_Label" )} -> Aakad (From "Bhalwan Singh" Soundtrack) | D5: {=ifs(and(isblank($A5),isblank($B5)),"", not(iserror(vlookup($A5&$B5,'3) Release_Label'!$D:$D&'3) Release_Label'!$E:$E,1,0))),vlookup($A5&$B5,{'3) Release_Label'!$D:$D&'3) Release_Label'!$E:$E,'3) Release_Label'!$H:$H},2,0), or(and(not(isblank($B5)),$B5=$B4,$A5<>$A4),and(not(isblank($A5)),$A5=$A4,$B5<>$B4)),"ID LISTS UNALIGNED",and($A5<>"",countif('3) Release_Label'!$D:$D,$A5)=0),"NO UPC MATCH in Release_Label",and($B5<>"",countif('3) Release_Label'!$E:$E,$B5)=0),"NO CATALOG ID MATCH in Release_Label",iserror(vlookup($A5&$B5,'3) Release_Label'!$D:$D&'3) Release_Label'!$E:$E,1,0)),"NO UPC-CATALOG ID pair MATCH in Release_Label" )} | E5: Ranjit Bawa | F5: Main Primary Artist | G5: {=ifs(or($F5="",$F5="Main Primary Artist"),$F5,not(iserror(vlookup($F5,'Reference info'!$J$5:$J$8,1,0))),"Key Artist",not(iserror(vlookup($F5,'Reference info'!$J$38:$J$405,1,0))),"Performer",not(iserror(vlookup($F5,'Reference info'!$J$10:$J$36,1,0))),"Producer & Engineer")} -> Main Primary Artist
A6: 9995964332174 | C6: {=ifs(and(isblank($A6),isblank($B6)),"", not(iserror(vlookup($A6&$B6,'3) Release_Label'!$D:$D&'3) Release_Label'!$E:$E,1,0))),vlookup($A6&$B6,{'3) Release_Label'!$D:$D&'3) Release_Label'!$E:$E,'3) Release_Label'!$F:$F},2,0), or(and(not(isblank($B6)),$B6=$B5,$A6<>$A5),and(not(isblank($A6)),$A6=$A5,$B6<>$B5)),"ID LISTS UNALIGNED",and($A6<>"",countif('3) Release_Label'!$D:$D,$A6)=0),"NO UPC MATCH in Release_Label",and($B6<>"",countif('3) Release_Label'!$E:$E,$B6)=0),"NO CATALOG ID MATCH in Release_Label",iserror(vlookup($A6&$B6,'3) Release_Label'!$D:$D&'3) Release_Label'!$E:$E,1,0)),"NO UPC-CATALOG ID pair MATCH in Release_Label" )} -> Aakad (From "Bhalwan Singh" Soundtrack) | D6: {=ifs(and(isblank($A6),isblank($B6)),"", not(iserror(vlookup($A6&$B6,'3) Release_Label'!$D:$D&'3) Release_Label'!$E:$E,1,0))),vlookup($A6&$B6,{'3) Release_Label'!$D:$D&'3) Release_Label'!$E:$E,'3) Release_Label'!$H:$H},2,0), or(and(not(isblank($B6)),$B6=$B5,$A6<>$A5),and(not(isblank($A6)),$A6=$A5,$B6<>$B5)),"ID LISTS UNALIGNED",and($A6<>"",countif('3) Release_Label'!$D:$D,$A6)=0),"NO UPC MATCH in Release_Label",and($B6<>"",countif('3) Release_Label'!$E:$E,$B6)=0),"NO CATALOG ID MATCH in Release_Label",iserror(vlookup($A6&$B6,'3) Release_Label'!$D:$D&'3) Release_Label'!$E:$E,1,0)),"NO UPC-CATALOG ID pair MATCH in Release_Label" )} | E6: Sunidhi Chauhan | F6: Primary Artist | G6: {=ifs(or($F6="",$F6="Main Primary Artist"),$F6,not(iserror(vlookup($F6,'Reference info'!$J$5:$J$8,1,0))),"Key Artist",not(iserror(vlookup($F6,'Reference info'!$J$38:$J$405,1,0))),"Performer",not(iserror(vlookup($F6,'Reference info'!$J$10:$J$36,1,0))),"Producer & Engineer")} -> Key Artist
A7: 9995964332174 | C7: {=ifs(and(isblank($A7),isblank($B7)),"", not(iserror(vlookup($A7&$B7,'3) Release_Label'!$D:$D&'3) Release_Label'!$E:$E,1,0))),vlookup($A7&$B7,{'3) Release_Label'!$D:$D&'3) Release_Label'!$E:$E,'3) Release_Label'!$F:$F},2,0), or(and(not(isblank($B7)),$B7=$B6,$A7<>$A6),and(not(isblank($A7)),$A7=$A6,$B7<>$B6)),"ID LISTS UNALIGNED",and($A7<>"",countif('3) Release_Label'!$D:$D,$A7)=0),"NO UPC MATCH in Release_Label",and($B7<>"",countif('3) Release_Label'!$E:$E,$B7)=0),"NO CATALOG ID MATCH in Release_Label",iserror(vlookup($A7&$B7,'3) Release_Label'!$D:$D&'3) Release_Label'!$E:$E,1,0)),"NO UPC-CATALOG ID pair MATCH in Release_Label" )} -> Aakad (From "Bhalwan Singh" Soundtrack) | D7: {=ifs(and(isblank($A7),isblank($B7)),"", not(iserror(vlookup($A7&$B7,'3) Release_Label'!$D:$D&'3) Release_Label'!$E:$E,1,0))),vlookup($A7&$B7,{'3) Release_Label'!$D:$D&'3) Release_Label'!$E:$E,'3) Release_Label'!$H:$H},2,0), or(and(not(isblank($B7)),$B7=$B6,$A7<>$A6),and(not(isblank($A7)),$A7=$A6,$B7<>$B6)),"ID LISTS UNALIGNED",and($A7<>"",countif('3) Release_Label'!$D:$D,$A7)=0),"NO UPC MATCH in Release_Label",and($B7<>"",countif('3) Release_Label'!$E:$E,$B7)=0),"NO CATALOG ID MATCH in Release_Label",iserror(vlookup($A7&$B7,'3) Release_Label'!$D:$D&'3) Release_Label'!$E:$E,1,0)),"NO UPC-CATALOG ID pair MATCH in Release_Label" )} | E7: Gurmoh | F7: With | G7: {=ifs(or($F7="",$F7="Main Primary Artist"),$F7,not(iserror(vlookup($F7,'Reference info'!$J$5:$J$8,1,0))),"Key Artist",not(iserror(vlookup($F7,'Reference info'!$J$38:$J$405,1,0))),"Performer",not(iserror(vlookup($F7,'Reference info'!$J$10:$J$36,1,0))),"Producer & Engineer")} -> Key Artist
A8: 9995964332174 | C8: {=ifs(and(isblank($A8),isblank($B8)),"", not(iserror(vlookup($A8&$B8,'3) Release_Label'!$D:$D&'3) Release_Label'!$E:$E,1,0))),vlookup($A8&$B8,{'3) Release_Label'!$D:$D&'3) Release_Label'!$E:$E,'3) Release_Label'!$F:$F},2,0), or(and(not(isblank($B8)),$B8=$B6,$A8<>$A6),and(not(isblank($A8)),$A8=$A6,$B8<>$B6)),"ID LISTS UNALIGNED",and($A8<>"",countif('3) Release_Label'!$D:$D,$A8)=0),"NO UPC MATCH in Release_Label",and($B8<>"",countif('3) Release_Label'!$E:$E,$B8)=0),"NO CATALOG ID MATCH in Release_Label",iserror(vlookup($A8&$B8,'3) Release_Label'!$D:$D&'3) Release_Label'!$E:$E,1,0)),"NO UPC-CATALOG ID pair MATCH in Release_Label" )} -> Aakad (From "Bhalwan Singh" Soundtrack) | D8: {=ifs(and(isblank($A8),isblank($B8)),"", not(iserror(vlookup($A8&$B8,'3) Release_Label'!$D:$D&'3) Release_Label'!$E:$E,1,0))),vlookup($A8&$B8,{'3) Release_Label'!$D:$D&'3) Release_Label'!$E:$E,'3) Release_Label'!$H:$H},2,0), or(and(not(isblank($B8)),$B8=$B6,$A8<>$A6),and(not(isblank($A8)),$A8=$A6,$B8<>$B6)),"ID LISTS UNALIGNED",and($A8<>"",countif('3) Release_Label'!$D:$D,$A8)=0),"NO UPC MATCH in Release_Label",and($B8<>"",countif('3) Release_Label'!$E:$E,$B8)=0),"NO CATALOG ID MATCH in Release_Label",iserror(vlookup($A8&$B8,'3) Release_Label'!$D:$D&'3) Release_Label'!$E:$E,1,0)),"NO UPC-CATALOG ID pair MATCH in Release_Label" )} | E8: Gurmoh | F8: Producer | G8: {=ifs(or($F8="",$F8="Main Primary Artist"),$F8,not(iserror(vlookup($F8,'Reference info'!$J$5:$J$8,1,0))),"Key Artist",not(iserror(vlookup($F8,'Reference info'!$J$38:$J$405,1,0))),"Performer",not(iserror(vlookup($F8,'Reference info'!$J$10:$J$36,1,0))),"Producer & Engineer")} -> Producer & Engineer
A9: 9995964356132 | C9: {=ifs(and(isblank($A9),isblank($B9)),"", not(iserror(vlookup($A9&$B9,'3) Release_Label'!$D:$D&'3) Release_Label'!$E:$E,1,0))),vlookup($A9&$B9,{'3) Release_Label'!$D:$D&'3) Release_Label'!$E:$E,'3) Release_Label'!$F:$F},2,0), or(and(not(isblank($B9)),$B9=$B7,$A9<>$A7),and(not(isblank($A9)),$A9=$A7,$B9<>$B7)),"ID LISTS UNALIGNED",and($A9<>"",countif('3) Release_Label'!$D:$D,$A9)=0),"NO UPC MATCH in Release_Label",and($B9<>"",countif('3) Release_Label'!$E:$E,$B9)=0),"NO CATALOG ID MATCH in Release_Label",iserror(vlookup($A9&$B9,'3) Release_Label'!$D:$D&'3) Release_Label'!$E:$E,1,0)),"NO UPC-CATALOG ID pair MATCH in Release_Label" )} -> Aisi Taisi (From "Golak Bugni Bank Te Batua" Soundtrack) | D9: {=ifs(and(isblank($A9),isblank($B9)),"", not(iserror(vlookup($A9&$B9,'3) Release_Label'!$D:$D&'3) Release_Label'!$E:$E,1,0))),vlookup($A9&$B9,{'3) Release_Label'!$D:$D&'3) Release_Label'!$E:$E,'3) Release_Label'!$H:$H},2,0), or(and(not(isblank($B9)),$B9=$B7,$A9<>$A7),and(not(isblank($A9)),$A9=$A7,$B9<>$B7)),"ID LISTS UNALIGNED",and($A9<>"",countif('3) Release_Label'!$D:$D,$A9)=0),"NO UPC MATCH in Release_Label",and($B9<>"",countif('3) Release_Label'!$E:$E,$B9)=0),"NO CATALOG ID MATCH in Release_Label",iserror(vlookup($A9&$B9,'3) Release_Label'!$D:$D&'3) Release_Label'!$E:$E,1,0)),"NO UPC-CATALOG ID pair MATCH in Release_Label" )} | E9: Amrinder Gill | F9: Main Primary Artist | G9: {=ifs(or($F9="",$F9="Main Primary Artist"),$F9,not(iserror(vlookup($F9,'Reference info'!$J$5:$J$8,1,0))),"Key Artist",not(iserror(vlookup($F9,'Reference info'!$J$38:$J$405,1,0))),"Performer",not(iserror(vlookup($F9,'Reference info'!$J$10:$J$36,1,0))),"Producer & Engineer")} -> Main Primary Artist
A10: 9995964356132 | C10: {=ifs(and(isblank($A10),isblank($B10)),"", not(iserror(vlookup($A10&$B10,'3) Release_Label'!$D:$D&'3) Release_Label'!$E:$E,1,0))),vlookup($A10&$B10,{'3) Release_Label'!$D:$D&'3) Release_Label'!$E:$E,'3) Release_Label'!$F:$F},2,0), or(and(not(isblank($B10)),$B10=$B9,$A10<>$A9),and(not(isblank($A10)),$A10=$A9,$B10<>$B9)),"ID LISTS UNALIGNED",and($A10<>"",countif('3) Release_Label'!$D:$D,$A10)=0),"NO UPC MATCH in Release_Label",and($B10<>"",countif('3) Release_Label'!$E:$E,$B10)=0),"NO CATALOG ID MATCH in Release_Label",iserror(vlookup($A10&$B10,'3) Release_Label'!$D:$D&'3) Release_Label'!$E:$E,1,0)),"NO UPC-CATALOG ID pair MATCH in Release_Label" )} -> Aisi Taisi (From "Golak Bugni Bank Te Batua" Soundtrack) | D10: {=ifs(and(isblank($A10),isblank($B10)),"", not(iserror(vlookup($A10&$B10,'3) Release_Label'!$D:$D&'3) Release_Label'!$E:$E,1,0))),vlookup($A10&$B10,{'3) Release_Label'!$D:$D&'3) Release_Label'!$E:$E,'3) Release_Label'!$H:$H},2,0), or(and(not(isblank($B10)),$B10=$B9,$A10<>$A9),and(not(isblank($A10)),$A10=$A9,$B10<>$B9)),"ID LISTS UNALIGNED",and($A10<>"",countif('3) Release_Label'!$D:$D,$A10)=0),"NO UPC MATCH in Release_Label",and($B10<>"",countif('3) Release_Label'!$E:$E,$B10)=0),"NO CATALOG ID MATCH in Release_Label",iserror(vlookup($A10&$B10,'3) Release_Label'!$D:$D&'3) Release_Label'!$E:$E,1,0)),"NO UPC-CATALOG ID pair MATCH in Release_Label" )} | E10: Jatinder Shah | F10: With | G10: {=ifs(or($F10="",$F10="Main Primary Artist"),$F10,not(iserror(vlookup($F10,'Reference info'!$J$5:$J$8,1,0))),"Key Artist",not(iserror(vlookup($F10,'Reference info'!$J$38:$J$405,1,0))),"Performer",not(iserror(vlookup($F10,'Reference info'!$J$10:$J$36,1,0))),"Producer & Engineer")} -> Key Artist
A11: 9995964330651 | C11: {=ifs(and(isblank($A11),isblank($B11)),"", not(iserror(vlookup($A11&$B11,'3) Release_Label'!$D:$D&'3) Release_Label'!$E:$E,1,0))),vlookup($A11&$B11,{'3) Release_Label'!$D:$D&'3) Release_Label'!$E:$E,'3) Release_Label'!$F:$F},2,0), or(and(not(isblank($B11)),$B11=$B10,$A11<>$A10),and(not(isblank($A11)),$A11=$A10,$B11<>$B10)),"ID LISTS UNALIGNED",and($A11<>"",countif('3) Release_Label'!$D:$D,$A11)=0),"NO UPC MATCH in Release_Label",and($B11<>"",countif('3) Release_Label'!$E:$E,$B11)=0),"NO CATALOG ID MATCH in Release_Label",iserror(vlookup($A11&$B11,'3) Release_Label'!$D:$D&'3) Release_Label'!$E:$E,1,0)),"NO UPC-CATALOG ID pair MATCH in Release_Label" )} -> Akhar - Female Version (From "Lahoriye" Soundtrack) | D11: {=ifs(and(isblank($A11),isblank($B11)),"", not(iserror(vlookup($A11&$B11,'3) Release_Label'!$D:$D&'3) Release_Label'!$E:$E,1,0))),vlookup($A11&$B11,{'3) Release_Label'!$D:$D&'3) Release_Label'!$E:$E,'3) Release_Label'!$H:$H},2,0), or(and(not(isblank($B11)),$B11=$B10,$A11<>$A10),and(not(isblank($A11)),$A11=$A10,$B11<>$B10)),"ID LISTS UNALIGNED",and($A11<>"",countif('3) Release_Label'!$D:$D,$A11)=0),"NO UPC MATCH in Release_Label",and($B11<>"",countif('3) Release_Label'!$E:$E,$B11)=0),"NO CATALOG ID MATCH in Release_Label",iserror(vlookup($A11&$B11,'3) Release_Label'!$D:$D&'3) Release_Label'!$E:$E,1,0)),"NO UPC-CATALOG ID pair MATCH in Release_Label" )} | E11: Nimrat Khaira | F11: Main Primary Artist | G11: {=ifs(or($F11="",$F11="Main Primary Artist"),$F11,not(iserror(vlookup($F11,'Reference info'!$J$5:$J$8,1,0))),"Key Artist",not(iserror(vlookup($F11,'Reference info'!$J$38:$J$405,1,0))),"Performer",not(iserror(vlookup($F11,'Reference info'!$J$10:$J$36,1,0))),"Producer & Engineer")} -> Main Primary Artist
A12: 9995964330651 | C12: {=ifs(and(isblank($A12),isblank($B12)),"", not(iserror(vlookup($A12&$B12,'3) Release_Label'!$D:$D&'3) Release_Label'!$E:$E,1,0))),vlookup($A12&$B12,{'3) Release_Label'!$D:$D&'3) Release_Label'!$E:$E,'3) Release_Label'!$F:$F},2,0), or(and(not(isblank($B12)),$B12=$B11,$A12<>$A11),and(not(isblank($A12)),$A12=$A11,$B12<>$B11)),"ID LISTS UNALIGNED",and($A12<>"",countif('3) Release_Label'!$D:$D,$A12)=0),"NO UPC MATCH in Release_Label",and($B12<>"",countif('3) Release_Label'!$E:$E,$B12)=0),"NO CATALOG ID MATCH in Release_Label",iserror(vlookup($A12&$B12,'3) Release_Label'!$D:$D&'3) Release_Label'!$E:$E,1,0)),"NO UPC-CATALOG ID pair MATCH in Release_Label" )} -> Akhar - Female Version (From "Lahoriye" Soundtrack) | D12: {=ifs(and(isblank($A12),isblank($B12)),"", not(iserror(vlookup($A12&$B12,'3) Release_Label'!$D:$D&'3) Release_Label'!$E:$E,1,0))),vlookup($A12&$B12,{'3) Release_Label'!$D:$D&'3) Release_Label'!$E:$E,'3) Release_Label'!$H:$H},2,0), or(and(not(isblank($B12)),$B12=$B11,$A12<>$A11),and(not(isblank($A12)),$A12=$A11,$B12<>$B11)),"ID LISTS UNALIGNED",and($A12<>"",countif('3) Release_Label'!$D:$D,$A12)=0),"NO UPC MATCH in Release_Label",and($B12<>"",countif('3) Release_Label'!$E:$E,$B12)=0),"NO CATALOG ID MATCH in Release_Label",iserror(vlookup($A12&$B12,'3) Release_Label'!$D:$D&'3) Release_Label'!$E:$E,1,0)),"NO UPC-CATALOG ID pair MATCH in Release_Label" )} | E12: Jatinder Shah | F12: With | G12: {=ifs(or($F12="",$F12="Main Primary Artist"),$F12,not(iserror(vlookup($F12,'Reference info'!$J$5:$J$8,1,0))),"Key Artist",not(iserror(vlookup($F12,'Reference info'!$J$38:$J$405,1,0))),"Performer",not(iserror(vlookup($F12,'Reference info'!$J$10:$J$36,1,0))),"Producer & Engineer")} -> Key Artist | H12: sort(if(countif($A$5:$A&$B$5:$B,'3) Release_Label'!$D$5:$D&'3) Release_Label'!$E$5:$E)=0,'3) Release_Label'!$D$5:$D&" "&'3) Release_Label'!$E$5:$E,))
A13: 9995964330088 | C13: {=ifs(and(isblank($A13),isblank($B13)),"", not(iserror(vlookup($A13&$B13,'3) Release_Label'!$D:$D&'3) Release_Label'!$E:$E,1,0))),vlookup($A13&$B13,{'3) Release_Label'!$D:$D&'3) Release_Label'!$E:$E,'3) Release_Label'!$F:$F},2,0), or(and(not(isblank($B13)),$B13=$B12,$A13<>$A12),and(not(isblank($A13)),$A13=$A12,$B13<>$B12)),"ID LISTS UNALIGNED",and($A13<>"",countif('3) Release_Label'!$D:$D,$A13)=0),"NO UPC MATCH in Release_Label",and($B13<>"",countif('3) Release_Label'!$E:$E,$B13)=0),"NO CATALOG ID MATCH in Release_Label",iserror(vlookup($A13&$B13,'3) Release_Label'!$D:$D&'3) Release_Label'!$E:$E,1,0)),"NO UPC-CATALOG ID pair MATCH in Release_Label" )} -> Akhar (From "Lahoriye" Soundtrack) | D13: {=ifs(and(isblank($A13),isblank($B13)),"", not(iserror(vlookup($A13&$B13,'3) Release_Label'!$D:$D&'3) Release_Label'!$E:$E,1,0))),vlookup($A13&$B13,{'3) Release_Label'!$D:$D&'3) Release_Label'!$E:$E,'3) Release_Label'!$H:$H},2,0), or(and(not(isblank($B13)),$B13=$B12,$A13<>$A12),and(not(isblank($A13)),$A13=$A12,$B13<>$B12)),"ID LISTS UNALIGNED",and($A13<>"",countif('3) Release_Label'!$D:$D,$A13)=0),"NO UPC MATCH in Release_Label",and($B13<>"",countif('3) Release_Label'!$E:$E,$B13)=0),"NO CATALOG ID MATCH in Release_Label",iserror(vlookup($A13&$B13,'3) Release_Label'!$D:$D&'3) Release_Label'!$E:$E,1,0)),"NO UPC-CATALOG ID pair MATCH in Release_Label" )} | E13: Amrinder Gill | F13: Main Primary Artist | G13: {=ifs(or($F13="",$F13="Main Primary Artist"),$F13,not(iserror(vlookup($F13,'Reference info'!$J$5:$J$8,1,0))),"Key Artist",not(iserror(vlookup($F13,'Reference info'!$J$38:$J$405,1,0))),"Performer",not(iserror(vlookup($F13,'Reference info'!$J$10:$J$36,1,0))),"Producer & Engineer")} -> Main Primary Artist | H13: sort(if(countif({A5:A,B5:B},{'3) Release_Label'!D5:D,'3) Release_Label'!E5:E})=0,{'3) Release_Label'!D5:D,'3) Release_Label'!E5:E},))
A14: 9995964330088 | C14: {=ifs(and(isblank($A14),isblank($B14)),"", not(iserror(vlookup($A14&$B14,'3) Release_Label'!$D:$D&'3) Release_Label'!$E:$E,1,0))),vlookup($A14&$B14,{'3) Release_Label'!$D:$D&'3) Release_Label'!$E:$E,'3) Release_Label'!$F:$F},2,0), or(and(not(isblank($B14)),$B14=$B13,$A14<>$A13),and(not(isblank($A14)),$A14=$A13,$B14<>$B13)),"ID LISTS UNALIGNED",and($A14<>"",countif('3) Release_Label'!$D:$D,$A14)=0),"NO UPC MATCH in Release_Label",and($B14<>"",countif('3) Release_Label'!$E:$E,$B14)=0),"NO CATALOG ID MATCH in Release_Label",iserror(vlookup($A14&$B14,'3) Release_Label'!$D:$D&'3) Release_Label'!$E:$E,1,0)),"NO UPC-CATALOG ID pair MATCH in Release_Label" )} -> Akhar (From "Lahoriye" Soundtrack) | D14: {=ifs(and(isblank($A14),isblank($B14)),"", not(iserror(vlookup($A14&$B14,'3) Release_Label'!$D:$D&'3) Release_Label'!$E:$E,1,0))),vlookup($A14&$B14,{'3) Release_Label'!$D:$D&'3) Release_Label'!$E:$E,'3) Release_Label'!$H:$H},2,0), or(and(not(isblank($B14)),$B14=$B13,$A14<>$A13),and(not(isblank($A14)),$A14=$A13,$B14<>$B13)),"ID LISTS UNALIGNED",and($A14<>"",countif('3) Release_Label'!$D:$D,$A14)=0),"NO UPC MATCH in Release_Label",and($B14<>"",countif('3) Release_Label'!$E:$E,$B14)=0),"NO CATALOG ID MATCH in Release_Label",iserror(vlookup($A14&$B14,'3) Release_Label'!$D:$D&'3) Release_Label'!$E:$E,1,0)),"NO UPC-CATALOG ID pair MATCH in Release_Label" )} | E14: Jatinder Shah | F14: With | G14: {=ifs(or($F14="",$F14="Main Primary Artist"),$F14,not(iserror(vlookup($F14,'Reference info'!$J$5:$J$8,1,0))),"Key Artist",not(iserror(vlookup($F14,'Reference info'!$J$38:$J$405,1,0))),"Performer",not(iserror(vlookup($F14,'Reference info'!$J$10:$J$36,1,0))),"Producer & Engineer")} -> Key Artist | H14: sort(if(countif(filter($A:$B,$F:$F="Main Primary Artist"),'3) Release_Label'!$D$5:$E)=0,'3) Release_Label'!$D$5:$E,))
A15: 9995964312657 | C15: {=ifs(and(isblank($A15),isblank($B15)),"", not(iserror(vlookup($A15&$B15,'3) Release_Label'!$D:$D&'3) Release_Label'!$E:$E,1,0))),vlookup($A15&$B15,{'3) Release_Label'!$D:$D&'3) Release_Label'!$E:$E,'3) Release_Label'!$F:$F},2,0), or(and(not(isblank($B15)),$B15=$B14,$A15<>$A14),and(not(isblank($A15)),$A15=$A14,$B15<>$B14)),"ID LISTS UNALIGNED",and($A15<>"",countif('3) Release_Label'!$D:$D,$A15)=0),"NO UPC MATCH in Release_Label",and($B15<>"",countif('3) Release_Label'!$E:$E,$B15)=0),"NO CATALOG ID MATCH in Release_Label",iserror(vlookup($A15&$B15,'3) Release_Label'!$D:$D&'3) Release_Label'!$E:$E,1,0)),"NO UPC-CATALOG ID pair MATCH in Release_Label" )} -> Angrej (Original Motion Picture Soundtrack) | D15: {=ifs(and(isblank($A15),isblank($B15)),"", not(iserror(vlookup($A15&$B15,'3) Release_Label'!$D:$D&'3) Release_Label'!$E:$E,1,0))),vlookup($A15&$B15,{'3) Release_Label'!$D:$D&'3) Release_Label'!$E:$E,'3) Release_Label'!$H:$H},2,0), or(and(not(isblank($B15)),$B15=$B14,$A15<>$A14),and(not(isblank($A15)),$A15=$A14,$B15<>$B14)),"ID LISTS UNALIGNED",and($A15<>"",countif('3) Release_Label'!$D:$D,$A15)=0),"NO UPC MATCH in Release_Label",and($B15<>"",countif('3) Release_Label'!$E:$E,$B15)=0),"NO CATALOG ID MATCH in Release_Label",iserror(vlookup($A15&$B15,'3) Release_Label'!$D:$D&'3) Release_Label'!$E:$E,1,0)),"NO UPC-CATALOG ID pair MATCH in Release_Label" )} | E15: Amrinder Gill | F15: Main Primary Artist | G15: {=ifs(or($F15="",$F15="Main Primary Artist"),$F15,not(iserror(vlookup($F15,'Reference info'!$J$5:$J$8,1,0))),"Key Artist",not(iserror(vlookup($F15,'Reference info'!$J$38:$J$405,1,0))),"Performer",not(iserror(vlookup($F15,'Reference info'!$J$10:$J$36,1,0))),"Producer & Engineer")} -> Main Primary Artist | H15: sort(if(countif(filter($A:$B,$F:$F="Main Primary Artist"),'3) Release_Label'!$D$5:$E)>1,'3) Release_Label'!$D$5:$E,))
A16: 9995964321390 | C16: {=ifs(and(isblank($A16),isblank($B16)),"", not(iserror(vlookup($A16&$B16,'3) Release_Label'!$D:$D&'3) Release_Label'!$E:$E,1,0))),vlookup($A16&$B16,{'3) Release_Label'!$D:$D&'3) Release_Label'!$E:$E,'3) Release_Label'!$F:$F},2,0), or(and(not(isblank($B16)),$B16=#REF!,$A16<>#REF!),and(not(isblank($A16)),$A16=#REF!,$B16<>#REF!)),"ID LISTS UNALIGNED",and($A16<>"",countif('3) Release_Label'!$D:$D,$A16)=0),"NO UPC MATCH in Release_Label",and($B16<>"",countif('3) Release_Label'!$E:$E,$B16)=0),"NO CATALOG ID MATCH in Release_Label",iserror(vlookup($A16&$B16,'3) Release_Label'!$D:$D&'3) Release_Label'!$E:$E,1,0)),"NO UPC-CATALOG ID pair MATCH in Release_Label" )} -> Bambukat (From "Bambukat" Soundtrack) | D16: {=ifs(and(isblank($A16),isblank($B16)),"", not(iserror(vlookup($A16&$B16,'3) Release_Label'!$D:$D&'3) Release_Label'!$E:$E,1,0))),vlookup($A16&$B16,{'3) Release_Label'!$D:$D&'3) Release_Label'!$E:$E,'3) Release_Label'!$H:$H},2,0), or(and(not(isblank($B16)),$B16=#REF!,$A16<>#REF!),and(not(isblank($A16)),$A16=#REF!,$B16<>#REF!)),"ID LISTS UNALIGNED",and($A16<>"",countif('3) Release_Label'!$D:$D,$A16)=0),"NO UPC MATCH in Release_Label",and($B16<>"",countif('3) Release_Label'!$E:$E,$B16)=0),"NO CATALOG ID MATCH in Release_Label",iserror(vlookup($A16&$B16,'3) Release_Label'!$D:$D&'3) Release_Label'!$E:$E,1,0)),"NO UPC-CATALOG ID pair MATCH in Release_Label" )} | E16: Ammy Virk | F16: Main Primary Artist | G16: {=ifs(or($F16="",$F16="Main Primary Artist"),$F16,not(iserror(vlookup($F16,'Reference info'!$J$5:$J$8,1,0))),"Key Artist",not(iserror(vlookup($F16,'Reference info'!$J$38:$J$405,1,0))),"Performer",not(iserror(vlookup($F16,'Reference info'!$J$10:$J$36,1,0))),"Producer & Engineer")} -> Main Primary Artist
A17: 9995964321390 | C17: {=ifs(and(isblank($A17),isblank($B17)),"", not(iserror(vlookup($A17&$B17,'3) Release_Label'!$D:$D&'3) Release_Label'!$E:$E,1,0))),vlookup($A17&$B17,{'3) Release_Label'!$D:$D&'3) Release_Label'!$E:$E,'3) Release_Label'!$F:$F},2,0), or(and(not(isblank($B17)),$B17=$B16,$A17<>$A16),and(not(isblank($A17)),$A17=$A16,$B17<>$B16)),"ID LISTS UNALIGNED",and($A17<>"",countif('3) Release_Label'!$D:$D,$A17)=0),"NO UPC MATCH in Release_Label",and($B17<>"",countif('3) Release_Label'!$E:$E,$B17)=0),"NO CATALOG ID MATCH in Release_Label",iserror(vlookup($A17&$B17,'3) Release_Label'!$D:$D&'3) Release_Label'!$E:$E,1,0)),"NO UPC-CATALOG ID pair MATCH in Release_Label" )} -> Bambukat (From "Bambukat" Soundtrack) | D17: {=ifs(and(isblank($A17),isblank($B17)),"", not(iserror(vlookup($A17&$B17,'3) Release_Label'!$D:$D&'3) Release_Label'!$E:$E,1,0))),vlookup($A17&$B17,{'3) Release_Label'!$D:$D&'3) Release_Label'!$E:$E,'3) Release_Label'!$H:$H},2,0), or(and(not(isblank($B17)),$B17=$B16,$A17<>$A16),and(not(isblank($A17)),$A17=$A16,$B17<>$B16)),"ID LISTS UNALIGNED",and($A17<>"",countif('3) Release_Label'!$D:$D,$A17)=0),"NO UPC MATCH in Release_Label",and($B17<>"",countif('3) Release_Label'!$E:$E,$B17)=0),"NO CATALOG ID MATCH in Release_Label",iserror(vlookup($A17&$B17,'3) Release_Label'!$D:$D&'3) Release_Label'!$E:$E,1,0)),"NO UPC-CATALOG ID pair MATCH in Release_Label" )} | E17: Jatinder Shah | F17: With | G17: {=ifs(or($F17="",$F17="Main Primary Artist"),$F17,not(iserror(vlookup($F17,'Reference info'!$J$5:$J$8,1,0))),"Key Artist",not(iserror(vlookup($F17,'Reference info'!$J$38:$J$405,1,0))),"Performer",not(iserror(vlookup($F17,'Reference info'!$J$10:$J$36,1,0))),"Producer & Engineer")} -> Key Artist
A18: 9995964330187 | C18: {=ifs(and(isblank($A18),isblank($B18)),"", not(iserror(vlookup($A18&$B18,'3) Release_Label'!$D:$D&'3) Release_Label'!$E:$E,1,0))),vlookup($A18&$B18,{'3) Release_Label'!$D:$D&'3) Release_Label'!$E:$E,'3) Release_Label'!$F:$F},2,0), or(and(not(isblank($B18)),$B18=$B17,$A18<>$A17),and(not(isblank($A18)),$A18=$A17,$B18<>$B17)),"ID LISTS UNALIGNED",and($A18<>"",countif('3) Release_Label'!$D:$D,$A18)=0),"NO UPC MATCH in Release_Label",and($B18<>"",countif('3) Release_Label'!$E:$E,$B18)=0),"NO CATALOG ID MATCH in Release_Label",iserror(vlookup($A18&$B18,'3) Release_Label'!$D:$D&'3) Release_Label'!$E:$E,1,0)),"NO UPC-CATALOG ID pair MATCH in Release_Label" )} -> Chann Ve | D18: {=ifs(and(isblank($A18),isblank($B18)),"", not(iserror(vlookup($A18&$B18,'3) Release_Label'!$D:$D&'3) Release_Label'!$E:$E,1,0))),vlookup($A18&$B18,{'3) Release_Label'!$D:$D&'3) Release_Label'!$E:$E,'3) Release_Label'!$H:$H},2,0), or(and(not(isblank($B18)),$B18=$B17,$A18<>$A17),and(not(isblank($A18)),$A18=$A17,$B18<>$B17)),"ID LISTS UNALIGNED",and($A18<>"",countif('3) Release_Label'!$D:$D,$A18)=0),"NO UPC MATCH in Release_Label",and($B18<>"",countif('3) Release_Label'!$E:$E,$B18)=0),"NO CATALOG ID MATCH in Release_Label",iserror(vlookup($A18&$B18,'3) Release_Label'!$D:$D&'3) Release_Label'!$E:$E,1,0)),"NO UPC-CATALOG ID pair MATCH in Release_Label" )} | E18: Gurshabad | F18: Main Primary Artist | G18: {=ifs(or($F18="",$F18="Main Primary Artist"),$F18,not(iserror(vlookup($F18,'Reference info'!$J$5:$J$8,1,0))),"Key Artist",not(iserror(vlookup($F18,'Reference info'!$J$38:$J$405,1,0))),"Performer",not(iserror(vlookup($F18,'Reference info'!$J$10:$J$36,1,0))),"Producer & Engineer")} -> Main Primary Artist
A19: 9995964330187 | C19: {=ifs(and(isblank($A19),isblank($B19)),"", not(iserror(vlookup($A19&$B19,'3) Release_Label'!$D:$D&'3) Release_Label'!$E:$E,1,0))),vlookup($A19&$B19,{'3) Release_Label'!$D:$D&'3) Release_Label'!$E:$E,'3) Release_Label'!$F:$F},2,0), or(and(not(isblank($B19)),$B19=$B18,$A19<>$A18),and(not(isblank($A19)),$A19=$A18,$B19<>$B18)),"ID LISTS UNALIGNED",and($A19<>"",countif('3) Release_Label'!$D:$D,$A19)=0),"NO UPC MATCH in Release_Label",and($B19<>"",countif('3) Release_Label'!$E:$E,$B19)=0),"NO CATALOG ID MATCH in Release_Label",iserror(vlookup($A19&$B19,'3) Release_Label'!$D:$D&'3) Release_Label'!$E:$E,1,0)),"NO UPC-CATALOG ID pair MATCH in Release_Label" )} -> Chann Ve | D19: {=ifs(and(isblank($A19),isblank($B19)),"", not(iserror(vlookup($A19&$B19,'3) Release_Label'!$D:$D&'3) Release_Label'!$E:$E,1,0))),vlookup($A19&$B19,{'3) Release_Label'!$D:$D&'3) Release_Label'!$E:$E,'3) Release_Label'!$H:$H},2,0), or(and(not(isblank($B19)),$B19=$B18,$A19<>$A18),and(not(isblank($A19)),$A19=$A18,$B19<>$B18)),"ID LISTS UNALIGNED",and($A19<>"",countif('3) Release_Label'!$D:$D,$A19)=0),"NO UPC MATCH in Release_Label",and($B19<>"",countif('3) Release_Label'!$E:$E,$B19)=0),"NO CATALOG ID MATCH in Release_Label",iserror(vlookup($A19&$B19,'3) Release_Label'!$D:$D&'3) Release_Label'!$E:$E,1,0)),"NO UPC-CATALOG ID pair MATCH in Release_Label" )} | E19: Gurmoh | F19: With | G19: {=ifs(or($F19="",$F19="Main Primary Artist"),$F19,not(iserror(vlookup($F19,'Reference info'!$J$5:$J$8,1,0))),"Key Artist",not(iserror(vlookup($F19,'Reference info'!$J$38:$J$405,1,0))),"Performer",not(iserror(vlookup($F19,'Reference info'!$J$10:$J$36,1,0))),"Producer & Engineer")} -> Key Artist
A20: 9995964330446 | C20: {=ifs(and(isblank($A20),isblank($B20)),"", not(iserror(vlookup($A20&$B20,'3) Release_Label'!$D:$D&'3) Release_Label'!$E:$E,1,0))),vlookup($A20&$B20,{'3) Release_Label'!$D:$D&'3) Release_Label'!$E:$E,'3) Release_Label'!$F:$F},2,0), or(and(not(isblank($B20)),$B20=$B19,$A20<>$A19),and(not(isblank($A20)),$A20=$A19,$B20<>$B19)),"ID LISTS UNALIGNED",and($A20<>"",countif('3) Release_Label'!$D:$D,$A20)=0),"NO UPC MATCH in Release_Label",and($B20<>"",countif('3) Release_Label'!$E:$E,$B20)=0),"NO CATALOG ID MATCH in Release_Label",iserror(vlookup($A20&$B20,'3) Release_Label'!$D:$D&'3) Release_Label'!$E:$E,1,0)),"NO UPC-CATALOG ID pair MATCH in Release_Label" )} -> Chunni (From "Lahoriye" Soundtrack) | D20: {=ifs(and(isblank($A20),isblank($B20)),"", not(iserror(vlookup($A20&$B20,'3) Release_Label'!$D:$D&'3) Release_Label'!$E:$E,1,0))),vlookup($A20&$B20,{'3) Release_Label'!$D:$D&'3) Release_Label'!$E:$E,'3) Release_Label'!$H:$H},2,0), or(and(not(isblank($B20)),$B20=$B19,$A20<>$A19),and(not(isblank($A20)),$A20=$A19,$B20<>$B19)),"ID LISTS UNALIGNED",and($A20<>"",countif('3) Release_Label'!$D:$D,$A20)=0),"NO UPC MATCH in Release_Label",and($B20<>"",countif('3) Release_Label'!$E:$E,$B20)=0),"NO CATALOG ID MATCH in Release_Label",iserror(vlookup($A20&$B20,'3) Release_Label'!$D:$D&'3) Release_Label'!$E:$E,1,0)),"NO UPC-CATALOG ID pair MATCH in Release_Label" )} | E20: Amrinder Gill | F20: Main Primary Artist | G20: {=ifs(or($F20="",$F20="Main Primary Artist"),$F20,not(iserror(vlookup($F20,'Reference info'!$J$5:$J$8,1,0))),"Key Artist",not(iserror(vlookup($F20,'Reference info'!$J$38:$J$405,1,0))),"Performer",not(iserror(vlookup($F20,'Reference info'!$J$10:$J$36,1,0))),"Producer & Engineer")} -> Main Primary Artist
A21: 9995964330446 | C21: {=ifs(and(isblank($A21),isblank($B21)),"", not(iserror(vlookup($A21&$B21,'3) Release_Label'!$D:$D&'3) Release_Label'!$E:$E,1,0))),vlookup($A21&$B21,{'3) Release_Label'!$D:$D&'3) Release_Label'!$E:$E,'3) Release_Label'!$F:$F},2,0), or(and(not(isblank($B21)),$B21=$B20,$A21<>$A20),and(not(isblank($A21)),$A21=$A20,$B21<>$B20)),"ID LISTS UNALIGNED",and($A21<>"",countif('3) Release_Label'!$D:$D,$A21)=0),"NO UPC MATCH in Release_Label",and($B21<>"",countif('3) Release_Label'!$E:$E,$B21)=0),"NO CATALOG ID MATCH in Release_Label",iserror(vlookup($A21&$B21,'3) Release_Label'!$D:$D&'3) Release_Label'!$E:$E,1,0)),"NO UPC-CATALOG ID pair MATCH in Release_Label" )} -> Chunni (From "Lahoriye" Soundtrack) | D21: {=ifs(and(isblank($A21),isblank($B21)),"", not(iserror(vlookup($A21&$B21,'3) Release_Label'!$D:$D&'3) Release_Label'!$E:$E,1,0))),vlookup($A21&$B21,{'3) Release_Label'!$D:$D&'3) Release_Label'!$E:$E,'3) Release_Label'!$H:$H},2,0), or(and(not(isblank($B21)),$B21=$B20,$A21<>$A20),and(not(isblank($A21)),$A21=$A20,$B21<>$B20)),"ID LISTS UNALIGNED",and($A21<>"",countif('3) Release_Label'!$D:$D,$A21)=0),"NO UPC MATCH in Release_Label",and($B21<>"",countif('3) Release_Label'!$E:$E,$B21)=0),"NO CATALOG ID MATCH in Release_Label",iserror(vlookup($A21&$B21,'3) Release_Label'!$D:$D&'3) Release_Label'!$E:$E,1,0)),"NO UPC-CATALOG ID pair MATCH in Release_Label" )} | E21: Jatinder Shah | F21: With | G21: {=ifs(or($F21="",$F21="Main Primary Artist"),$F21,not(iserror(vlookup($F21,'Reference info'!$J$5:$J$8,1,0))),"Key Artist",not(iserror(vlookup($F21,'Reference info'!$J$38:$J$405,1,0))),"Performer",not(iserror(vlookup($F21,'Reference info'!$J$10:$J$36,1,0))),"Producer & Engineer")} -> Key Artist
A22: 9995964357078 | C22: {=ifs(and(isblank($A22),isblank($B22)),"", not(iserror(vlookup($A22&$B22,'3) Release_Label'!$D:$D&'3) Release_Label'!$E:$E,1,0))),vlookup($A22&$B22,{'3) Release_Label'!$D:$D&'3) Release_Label'!$E:$E,'3) Release_Label'!$F:$F},2,0), or(and(not(isblank($B22)),$B22=$B21,$A22<>$A21),and(not(isblank($A22)),$A22=$A21,$B22<>$B21)),"ID LISTS UNALIGNED",and($A22<>"",countif('3) Release_Label'!$D:$D,$A22)=0),"NO UPC MATCH in Release_Label",and($B22<>"",countif('3) Release_Label'!$E:$E,$B22)=0),"NO CATALOG ID MATCH in Release_Label",iserror(vlookup($A22&$B22,'3) Release_Label'!$D:$D&'3) Release_Label'!$E:$E,1,0)),"NO UPC-CATALOG ID pair MATCH in Release_Label" )} -> Daana Paani - Title Song (From "Daana Paani" Soundtrack) | D22: {=ifs(and(isblank($A22),isblank($B22)),"", not(iserror(vlookup($A22&$B22,'3) Release_Label'!$D:$D&'3) Release_Label'!$E:$E,1,0))),vlookup($A22&$B22,{'3) Release_Label'!$D:$D&'3) Release_Label'!$E:$E,'3) Release_Label'!$H:$H},2,0), or(and(not(isblank($B22)),$B22=$B21,$A22<>$A21),and(not(isblank($A22)),$A22=$A21,$B22<>$B21)),"ID LISTS UNALIGNED",and($A22<>"",countif('3) Release_Label'!$D:$D,$A22)=0),"NO UPC MATCH in Release_Label",and($B22<>"",countif('3) Release_Label'!$E:$E,$B22)=0),"NO CATALOG ID MATCH in Release_Label",iserror(vlookup($A22&$B22,'3) Release_Label'!$D:$D&'3) Release_Label'!$E:$E,1,0)),"NO UPC-CATALOG ID pair MATCH in Release_Label" )} | E22: Tarsem Jassar | F22: Main Primary Artist | G22: {=ifs(or($F22="",$F22="Main Primary Artist"),$F22,not(iserror(vlookup($F22,'Reference info'!$J$5:$J$8,1,0))),"Key Artist",not(iserror(vlookup($F22,'Reference info'!$J$38:$J$405,1,0))),"Performer",not(iserror(vlookup($F22,'Reference info'!$J$10:$J$36,1,0))),"Producer & Engineer")} -> Main Primary Artist
A23: 9995964357078 | C23: {=ifs(and(isblank($A23),isblank($B23)),"", not(iserror(vlookup($A23&$B23,'3) Release_Label'!$D:$D&'3) Release_Label'!$E:$E,1,0))),vlookup($A23&$B23,{'3) Release_Label'!$D:$D&'3) Release_Label'!$E:$E,'3) Release_Label'!$F:$F},2,0), or(and(not(isblank($B23)),$B23=$B22,$A23<>$A22),and(not(isblank($A23)),$A23=$A22,$B23<>$B22)),"ID LISTS UNALIGNED",and($A23<>"",countif('3) Release_Label'!$D:$D,$A23)=0),"NO UPC MATCH in Release_Label",and($B23<>"",countif('3) Release_Label'!$E:$E,$B23)=0),"NO CATALOG ID MATCH in Release_Label",iserror(vlookup($A23&$B23,'3) Release_Label'!$D:$D&'3) Release_Label'!$E:$E,1,0)),"NO UPC-CATALOG ID pair MATCH in Release_Label" )} -> Daana Paani - Title Song (From "Daana Paani" Soundtrack) | D23: {=ifs(and(isblank($A23),isblank($B23)),"", not(iserror(vlookup($A23&$B23,'3) Release_Label'!$D:$D&'3) Release_Label'!$E:$E,1,0))),vlookup($A23&$B23,{'3) Release_Label'!$D:$D&'3) Release_Label'!$E:$E,'3) Release_Label'!$H:$H},2,0), or(and(not(isblank($B23)),$B23=$B22,$A23<>$A22),and(not(isblank($A23)),$A23=$A22,$B23<>$B22)),"ID LISTS UNALIGNED",and($A23<>"",countif('3) Release_Label'!$D:$D,$A23)=0),"NO UPC MATCH in Release_Label",and($B23<>"",countif('3) Release_Label'!$E:$E,$B23)=0),"NO CATALOG ID MATCH in Release_Label",iserror(vlookup($A23&$B23,'3) Release_Label'!$D:$D&'3) Release_Label'!$E:$E,1,0)),"NO UPC-CATALOG ID pair MATCH in Release_Label" )} | E23: R. Guru | F23: With | G23: {=ifs(or($F23="",$F23="Main Primary Artist"),$F23,not(iserror(vlookup($F23,'Reference info'!$J$5:$J$8,1,0))),"Key Artist",not(iserror(vlookup($F23,'Reference info'!$J$38:$J$405,1,0))),"Performer",not(iserror(vlookup($F23,'Reference info'!$J$10:$J$36,1,0))),"Producer & Engineer")} -> Key Artist
A24: 9995964357016 | C24: {=ifs(and(isblank($A24),isblank($B24)),"", not(iserror(vlookup($A24&$B24,'3) Release_Label'!$D:$D&'3) Release_Label'!$E:$E,1,0))),vlookup($A24&$B24,{'3) Release_Label'!$D:$D&'3) Release_Label'!$E:$E,'3) Release_Label'!$F:$F},2,0), or(and(not(isblank($B24)),$B24=$B23,$A24<>$A23),and(not(isblank($A24)),$A24=$A23,$B24<>$B23)),"ID LISTS UNALIGNED",and($A24<>"",countif('3) Release_Label'!$D:$D,$A24)=0),"NO UPC MATCH in Release_Label",and($B24<>"",countif('3) Release_Label'!$E:$E,$B24)=0),"NO CATALOG ID MATCH in Release_Label",iserror(vlookup($A24&$B24,'3) Release_Label'!$D:$D&'3) Release_Label'!$E:$E,1,0)),"NO UPC-CATALOG ID pair MATCH in Release_Label" )} -> Daana Paani (From "Daana Paani" Soundtrack) | D24: {=ifs(and(isblank($A24),isblank($B24)),"", not(iserror(vlookup($A24&$B24,'3) Release_Label'!$D:$D&'3) Release_Label'!$E:$E,1,0))),vlookup($A24&$B24,{'3) Release_Label'!$D:$D&'3) Release_Label'!$E:$E,'3) Release_Label'!$H:$H},2,0), or(and(not(isblank($B24)),$B24=$B23,$A24<>$A23),and(not(isblank($A24)),$A24=$A23,$B24<>$B23)),"ID LISTS UNALIGNED",and($A24<>"",countif('3) Release_Label'!$D:$D,$A24)=0),"NO UPC MATCH in Release_Label",and($B24<>"",countif('3) Release_Label'!$E:$E,$B24)=0),"NO CATALOG ID MATCH in Release_Label",iserror(vlookup($A24&$B24,'3) Release_Label'!$D:$D&'3) Release_Label'!$E:$E,1,0)),"NO UPC-CATALOG ID pair MATCH in Release_Label" )} | E24: Amrinder Gill | F24: Main Primary Artist | G24: {=ifs(or($F24="",$F24="Main Primary Artist"),$F24,not(iserror(vlookup($F24,'Reference info'!$J$5:$J$8,1,0))),"Key Artist",not(iserror(vlookup($F24,'Reference info'!$J$38:$J$405,1,0))),"Performer",not(iserror(vlookup($F24,'Reference info'!$J$10:$J$36,1,0))),"Producer & Engineer")} -> Main Primary Artist
A25: 9995964357016 | C25: {=ifs(and(isblank($A25),isblank($B25)),"", not(iserror(vlookup($A25&$B25,'3) Release_Label'!$D:$D&'3) Release_Label'!$E:$E,1,0))),vlookup($A25&$B25,{'3) Release_Label'!$D:$D&'3) Release_Label'!$E:$E,'3) Release_Label'!$F:$F},2,0), or(and(not(isblank($B25)),$B25=$B24,$A25<>$A24),and(not(isblank($A25)),$A25=$A24,$B25<>$B24)),"ID LISTS UNALIGNED",and($A25<>"",countif('3) Release_Label'!$D:$D,$A25)=0),"NO UPC MATCH in Release_Label",and($B25<>"",countif('3) Release_Label'!$E:$E,$B25)=0),"NO CATALOG ID MATCH in Release_Label",iserror(vlookup($A25&$B25,'3) Release_Label'!$D:$D&'3) Release_Label'!$E:$E,1,0)),"NO UPC-CATALOG ID pair MATCH in Release_Label" )} -> Daana Paani (From "Daana Paani" Soundtrack) | D25: {=ifs(and(isblank($A25),isblank($B25)),"", not(iserror(vlookup($A25&$B25,'3) Release_Label'!$D:$D&'3) Release_Label'!$E:$E,1,0))),vlookup($A25&$B25,{'3) Release_Label'!$D:$D&'3) Release_Label'!$E:$E,'3) Release_Label'!$H:$H},2,0), or(and(not(isblank($B25)),$B25=$B24,$A25<>$A24),and(not(isblank($A25)),$A25=$A24,$B25<>$B24)),"ID LISTS UNALIGNED",and($A25<>"",countif('3) Release_Label'!$D:$D,$A25)=0),"NO UPC MATCH in Release_Label",and($B25<>"",countif('3) Release_Label'!$E:$E,$B25)=0),"NO CATALOG ID MATCH in Release_Label",iserror(vlookup($A25&$B25,'3) Release_Label'!$D:$D&'3) Release_Label'!$E:$E,1,0)),"NO UPC-CATALOG ID pair MATCH in Release_Label" )} | E25: Bir Singh | F25: With | G25: {=ifs(or($F25="",$F25="Main Primary Artist"),$F25,not(iserror(vlookup($F25,'Reference info'!$J$5:$J$8,1,0))),"Key Artist",not(iserror(vlookup($F25,'Reference info'!$J$38:$J$405,1,0))),"Performer",not(iserror(vlookup($F25,'Reference info'!$J$10:$J$36,1,0))),"Producer & Engineer")} -> Key Artist
A26: 9995964332198 | C26: {=ifs(and(isblank($A26),isblank($B26)),"", not(iserror(vlookup($A26&$B26,'3) Release_Label'!$D:$D&'3) Release_Label'!$E:$E,1,0))),vlookup($A26&$B26,{'3) Release_Label'!$D:$D&'3) Release_Label'!$E:$E,'3) Release_Label'!$F:$F},2,0), or(and(not(isblank($B26)),$B26=$B25,$A26<>$A25),and(not(isblank($A26)),$A26=$A25,$B26<>$B25)),"ID LISTS UNALIGNED",and($A26<>"",countif('3) Release_Label'!$D:$D,$A26)=0),"NO UPC MATCH in Release_Label",and($B26<>"",countif('3) Release_Label'!$E:$E,$B26)=0),"NO CATALOG ID MATCH in Release_Label",iserror(vlookup($A26&$B26,'3) Release_Label'!$D:$D&'3) Release_Label'!$E:$E,1,0)),"NO UPC-CATALOG ID pair MATCH in Release_Label" )} -> Dil Di Dua (From "Bhalwan Singh" Soundtrack) | D26: {=ifs(and(isblank($A26),isblank($B26)),"", not(iserror(vlookup($A26&$B26,'3) Release_Label'!$D:$D&'3) Release_Label'!$E:$E,1,0))),vlookup($A26&$B26,{'3) Release_Label'!$D:$D&'3) Release_Label'!$E:$E,'3) Release_Label'!$H:$H},2,0), or(and(not(isblank($B26)),$B26=$B25,$A26<>$A25),and(not(isblank($A26)),$A26=$A25,$B26<>$B25)),"ID LISTS UNALIGNED",and($A26<>"",countif('3) Release_Label'!$D:$D,$A26)=0),"NO UPC MATCH in Release_Label",and($B26<>"",countif('3) Release_Label'!$E:$E,$B26)=0),"NO CATALOG ID MATCH in Release_Label",iserror(vlookup($A26&$B26,'3) Release_Label'!$D:$D&'3) Release_Label'!$E:$E,1,0)),"NO UPC-CATALOG ID pair MATCH in Release_Label" )} | E26: Amrinder Gill | F26: Main Primary Artist | G26: {=ifs(or($F26="",$F26="Main Primary Artist"),$F26,not(iserror(vlookup($F26,'Reference info'!$J$5:$J$8,1,0))),"Key Artist",not(iserror(vlookup($F26,'Reference info'!$J$38:$J$405,1,0))),"Performer",not(iserror(vlookup($F26,'Reference info'!$J$10:$J$36,1,0))),"Producer & Engineer")} -> Main Primary Artist
A27: 9995964332198 | C27: {=ifs(and(isblank($A27),isblank($B27)),"", not(iserror(vlookup($A27&$B27,'3) Release_Label'!$D:$D&'3) Release_Label'!$E:$E,1,0))),vlookup($A27&$B27,{'3) Release_Label'!$D:$D&'3) Release_Label'!$E:$E,'3) Release_Label'!$F:$F},2,0), or(and(not(isblank($B27)),$B27=$B26,$A27<>$A26),and(not(isblank($A27)),$A27=$A26,$B27<>$B26)),"ID LISTS UNALIGNED",and($A27<>"",countif('3) Release_Label'!$D:$D,$A27)=0),"NO UPC MATCH in Release_Label",and($B27<>"",countif('3) Release_Label'!$E:$E,$B27)=0),"NO CATALOG ID MATCH in Release_Label",iserror(vlookup($A27&$B27,'3) Release_Label'!$D:$D&'3) Release_Label'!$E:$E,1,0)),"NO UPC-CATALOG ID pair MATCH in Release_Label" )} -> Dil Di Dua (From "Bhalwan Singh" Soundtrack) | D27: {=ifs(and(isblank($A27),isblank($B27)),"", not(iserror(vlookup($A27&$B27,'3) Release_Label'!$D:$D&'3) Release_Label'!$E:$E,1,0))),vlookup($A27&$B27,{'3) Release_Label'!$D:$D&'3) Release_Label'!$E:$E,'3) Release_Label'!$H:$H},2,0), or(and(not(isblank($B27)),$B27=$B26,$A27<>$A26),and(not(isblank($A27)),$A27=$A26,$B27<>$B26)),"ID LISTS UNALIGNED",and($A27<>"",countif('3) Release_Label'!$D:$D,$A27)=0),"NO UPC MATCH in Release_Label",and($B27<>"",countif('3) Release_Label'!$E:$E,$B27)=0),"NO CATALOG ID MATCH in Release_Label",iserror(vlookup($A27&$B27,'3) Release_Label'!$D:$D&'3) Release_Label'!$E:$E,1,0)),"NO UPC-CATALOG ID pair MATCH in Release_Label" )} | E27: Gurmoh | F27: With | G27: {=ifs(or($F27="",$F27="Main Primary Artist"),$F27,not(iserror(vlookup($F27,'Reference info'!$J$5:$J$8,1,0))),"Key Artist",not(iserror(vlookup($F27,'Reference info'!$J$38:$J$405,1,0))),"Performer",not(iserror(vlookup($F27,'Reference info'!$J$10:$J$36,1,0))),"Producer & Engineer")} -> Key Artist
A28: 9995964321710 | C28: {=ifs(and(isblank($A28),isblank($B28)),"", not(iserror(vlookup($A28&$B28,'3) Release_Label'!$D:$D&'3) Release_Label'!$E:$E,1,0))),vlookup($A28&$B28,{'3) Release_Label'!$D:$D&'3) Release_Label'!$E:$E,'3) Release_Label'!$F:$F},2,0), or(and(not(isblank($B28)),$B28=$B27,$A28<>$A27),and(not(isblank($A28)),$A28=$A27,$B28<>$B27)),"ID LISTS UNALIGNED",and($A28<>"",countif('3) Release_Label'!$D:$D,$A28)=0),"NO UPC MATCH in Release_Label",and($B28<>"",countif('3) Release_Label'!$E:$E,$B28)=0),"NO CATALOG ID MATCH in Release_Label",iserror(vlookup($A28&$B28,'3) Release_Label'!$D:$D&'3) Release_Label'!$E:$E,1,0)),"NO UPC-CATALOG ID pair MATCH in Release_Label" )} -> Geetkariyan | D28: {=ifs(and(isblank($A28),isblank($B28)),"", not(iserror(vlookup($A28&$B28,'3) Release_Label'!$D:$D&'3) Release_Label'!$E:$E,1,0))),vlookup($A28&$B28,{'3) Release_Label'!$D:$D&'3) Release_Label'!$E:$E,'3) Release_Label'!$H:$H},2,0), or(and(not(isblank($B28)),$B28=$B27,$A28<>$A27),and(not(isblank($A28)),$A28=$A27,$B28<>$B27)),"ID LISTS UNALIGNED",and($A28<>"",countif('3) Release_Label'!$D:$D,$A28)=0),"NO UPC MATCH in Release_Label",and($B28<>"",countif('3) Release_Label'!$E:$E,$B28)=0),"NO CATALOG ID MATCH in Release_Label",iserror(vlookup($A28&$B28,'3) Release_Label'!$D:$D&'3) Release_Label'!$E:$E,1,0)),"NO UPC-CATALOG ID pair MATCH in Release_Label" )} | E28: Gurshabad | F28: Main Primary Artist | G28: {=ifs(or($F28="",$F28="Main Primary Artist"),$F28,not(iserror(vlookup($F28,'Reference info'!$J$5:$J$8,1,0))),"Key Artist",not(iserror(vlookup($F28,'Reference info'!$J$38:$J$405,1,0))),"Performer",not(iserror(vlookup($F28,'Reference info'!$J$10:$J$36,1,0))),"Producer & Engineer")} -> Main Primary Artist
... A30: 9995964321710 | C30: {=ifs(and(isblank($A30),isblank($B30)),"", not(iserror(vlookup($A30&$B30,'3) Release_Label'!$D:$D&'3) Release_Label'!$E:$E,1,0))),vlookup($A30&$B30,{'3) Release_Label'!$D:$D&'3) Release_Label'!$E:$E,'3) Release_Label'!$F:$F},2,0), or(and(not(isblank($B30)),$B30=$B29,$A30<>$A29),and(not(isblank($A30)),$A30=$A29,$B30<>$B29)),"ID LISTS UNALIGNED",and($A30<>"",countif('3) Release_Label'!$D:$D,$A30)=0),"NO UPC MATCH in Release_Label",and($B30<>"",countif('3) Release_Label'!$E:$E,$B30)=0),"NO CATALOG ID MATCH in Release_Label",iserror(vlookup($A30&$B30,'3) Release_Label'!$D:$D&'3) Release_Label'!$E:$E,1,0)),"NO UPC-CATALOG ID pair MATCH in Release_Label" )} -> Geetkariyan | D30: {=ifs(and(isblank($A30),isblank($B30)),"", not(iserror(vlookup($A30&$B30,'3) Release_Label'!$D:$D&'3) Release_Label'!$E:$E,1,0))),vlookup($A30&$B30,{'3) Release_Label'!$D:$D&'3) Release_Label'!$E:$E,'3) Release_Label'!$H:$H},2,0), or(and(not(isblank($B30)),$B30=$B29,$A30<>$A29),and(not(isblank($A30)),$A30=$A29,$B30<>$B29)),"ID LISTS UNALIGNED",and($A30<>"",countif('3) Release_Label'!$D:$D,$A30)=0),"NO UPC MATCH in Release_Label",and($B30<>"",countif('3) Release_Label'!$E:$E,$B30)=0),"NO CATALOG ID MATCH in Release_Label",iserror(vlookup($A30&$B30,'3) Release_Label'!$D:$D&'3) Release_Label'!$E:$E,1,0)),"NO UPC-CATALOG ID pair MATCH in Release_Label" )} | E30: Gurmoh | F30: With | G30: {=ifs(or($F30="",$F30="Main Primary Artist"),$F30,not(iserror(vlookup($F30,'Reference info'!$J$5:$J$8,1,0))),"Key Artist",not(iserror(vlookup($F30,'Reference info'!$J$38:$J$405,1,0))),"Performer",not(iserror(vlookup($F30,'Reference info'!$J$10:$J$36,1,0))),"Producer & Engineer")} -> Key Artist
A31: 9995964330514 | C31: {=ifs(and(isblank($A31),isblank($B31)),"", not(iserror(vlookup($A31&$B31,'3) Release_Label'!$D:$D&'3) Release_Label'!$E:$E,1,0))),vlookup($A31&$B31,{'3) Release_Label'!$D:$D&'3) Release_Label'!$E:$E,'3) Release_Label'!$F:$F},2,0), or(and(not(isblank($B31)),$B31=#REF!,$A31<>#REF!),and(not(isblank($A31)),$A31=#REF!,$B31<>#REF!)),"ID LISTS UNALIGNED",and($A31<>"",countif('3) Release_Label'!$D:$D,$A31)=0),"NO UPC MATCH in Release_Label",and($B31<>"",countif('3) Release_Label'!$E:$E,$B31)=0),"NO CATALOG ID MATCH in Release_Label",iserror(vlookup($A31&$B31,'3) Release_Label'!$D:$D&'3) Release_Label'!$E:$E,1,0)),"NO UPC-CATALOG ID pair MATCH in Release_Label" )} -> Janjhan (From "Lahoriye" Soundtrack) | D31: {=ifs(and(isblank($A31),isblank($B31)),"", not(iserror(vlookup($A31&$B31,'3) Release_Label'!$D:$D&'3) Release_Label'!$E:$E,1,0))),vlookup($A31&$B31,{'3) Release_Label'!$D:$D&'3) Release_Label'!$E:$E,'3) Release_Label'!$H:$H},2,0), or(and(not(isblank($B31)),$B31=#REF!,$A31<>#REF!),and(not(isblank($A31)),$A31=#REF!,$B31<>#REF!)),"ID LISTS UNALIGNED",and($A31<>"",countif('3) Release_Label'!$D:$D,$A31)=0),"NO UPC MATCH in Release_Label",and($B31<>"",countif('3) Release_Label'!$E:$E,$B31)=0),"NO CATALOG ID MATCH in Release_Label",iserror(vlookup($A31&$B31,'3) Release_Label'!$D:$D&'3) Release_Label'!$E:$E,1,0)),"NO UPC-CATALOG ID pair MATCH in Release_Label" )} | E31: Gurpreet Maan | F31: Main Primary Artist | G31: {=ifs(or($F31="",$F31="Main Primary Artist"),$F31,not(iserror(vlookup($F31,'Reference info'!$J$5:$J$8,1,0))),"Key Artist",not(iserror(vlookup($F31,'Reference info'!$J$38:$J$405,1,0))),"Performer",not(iserror(vlookup($F31,'Reference info'!$J$10:$J$36,1,0))),"Producer & Engineer")} -> Main Primary Artist
A32: 9995964330514 | C32: {=ifs(and(isblank($A32),isblank($B32)),"", not(iserror(vlookup($A32&$B32,'3) Release_Label'!$D:$D&'3) Release_Label'!$E:$E,1,0))),vlookup($A32&$B32,{'3) Release_Label'!$D:$D&'3) Release_Label'!$E:$E,'3) Release_Label'!$F:$F},2,0), or(and(not(isblank($B32)),$B32=$B31,$A32<>$A31),and(not(isblank($A32)),$A32=$A31,$B32<>$B31)),"ID LISTS UNALIGNED",and($A32<>"",countif('3) Release_Label'!$D:$D,$A32)=0),"NO UPC MATCH in Release_Label",and($B32<>"",countif('3) Release_Label'!$E:$E,$B32)=0),"NO CATALOG ID MATCH in Release_Label",iserror(vlookup($A32&$B32,'3) Release_Label'!$D:$D&'3) Release_Label'!$E:$E,1,0)),"NO UPC-CATALOG ID pair MATCH in Release_Label" )} -> Janjhan (From "Lahoriye" Soundtrack) | D32: {=ifs(and(isblank($A32),isblank($B32)),"", not(iserror(vlookup($A32&$B32,'3) Release_Label'!$D:$D&'3) Release_Label'!$E:$E,1,0))),vlookup($A32&$B32,{'3) Release_Label'!$D:$D&'3) Release_Label'!$E:$E,'3) Release_Label'!$H:$H},2,0), or(and(not(isblank($B32)),$B32=$B31,$A32<>$A31),and(not(isblank($A32)),$A32=$A31,$B32<>$B31)),"ID LISTS UNALIGNED",and($A32<>"",countif('3) Release_Label'!$D:$D,$A32)=0),"NO UPC MATCH in Release_Label",and($B32<>"",countif('3) Release_Label'!$E:$E,$B32)=0),"NO CATALOG ID MATCH in Release_Label",iserror(vlookup($A32&$B32,'3) Release_Label'!$D:$D&'3) Release_Label'!$E:$E,1,0)),"NO UPC-CATALOG ID pair MATCH in Release_Label" )} | E32: Jatinder Shah | F32: With | G32: {=ifs(or($F32="",$F32="Main Primary Artist"),$F32,not(iserror(vlookup($F32,'Reference info'!$J$5:$J$8,1,0))),"Key Artist",not(iserror(vlookup($F32,'Reference info'!$J$38:$J$405,1,0))),"Performer",not(iserror(vlookup($F32,'Reference info'!$J$10:$J$36,1,0))),"Producer & Engineer")} -> Key Artist
